Workbook

Sheet Empezar aquí
A2: Homologación de Farmacia: empezar aquí
A3: Neuquén, San Juan y Salta + SAP · 284 ítems únicos del master · incorporación de SAP al 25/09/2026.
A4: ="SAP: "&B43&" coincidencias de confianza alta · "&SUM(B44:B46)&" ítems para revisar · "&B47&" sin candidato. Empezá por la hoja Master vs SAP." -> SAP: 170 coincidencias de confianza alta · 97 ítems para revisar · 17 sin candidato. Empezá por la hoja Master vs SAP.
A5: Base / sistema | B5: Ítems del master | C5: Homologados | D5: Sin equivalente confirmado | E5: Pendientes de resolver
A6: Neuquén | B6: =COUNTA(Neuquén!A8:A291) -> 284 | C6: =COUNTIFS(Neuquén!O8:O291,"Homologado") -> 0 | D6: =COUNTIFS(Neuquén!O8:O291,"Sin equivalente confirmado") -> 0 | E6: =B6-C6-D6 -> 284
A7: San Juan | B7: =COUNTA('San Juan'!A8:A291) -> 284 | C7: =COUNTIFS('San Juan'!O8:O291,"Homologado") -> 0 | D7: =COUNTIFS('San Juan'!O8:O291,"Sin equivalente confirmado") -> 0 | E7: =B7-C7-D7 -> 284
A8: Salta | B8: =COUNTA(Salta!A8:A291) -> 284 | C8: =COUNTIFS(Salta!O8:O291,"Homologado") -> 0 | D8: =COUNTIFS(Salta!O8:O291,"Sin equivalente confirmado") -> 0 | E8: =B8-C8-D8 -> 284
A9: SAP (cruce único) | B9: =COUNTA('Master vs SAP'!A8:A291) -> 284 | C9: =COUNTIFS('Master vs SAP'!O8:O291,"Homologado") -> 0 | D9: =COUNTIFS('Master vs SAP'!O8:O291,"Sin equivalente confirmado") -> 0 | E9: =B9-C9-D9 -> 284
A10: Resultado del cruce de Salta | B10: Cuenta ítems del master, no códigos únicos ni aprobaciones. Un código puede aparecer en más de un componente.
A11: Clasificación | B11: Cantidad | C11: Qué significa
A12: Coincidencia | B12: =COUNTIFS(Salta!$F$8:$F$291,A12) -> 120 | C12: Las características explícitas coinciden. La base todavía debe validar.
A13: Revisar presentación | B13: =COUNTIFS(Salta!$F$8:$F$291,A13) -> 8 | C13: Mismo ítem o familia, pero cambia dosis, concentración, volumen, forma o calibre.
A14: Revisar datos | B14: =COUNTIFS(Salta!$F$8:$F$291,A14) -> 61 | C14: Falta un dato o hay una unidad/denominación ambigua. No se presume que coincida.
A15: Revisar grupo | B15: =COUNTIFS(Salta!$F$8:$F$291,A15) -> 22 | C15: El master agrupa variantes o componentes. Hay que confirmar cobertura y códigos.
A16: Sin coincidencia | B16: =COUNTIFS(Salta!$F$8:$F$291,A16) -> 73 | C16: No se identificó candidato en este inventario; no prueba ausencia en AVAIN.
A18: Cómo usar este archivo | B18: Cada base y SAP tienen su revisión independiente. El catálogo enlaza todos los códigos por el ID común.
A19: 1. Abrí la hoja a revisar | B19: Abrí Neuquén, San Juan, Salta o Master vs SAP. D/E: candidatos. F: clasificación. G: confianza. H: detalle de lo que debe revisarse.
A20: 2. Revisá las diferencias | B20: Filtrá F por Revisar presentación para ver las diferencias comprobadas. Revisar datos indica información faltante o ambigua.
A21: 3. Completá el amarillo | B21: I: decisión. J/K: código y nombre confirmados. L/M: validadores de producto y código. N: fecha. En SAP, usar los datos del material SAP.
A22: 4. Verificá el cierre | B22: O indica qué falta. Sin equivalente exige validadores y fecha, con J/K vacíos. En Master vs SAP elegí Sin equivalente en SAP.
A23: 5. Consultá el catálogo | B23: Catálogo común integra las tres bases y SAP: P:R reciben códigos de bases homologados; S:V muestran candidatos SAP; W recibe el SAP homologado.
A25: Cómo leer la confianza | B25: Describe la evidencia del cruce; no reemplaza la validación del producto y del código.
A26: Alta | B26: Coincidencia respaldada por la descripción disponible. En Salta y SAP, coinciden los atributos que explicita el ítem del master.
A27: Media | B27: Candidato plausible, pero falta información, hay variantes agrupadas o una diferencia de volumen/presentación que requiere resolver.
A28: Baja / Sin coincidencia | B28: Baja: hay una incompatibilidad importante o evidencia débil. Sin coincidencia: no hay candidato respaldado; revisar observaciones.
A29: Origen de la confianza | B29: Salta/SAP: evaluados en sus respectivos cruces. Neuquén/San Juan: confianza histórica ajustada ante conflictos; se conserva el valor original.
A30: Marcas y presentaciones | B30: Una marca distinta, con el mismo ítem, sólo va en observaciones. Una diferencia real de presentación se clasifica Revisar presentación.
... A42: Resultado inicial SAP | B42: Un solo cruce contra Ítem que pide el master. No se reutilizan coincidencias de las bases para inferir SAP.
A43: Coincidencia | B43: =COUNTIFS('Master vs SAP'!$F$8:$F$291,A43) -> 170 | C43: Los atributos explícitos coinciden. Los responsables de producto y SAP todavía deben validar.
A44: Revisar presentación | B44: =COUNTIFS('Master vs SAP'!$F$8:$F$291,A44) -> 9 | C44: Mismo ítem o familia, pero cambia dosis, concentración, volumen, forma o calibre.
A45: Revisar datos | B45: =COUNTIFS('Master vs SAP'!$F$8:$F$291,A45) -> 44 | C45: Falta un dato o hay una unidad/denominación ambigua. No se presume que coincida.
A46: Revisar grupo | B46: =COUNTIFS('Master vs SAP'!$F$8:$F$291,A46) -> 44 | C46: El master agrupa variantes o componentes. Hay que confirmar cobertura y códigos.
A47: Sin coincidencia | B47: =COUNTIFS('Master vs SAP'!$F$8:$F$291,A47) -> 17 | C47: No se identificó candidato en la hoja SAP recibida; no prueba ausencia en todo SAP.
A49: Varios materiales SAP | B49: Puede haber varios códigos para un ítem: duplicados, marcas o variantes. D/E conservan el mismo orden; H indica qué elegir o confirmar.
A50: Trazabilidad completa | B50: El catálogo relaciona las cuatro codificaciones por ID común. Un candidato de confianza alta sigue pendiente hasta completar su validación.

Sheet Catálogo común
A2: Catálogo común · Neuquén, San Juan, Salta y SAP
A3: Una fila por ID del master. Para revisar, usá la hoja de la provincia o la hoja Master vs SAP.
A4: D:O = candidatos de las bases · P:R = códigos de bases homologados · S:V = candidatos SAP · W = código SAP homologado.
A5: La clasificación del cruce no equivale a aprobación. Códigos múltiples y nombres se muestran en el mismo orden.
D6: Neuquén · cruce inicial | H6: San Juan · cruce inicial | L6: Salta · cruce inicial | P6: Sólo códigos homologados | S6: SAP · cruce único con el master | W6: Sólo código homologado
A7: ID común propuesto | B7: Tipo de ítem | C7: Nombre común propuesto (master) | D7: Códigos Base Neuquén | E7: Nomenclatura Base Neuquén | F7: Confianza Neuquén | G7: Clasificación Neuquén | H7: Códigos Base San Juan | I7: Nomenclatura Base San Juan | J7: Confianza San Juan | K7: Clasificación San Juan | L7: Códigos Base Salta | M7: Nomenclatura Base Salta | N7: Confianza Salta | O7: Clasificación Salta | P7: Código Neuquén confirmado | Q7: Código San Juan confirmado | R7: Código Salta confirmado | S7: Códigos SAP | T7: Nomenclatura SAP | U7: Nivel de confianza SAP | V7: Clasificación SAP | W7: Código SAP confirmado
A8: M01-001 | B8: Medicación | C8: Ácido acetilsalicílico 100 mg | D8: =IF(VLOOKUP($A8,Neuquén!$A$8:$O$291,4,FALSE)="","",VLOOKUP($A8,Neuquén!$A$8:$O$291,4,FALSE)) -> 23 | E8: =IF(VLOOKUP($A8,Neuquén!$A$8:$O$291,5,FALSE)="","",VLOOKUP($A8,Neuquén!$A$8:$O$291,5,FALSE)) -> ASPIRINA | F8: =IF(VLOOKUP($A8,Neuquén!$A$8:$O$291,7,FALSE)="","",VLOOKUP($A8,Neuquén!$A$8:$O$291,7,FALSE)) -> Alta | G8: =IF(VLOOKUP($A8,Neuquén!$A$8:$O$291,6,FALSE)="","",VLOOKUP($A8,Neuquén!$A$8:$O$291,6,FALSE)) -> Coincidencia por validar | H8: =IF(VLOOKUP($A8,'San Juan'!$A$8:$O$291,4,FALSE)="","",VLOOKUP($A8,'San Juan'!$A$8:$O$291,4,FALSE)) -> MED4 | I8: =IF(VLOOKUP($A8,'San Juan'!$A$8:$O$291,5,FALSE)="","",VLOOKUP($A8,'San Juan'!$A$8:$O$291,5,FALSE)) -> Acido Acetil Salicílico Comp x 100 mg | J8: =IF(VLOOKUP($A8,'San Juan'!$A$8:$O$291,7,FALSE)="","",VLOOKUP($A8,'San Juan'!$A$8:$O$291,7,FALSE)) -> Alta | K8: =IF(VLOOKUP($A8,'San Juan'!$A$8:$O$291,6,FALSE)="","",VLOOKUP($A8,'San Juan'!$A$8:$O$291,6,FALSE)) -> Coincidencia por validar | L8: =IF(VLOOKUP($A8,Salta!$A$8:$O$291,4,FALSE)="","",VLOOKUP($A8,Salta!$A$8:$O$291,4,FALSE)) -> 410 | M8: =IF(VLOOKUP($A8,Salta!$A$8:$O$291,5,FALSE)="","",VLOOKUP($A8,Salta!$A$8:$O$291,5,FALSE)) -> Aspirina comprimidos 100mg | N8: =IF(VLOOKUP($A8,Salta!$A$8:$O$291,7,FALSE)="","",VLOOKUP($A8,Salta!$A$8:$O$291,7,FALSE)) -> Alta | O8: =IF(VLOOKUP($A8,Salta!$A$8:$O$291,6,FALSE)="","",VLOOKUP($A8,Salta!$A$8:$O$291,6,FALSE)) -> Coincidencia | P8: =IF(VLOOKUP($A8,Neuquén!$A$8:$O$291,15,FALSE)="Homologado",VLOOKUP($A8,Neuquén!$A$8:$O$291,10,FALSE),"") | Q8: =IF(VLOOKUP($A8,'San Juan'!$A$8:$O$291,15,FALSE)="Homologado",VLOOKUP($A8,'San Juan'!$A$8:$O$291,10,FALSE),"") | R8: =IF(VLOOKUP($A8,Salta!$A$8:$O$291,15,FALSE)="Homologado",VLOOKUP($A8,Salta!$A$8:$O$291,10,FALSE),"") | S8: =IF(VLOOKUP($A8,'Master vs SAP'!$A$8:$O$291,4,FALSE)="","",VLOOKUP($A8,'Master vs SAP'!$A$8:$O$291,4,FALSE)) -> 1001237 1000802 1000136 | T8: =IF(VLOOKUP($A8,'Master vs SAP'!$A$8:$O$291,5,FALSE)="","",VLOOKUP($A8,'Master vs SAP'!$A$8:$O$291,5,FALSE)) -> ACIDO ACETILSALICILICO 100MG ACIDO ACETILSALICILICO 100MG x 20 COMP ASPIRINA DE 100 MG | U8: =IF(VLOOKUP($A8,'Master vs SAP'!$A$8:$O$291,7,FALSE)="","",VLOOKUP($A8,'Master vs SAP'!$A$8:$O$291,7,FALSE)) -> Alta | V8: =IF(VLOOKUP($A8,'Master vs SAP'!$A$8:$O$291,6,FALSE)="","",VLOOKUP($A8,'Master vs SAP'!$A$8:$O$291,6,FALSE)) -> Coincidencia | W8: =IF(VLOOKUP($A8,'Master vs SAP'!$A$8:$O$291,15,FALSE)="Homologado",VLOOKUP($A8,'Master vs SAP'!$A$8:$O$291,10,FALSE),"")
A9: M01-002 | B9: Medicación | C9: Diclofenac 75 mg comp. | D9: =IF(VLOOKUP($A9,Neuquén!$A$8:$O$291,4,FALSE)="","",VLOOKUP($A9,Neuquén!$A$8:$O$291,4,FALSE)) -> 83 | E9: =IF(VLOOKUP($A9,Neuquén!$A$8:$O$291,5,FALSE)="","",VLOOKUP($A9,Neuquén!$A$8:$O$291,5,FALSE)) -> DICLOFENAC75COMP | F9: =IF(VLOOKUP($A9,Neuquén!$A$8:$O$291,7,FALSE)="","",VLOOKUP($A9,Neuquén!$A$8:$O$291,7,FALSE)) -> Alta | G9: =IF(VLOOKUP($A9,Neuquén!$A$8:$O$291,6,FALSE)="","",VLOOKUP($A9,Neuquén!$A$8:$O$291,6,FALSE)) -> Coincidencia por validar | H9: =IF(VLOOKUP($A9,'San Juan'!$A$8:$O$291,4,FALSE)="","",VLOOKUP($A9,'San Juan'!$A$8:$O$291,4,FALSE)) -> DES001 | I9: =IF(VLOOKUP($A9,'San Juan'!$A$8:$O$291,5,FALSE)="","",VLOOKUP($A9,'San Juan'!$A$8:$O$291,5,FALSE)) -> Diclofenac Comp x 75mg | J9: =IF(VLOOKUP($A9,'San Juan'!$A$8:$O$291,7,FALSE)="","",VLOOKUP($A9,'San Juan'!$A$8:$O$291,7,FALSE)) -> Alta | K9: =IF(VLOOKUP($A9,'San Juan'!$A$8:$O$291,6,FALSE)="","",VLOOKUP($A9,'San Juan'!$A$8:$O$291,6,FALSE)) -> Coincidencia por validar | L9: =IF(VLOOKUP($A9,Salta!$A$8:$O$291,4,FALSE)="","",VLOOKUP($A9,Salta!$A$8:$O$291,4,FALSE)) -> 99 | M9: =IF(VLOOKUP($A9,Salta!$A$8:$O$291,5,FALSE)="","",VLOOKUP($A9,Salta!$A$8:$O$291,5,FALSE)) -> Diclofenac Sódico Comprimidos x75mg | N9: =IF(VLOOKUP($A9,Salta!$A$8:$O$291,7,FALSE)="","",VLOOKUP($A9,Salta!$A$8:$O$291,7,FALSE)) -> Alta | O9: =IF(VLOOKUP($A9,Salta!$A$8:$O$291,6,FALSE)="","",VLOOKUP($A9,Salta!$A$8:$O$291,6,FALSE)) -> Coincidencia | P9: =IF(VLOOKUP($A9,Neuquén!$A$8:$O$291,15,FALSE)="Homologado",VLOOKUP($A9,Neuquén!$A$8:$O$291,10,FALSE),"") | Q9: =IF(VLOOKUP($A9,'San Juan'!$A$8:$O$291,15,FALSE)="Homologado",VLOOKUP($A9,'San Juan'!$A$8:$O$291,10,FALSE),"") | R9: =IF(VLOOKUP($A9,Salta!$A$8:$O$291,15,FALSE)="Homologado",VLOOKUP($A9,Salta!$A$8:$O$291,10,FALSE),"") | S9: =IF(VLOOKUP($A9,'Master vs SAP'!$A$8:$O$291,4,FALSE)="","",VLOOKUP($A9,'Master vs SAP'!$A$8:$O$291,4,FALSE)) -> 1000125 | T9: =IF(VLOOKUP($A9,'Master vs SAP'!$A$8:$O$291,5,FALSE)="","",VLOOKUP($A9,'Master vs SAP'!$A$8:$O$291,5,FALSE)) -> DICLOFENAC 75 MG COMPRIMIDOS | U9: =IF(VLOOKUP($A9,'Master vs SAP'!$A$8:$O$291,7,FALSE)="","",VLOOKUP($A9,'Master vs SAP'!$A$8:$O$291,7,FALSE)) -> Alta | V9: =IF(VLOOKUP($A9,'Master vs SAP'!$A$8:$O$291,6,FALSE)="","",VLOOKUP($A9,'Master vs SAP'!$A$8:$O$291,6,FALSE)) -> Coincidencia | W9: =IF(VLOOKUP($A9,'Master vs SAP'!$A$8:$O$291,15,FALSE)="Homologado",VLOOKUP($A9,'Master vs SAP'!$A$8:$O$291,10,FALSE),"")
A10: M01-003 | B10: Medicación | C10: Diclofenac 75 mg/3 ml amp. | D10: =IF(VLOOKUP($A10,Neuquén!$A$8:$O$291,4,FALSE)="","",VLOOKUP($A10,Neuquén!$A$8:$O$291,4,FALSE)) -> 89 | E10: =IF(VLOOKUP($A10,Neuquén!$A$8:$O$291,5,FALSE)="","",VLOOKUP($A10,Neuquén!$A$8:$O$291,5,FALSE)) -> DICLOFENACSODICO75MGAMPOLLA | F10: =IF(VLOOKUP($A10,Neuquén!$A$8:$O$291,7,FALSE)="","",VLOOKUP($A10,Neuquén!$A$8:$O$291,7,FALSE)) -> Media | G10: =IF(VLOOKUP($A10,Neuquén!$A$8:$O$291,6,FALSE)="","",VLOOKUP($A10,Neuquén!$A$8:$O$291,6,FALSE)) -> Equivalencia a revisar | H10: =IF(VLOOKUP($A10,'San Juan'!$A$8:$O$291,4,FALSE)="","",VLOOKUP($A10,'San Juan'!$A$8:$O$291,4,FALSE)) -> MED62 | I10: =IF(VLOOKUP($A10,'San Juan'!$A$8:$O$291,5,FALSE)="","",VLOOKUP($A10,'San Juan'!$A$8:$O$291,5,FALSE)) -> Diclofenac 75mg Amp x 3ml | J10: =IF(VLOOKUP($A10,'San Juan'!$A$8:$O$291,7,FALSE)="","",VLOOKUP($A10,'San Juan'!$A$8:$O$291,7,FALSE)) -> Alta | K10: =IF(VLOOKUP($A10,'San Juan'!$A$8:$O$291,6,FALSE)="","",VLOOKUP($A10,'San Juan'!$A$8:$O$291,6,FALSE)) -> Coincidencia por validar | L10: =IF(VLOOKUP($A10,Salta!$A$8:$O$291,4,FALSE)="","",VLOOKUP($A10,Salta!$A$8:$O$291,4,FALSE)) -> 97 | M10: =IF(VLOOKUP($A10,Salta!$A$8:$O$291,5,FALSE)="","",VLOOKUP($A10,Salta!$A$8:$O$291,5,FALSE)) -> Diclofenac inyectable 1 amp=3ml x 75mg | N10: =IF(VLOOKUP($A10,Salta!$A$8:$O$291,7,FALSE)="","",VLOOKUP($A10,Salta!$A$8:$O$291,7,FALSE)) -> Alta | O10: =IF(VLOOKUP($A10,Salta!$A$8:$O$291,6,FALSE)="","",VLOOKUP($A10,Salta!$A$8:$O$291,6,FALSE)) -> Coincidencia | P10: =IF(VLOOKUP($A10,Neuquén!$A$8:$O$291,15,FALSE)="Homologado",VLOOKUP($A10,Neuquén!$A$8:$O$291,10,FALSE),"") | Q10: =IF(VLOOKUP($A10,'San Juan'!$A$8:$O$291,15,FALSE)="Homologado",VLOOKUP($A10,'San Juan'!$A$8:$O$291,10,FALSE),"") | R10: =IF(VLOOKUP($A10,Salta!$A$8:$O$291,15,FALSE)="Homologado",VLOOKUP($A10,Salta!$A$8:$O$291,10,FALSE),"") | S10: =IF(VLOOKUP($A10,'Master vs SAP'!$A$8:$O$291,4,FALSE)="","",VLOOKUP($A10,'Master vs SAP'!$A$8:$O$291,4,FALSE)) -> 1000045 | T10: =IF(VLOOKUP($A10,'Master vs SAP'!$A$8:$O$291,5,FALSE)="","",VLOOKUP($A10,'Master vs SAP'!$A$8:$O$291,5,FALSE)) -> DICLOFENAC 75MG AMPOLLA 3ML | U10: =IF(VLOOKUP($A10,'Master vs SAP'!$A$8:$O$291,7,FALSE)="","",VLOOKUP($A10,'Master vs SAP'!$A$8:$O$291,7,FALSE)) -> Alta | V10: =IF(VLOOKUP($A10,'Master vs SAP'!$A$8:$O$291,6,FALSE)="","",VLOOKUP($A10,'Master vs SAP'!$A$8:$O$291,6,FALSE)) -> Coincidencia | W10: =IF(VLOOKUP($A10,'Master vs SAP'!$A$8:$O$291,15,FALSE)="Homologado",VLOOKUP($A10,'Master vs SAP'!$A$8:$O$291,10,FALSE),"")
A11: M01-004 | B11: Medicación | C11: Diclofenac + Pridinol comp. | D11: =IF(VLOOKUP($A11,Neuquén!$A$8:$O$291,4,FALSE)="","",VLOOKUP($A11,Neuquén!$A$8:$O$291,4,FALSE)) -> 82 | E11: =IF(VLOOKUP($A11,Neuquén!$A$8:$O$291,5,FALSE)="","",VLOOKUP($A11,Neuquén!$A$8:$O$291,5,FALSE)) -> DICLOFENAC+PRIDINOL | F11: =IF(VLOOKUP($A11,Neuquén!$A$8:$O$291,7,FALSE)="","",VLOOKUP($A11,Neuquén!$A$8:$O$291,7,FALSE)) -> Alta | G11: =IF(VLOOKUP($A11,Neuquén!$A$8:$O$291,6,FALSE)="","",VLOOKUP($A11,Neuquén!$A$8:$O$291,6,FALSE)) -> Coincidencia por validar | H11: =IF(VLOOKUP($A11,'San Juan'!$A$8:$O$291,4,FALSE)="","",VLOOKUP($A11,'San Juan'!$A$8:$O$291,4,FALSE)) -> MED61 | I11: =IF(VLOOKUP($A11,'San Juan'!$A$8:$O$291,5,FALSE)="","",VLOOKUP($A11,'San Juan'!$A$8:$O$291,5,FALSE)) -> Diclofenac + Pridinol Comp x 50/4 mg | J11: =IF(VLOOKUP($A11,'San Juan'!$A$8:$O$291,7,FALSE)="","",VLOOKUP($A11,'San Juan'!$A$8:$O$291,7,FALSE)) -> Alta | K11: =IF(VLOOKUP($A11,'San Juan'!$A$8:$O$291,6,FALSE)="","",VLOOKUP($A11,'San Juan'!$A$8:$O$291,6,FALSE)) -> Coincidencia por validar | L11: =IF(VLOOKUP($A11,Salta!$A$8:$O$291,4,FALSE)="","",VLOOKUP($A11,Salta!$A$8:$O$291,4,FALSE)) -> 96 | M11: =IF(VLOOKUP($A11,Salta!$A$8:$O$291,5,FALSE)="","",VLOOKUP($A11,Salta!$A$8:$O$291,5,FALSE)) -> Diclofenac + Pridinol Compromidos x50/4mg | N11: =IF(VLOOKUP($A11,Salta!$A$8:$O$291,7,FALSE)="","",VLOOKUP($A11,Salta!$A$8:$O$291,7,FALSE)) -> Alta | O11: =IF(VLOOKUP($A11,Salta!$A$8:$O$291,6,FALSE)="","",VLOOKUP($A11,Salta!$A$8:$O$291,6,FALSE)) -> Coincidencia | P11: =IF(VLOOKUP($A11,Neuquén!$A$8:$O$291,15,FALSE)="Homologado",VLOOKUP($A11,Neuquén!$A$8:$O$291,10,FALSE),"") | Q11: =IF(VLOOKUP($A11,'San Juan'!$A$8:$O$291,15,FALSE)="Homologado",VLOOKUP($A11,'San Juan'!$A$8:$O$291,10,FALSE),"") | R11: =IF(VLOOKUP($A11,Salta!$A$8:$O$291,15,FALSE)="Homologado",VLOOKUP($A11,Salta!$A$8:$O$291,10,FALSE),"") | S11: =IF(VLOOKUP($A11,'Master vs SAP'!$A$8:$O$291,4,FALSE)="","",VLOOKUP($A11,'Master vs SAP'!$A$8:$O$291,4,FALSE)) -> 1000889 | T11: =IF(VLOOKUP($A11,'Master vs SAP'!$A$8:$O$291,5,FALSE)="","",VLOOKUP($A11,'Master vs SAP'!$A$8:$O$291,5,FALSE)) -> DICLOFENAC+PRIDINOL COMPRIMIDOS | U11: =IF(VLOOKUP($A11,'Master vs SAP'!$A$8:$O$291,7,FALSE)="","",VLOOKUP($A11,'Master vs SAP'!$A$8:$O$291,7,FALSE)) -> Alta | V11: =IF(VLOOKUP($A11,'Master vs SAP'!$A$8:$O$291,6,FALSE)="","",VLOOKUP($A11,'Master vs SAP'!$A$8:$O$291,6,FALSE)) -> Coincidencia | W11: =IF(VLOOKUP($A11,'Master vs SAP'!$A$8:$O$291,15,FALSE)="Homologado",VLOOKUP($A11,'Master vs SAP'!$A$8:$O$291,10,FALSE),"")
A12: M01-005 | B12: Medicación | C12: Ibuprofeno 600 mg | D12: =IF(VLOOKUP($A12,Neuquén!$A$8:$O$291,4,FALSE)="","",VLOOKUP($A12,Neuquén!$A$8:$O$291,4,FALSE)) -> 396 | E12: =IF(VLOOKUP($A12,Neuquén!$A$8:$O$291,5,FALSE)="","",VLOOKUP($A12,Neuquén!$A$8:$O$291,5,FALSE)) -> IBUPROFENO600MGCOMPRECUBIERTOS | F12: =IF(VLOOKUP($A12,Neuquén!$A$8:$O$291,7,FALSE)="","",VLOOKUP($A12,Neuquén!$A$8:$O$291,7,FALSE)) -> Media | G12: =IF(VLOOKUP($A12,Neuquén!$A$8:$O$291,6,FALSE)="","",VLOOKUP($A12,Neuquén!$A$8:$O$291,6,FALSE)) -> Equivalencia a revisar | H12: =IF(VLOOKUP($A12,'San Juan'!$A$8:$O$291,4,FALSE)="","",VLOOKUP($A12,'San Juan'!$A$8:$O$291,4,FALSE)) -> MED102 | I12: =IF(VLOOKUP($A12,'San Juan'!$A$8:$O$291,5,FALSE)="","",VLOOKUP($A12,'San Juan'!$A$8:$O$291,5,FALSE)) -> Ibuprofeno Comp x 600 mg | J12: =IF(VLOOKUP($A12,'San Juan'!$A$8:$O$291,7,FALSE)="","",VLOOKUP($A12,'San Juan'!$A$8:$O$291,7,FALSE)) -> Alta | K12: =IF(VLOOKUP($A12,'San Juan'!$A$8:$O$291,6,FALSE)="","",VLOOKUP($A12,'San Juan'!$A$8:$O$291,6,FALSE)) -> Coincidencia por validar | L12: =IF(VLOOKUP($A12,Salta!$A$8:$O$291,4,FALSE)="","",VLOOKUP($A12,Salta!$A$8:$O$291,4,FALSE)) -> 150 | M12: =IF(VLOOKUP($A12,Salta!$A$8:$O$291,5,FALSE)="","",VLOOKUP($A12,Salta!$A$8:$O$291,5,FALSE)) -> Ibuprofeno Comprimidos x 600mg | N12: =IF(VLOOKUP($A12,Salta!$A$8:$O$291,7,FALSE)="","",VLOOKUP($A12,Salta!$A$8:$O$291,7,FALSE)) -> Alta | O12: =IF(VLOOKUP($A12,Salta!$A$8:$O$291,6,FALSE)="","",VLOOKUP($A12,Salta!$A$8:$O$291,6,FALSE)) -> Coincidencia | P12: =IF(VLOOKUP($A12,Neuquén!$A$8:$O$291,15,FALSE)="Homologado",VLOOKUP($A12,Neuquén!$A$8:$O$291,10,FALSE),"") | Q12: =IF(VLOOKUP($A12,'San Juan'!$A$8:$O$291,15,FALSE)="Homologado",VLOOKUP($A12,'San Juan'!$A$8:$O$291,10,FALSE),"") | R12: =IF(VLOOKUP($A12,Salta!$A$8:$O$291,15,FALSE)="Homologado",VLOOKUP($A12,Salta!$A$8:$O$291,10,FALSE),"") | S12: =IF(VLOOKUP($A12,'Master vs SAP'!$A$8:$O$291,4,FALSE)="","",VLOOKUP($A12,'Master vs SAP'!$A$8:$O$291,4,FALSE)) -> 1000124 | T12: =IF(VLOOKUP($A12,'Master vs SAP'!$A$8:$O$291,5,FALSE)="","",VLOOKUP($A12,'Master vs SAP'!$A$8:$O$291,5,FALSE)) -> IBUPROFENO COMP 600MG | U12: =IF(VLOOKUP($A12,'Master vs SAP'!$A$8:$O$291,7,FALSE)="","",VLOOKUP($A12,'Master vs SAP'!$A$8:$O$291,7,FALSE)) -> Alta | V12: =IF(VLOOKUP($A12,'Master vs SAP'!$A$8:$O$291,6,FALSE)="","",VLOOKUP($A12,'Master vs SAP'!$A$8:$O$291,6,FALSE)) -> Coincidencia | W12: =IF(VLOOKUP($A12,'Master vs SAP'!$A$8:$O$291,15,FALSE)="Homologado",VLOOKUP($A12,'Master vs SAP'!$A$8:$O$291,10,FALSE),"")
A13: M01-006 | B13: Medicación | C13: Ketorolac 10 mg SL | D13: =IF(VLOOKUP($A13,Neuquén!$A$8:$O$291,4,FALSE)="","",VLOOKUP($A13,Neuquén!$A$8:$O$291,4,FALSE)) -> 147 | E13: =IF(VLOOKUP($A13,Neuquén!$A$8:$O$291,5,FALSE)="","",VLOOKUP($A13,Neuquén!$A$8:$O$291,5,FALSE)) -> KETOROLAC | F13: =IF(VLOOKUP($A13,Neuquén!$A$8:$O$291,7,FALSE)="","",VLOOKUP($A13,Neuquén!$A$8:$O$291,7,FALSE)) -> Media | G13: =IF(VLOOKUP($A13,Neuquén!$A$8:$O$291,6,FALSE)="","",VLOOKUP($A13,Neuquén!$A$8:$O$291,6,FALSE)) -> Código compartido: revisar | H13: =IF(VLOOKUP($A13,'San Juan'!$A$8:$O$291,4,FALSE)="","",VLOOKUP($A13,'San Juan'!$A$8:$O$291,4,FALSE)) -> MED110 | I13: =IF(VLOOKUP($A13,'San Juan'!$A$8:$O$291,5,FALSE)="","",VLOOKUP($A13,'San Juan'!$A$8:$O$291,5,FALSE)) -> Ketorolac Comp SL X 10 mg | J13: =IF(VLOOKUP($A13,'San Juan'!$A$8:$O$291,7,FALSE)="","",VLOOKUP($A13,'San Juan'!$A$8:$O$291,7,FALSE)) -> Alta | K13: =IF(VLOOKUP($A13,'San Juan'!$A$8:$O$291,6,FALSE)="","",VLOOKUP($A13,'San Juan'!$A$8:$O$291,6,FALSE)) -> Coincidencia por validar | L13: =IF(VLOOKUP($A13,Salta!$A$8:$O$291,4,FALSE)="","",VLOOKUP($A13,Salta!$A$8:$O$291,4,FALSE)) -> 162 | M13: =IF(VLOOKUP($A13,Salta!$A$8:$O$291,5,FALSE)="","",VLOOKUP($A13,Salta!$A$8:$O$291,5,FALSE)) -> Ketorolac S/L Comprimidos x 10mg sl | N13: =IF(VLOOKUP($A13,Salta!$A$8:$O$291,7,FALSE)="","",VLOOKUP($A13,Salta!$A$8:$O$291,7,FALSE)) -> Alta | O13: =IF(VLOOKUP($A13,Salta!$A$8:$O$291,6,FALSE)="","",VLOOKUP($A13,Salta!$A$8:$O$291,6,FALSE)) -> Coincidencia | P13: =IF(VLOOKUP($A13,Neuquén!$A$8:$O$291,15,FALSE)="Homologado",VLOOKUP($A13,Neuquén!$A$8:$O$291,10,FALSE),"") | Q13: =IF(VLOOKUP($A13,'San Juan'!$A$8:$O$291,15,FALSE)="Homologado",VLOOKUP($A13,'San Juan'!$A$8:$O$291,10,FALSE),"") | R13: =IF(VLOOKUP($A13,Salta!$A$8:$O$291,15,FALSE)="Homologado",VLOOKUP($A13,Salta!$A$8:$O$291,10,FALSE),"") | S13: =IF(VLOOKUP($A13,'Master vs SAP'!$A$8:$O$291,4,FALSE)="","",VLOOKUP($A13,'Master vs SAP'!$A$8:$O$291,4,FALSE)) -> 1000129 | T13: =IF(VLOOKUP($A13,'Master vs SAP'!$A$8:$O$291,5,FALSE)="","",VLOOKUP($A13,'Master vs SAP'!$A$8:$O$291,5,FALSE)) -> KETOROLAC 10MG SUBLINGUAL | U13: =IF(VLOOKUP($A13,'Master vs SAP'!$A$8:$O$291,7,FALSE)="","",VLOOKUP($A13,'Master vs SAP'!$A$8:$O$291,7,FALSE)) -> Alta | V13: =IF(VLOOKUP($A13,'Master vs SAP'!$A$8:$O$291,6,FALSE)="","",VLOOKUP($A13,'Master vs SAP'!$A$8:$O$291,6,FALSE)) -> Coincidencia | W13: =IF(VLOOKUP($A13,'Master vs SAP'!$A$8:$O$291,15,FALSE)="Homologado",VLOOKUP($A13,'Master vs SAP'!$A$8:$O$291,10,FALSE),"")
A14: M01-007 | B14: Medicación | C14: Ketorolac 30 mg/1 ml amp. | D14: =IF(VLOOKUP($A14,Neuquén!$A$8:$O$291,4,FALSE)="","",VLOOKUP($A14,Neuquén!$A$8:$O$291,4,FALSE)) -> 147 | E14: =IF(VLOOKUP($A14,Neuquén!$A$8:$O$291,5,FALSE)="","",VLOOKUP($A14,Neuquén!$A$8:$O$291,5,FALSE)) -> KETOROLAC | F14: =IF(VLOOKUP($A14,Neuquén!$A$8:$O$291,7,FALSE)="","",VLOOKUP($A14,Neuquén!$A$8:$O$291,7,FALSE)) -> Media | G14: =IF(VLOOKUP($A14,Neuquén!$A$8:$O$291,6,FALSE)="","",VLOOKUP($A14,Neuquén!$A$8:$O$291,6,FALSE)) -> Código compartido: revisar | H14: =IF(VLOOKUP($A14,'San Juan'!$A$8:$O$291,4,FALSE)="","",VLOOKUP($A14,'San Juan'!$A$8:$O$291,4,FALSE)) -> MED109 | I14: =IF(VLOOKUP($A14,'San Juan'!$A$8:$O$291,5,FALSE)="","",VLOOKUP($A14,'San Juan'!$A$8:$O$291,5,FALSE)) -> Ketorolac 30mg Amp x 1 ml | J14: =IF(VLOOKUP($A14,'San Juan'!$A$8:$O$291,7,FALSE)="","",VLOOKUP($A14,'San Juan'!$A$8:$O$291,7,FALSE)) -> Alta | K14: =IF(VLOOKUP($A14,'San Juan'!$A$8:$O$291,6,FALSE)="","",VLOOKUP($A14,'San Juan'!$A$8:$O$291,6,FALSE)) -> Coincidencia por validar | L14: =IF(VLOOKUP($A14,Salta!$A$8:$O$291,4,FALSE)="","",VLOOKUP($A14,Salta!$A$8:$O$291,4,FALSE)) -> 160 | M14: =IF(VLOOKUP($A14,Salta!$A$8:$O$291,5,FALSE)="","",VLOOKUP($A14,Salta!$A$8:$O$291,5,FALSE)) -> Ketorolac 1 amp=30 mgr x 1ml | N14: =IF(VLOOKUP($A14,Salta!$A$8:$O$291,7,FALSE)="","",VLOOKUP($A14,Salta!$A$8:$O$291,7,FALSE)) -> Alta | O14: =IF(VLOOKUP($A14,Salta!$A$8:$O$291,6,FALSE)="","",VLOOKUP($A14,Salta!$A$8:$O$291,6,FALSE)) -> Coincidencia | P14: =IF(VLOOKUP($A14,Neuquén!$A$8:$O$291,15,FALSE)="Homologado",VLOOKUP($A14,Neuquén!$A$8:$O$291,10,FALSE),"") | Q14: =IF(VLOOKUP($A14,'San Juan'!$A$8:$O$291,15,FALSE)="Homologado",VLOOKUP($A14,'San Juan'!$A$8:$O$291,10,FALSE),"") | R14: =IF(VLOOKUP($A14,Salta!$A$8:$O$291,15,FALSE)="Homologado",VLOOKUP($A14,Salta!$A$8:$O$291,10,FALSE),"") | S14: =IF(VLOOKUP($A14,'Master vs SAP'!$A$8:$O$291,4,FALSE)="","",VLOOKUP($A14,'Master vs SAP'!$A$8:$O$291,4,FALSE)) -> 1000196 | T14: =IF(VLOOKUP($A14,'Master vs SAP'!$A$8:$O$291,5,FALSE)="","",VLOOKUP($A14,'Master vs SAP'!$A$8:$O$291,5,FALSE)) -> KETOROLAC 30 MG/1ML AMP | U14: =IF(VLOOKUP($A14,'Master vs SAP'!$A$8:$O$291,7,FALSE)="","",VLOOKUP($A14,'Master vs SAP'!$A$8:$O$291,7,FALSE)) -> Alta | V14: =IF(VLOOKUP($A14,'Master vs SAP'!$A$8:$O$291,6,FALSE)="","",VLOOKUP($A14,'Master vs SAP'!$A$8:$O$291,6,FALSE)) -> Coincidencia | W14: =IF(VLOOKUP($A14,'Master vs SAP'!$A$8:$O$291,15,FALSE)="Homologado",VLOOKUP($A14,'Master vs SAP'!$A$8:$O$291,10,FALSE),"")
A15: M01-008 | B15: Medicación | C15: Paracetamol 500 mg | D15: =IF(VLOOKUP($A15,Neuquén!$A$8:$O$291,4,FALSE)="","",VLOOKUP($A15,Neuquén!$A$8:$O$291,4,FALSE)) -> 179 | E15: =IF(VLOOKUP($A15,Neuquén!$A$8:$O$291,5,FALSE)="","",VLOOKUP($A15,Neuquén!$A$8:$O$291,5,FALSE)) -> PARACETAMOL500MG | F15: =IF(VLOOKUP($A15,Neuquén!$A$8:$O$291,7,FALSE)="","",VLOOKUP($A15,Neuquén!$A$8:$O$291,7,FALSE)) -> Alta | G15: =IF(VLOOKUP($A15,Neuquén!$A$8:$O$291,6,FALSE)="","",VLOOKUP($A15,Neuquén!$A$8:$O$291,6,FALSE)) -> Coincidencia por validar | H15: =IF(VLOOKUP($A15,'San Juan'!$A$8:$O$291,4,FALSE)="","",VLOOKUP($A15,'San Juan'!$A$8:$O$291,4,FALSE)) -> MED150 | I15: =IF(VLOOKUP($A15,'San Juan'!$A$8:$O$291,5,FALSE)="","",VLOOKUP($A15,'San Juan'!$A$8:$O$291,5,FALSE)) -> Paracetamol Comp x 1 gr | J15: =IF(VLOOKUP($A15,'San Juan'!$A$8:$O$291,7,FALSE)="","",VLOOKUP($A15,'San Juan'!$A$8:$O$291,7,FALSE)) -> Baja | K15: =IF(VLOOKUP($A15,'San Juan'!$A$8:$O$291,6,FALSE)="","",VLOOKUP($A15,'San Juan'!$A$8:$O$291,6,FALSE)) -> Revisar presentación | L15: =IF(VLOOKUP($A15,Salta!$A$8:$O$291,4,FALSE)="","",VLOOKUP($A15,Salta!$A$8:$O$291,4,FALSE)) -> 198 | M15: =IF(VLOOKUP($A15,Salta!$A$8:$O$291,5,FALSE)="","",VLOOKUP($A15,Salta!$A$8:$O$291,5,FALSE)) -> Paracetamol comprimidos 500mg | N15: =IF(VLOOKUP($A15,Salta!$A$8:$O$291,7,FALSE)="","",VLOOKUP($A15,Salta!$A$8:$O$291,7,FALSE)) -> Alta | O15: =IF(VLOOKUP($A15,Salta!$A$8:$O$291,6,FALSE)="","",VLOOKUP($A15,Salta!$A$8:$O$291,6,FALSE)) -> Coincidencia | P15: =IF(VLOOKUP($A15,Neuquén!$A$8:$O$291,15,FALSE)="Homologado",VLOOKUP($A15,Neuquén!$A$8:$O$291,10,FALSE),"") | Q15: =IF(VLOOKUP($A15,'San Juan'!$A$8:$O$291,15,FALSE)="Homologado",VLOOKUP($A15,'San Juan'!$A$8:$O$291,10,FALSE),"") | R15: =IF(VLOOKUP($A15,Salta!$A$8:$O$291,15,FALSE)="Homologado",VLOOKUP($A15,Salta!$A$8:$O$291,10,FALSE),"") | S15: =IF(VLOOKUP($A15,'Master vs SAP'!$A$8:$O$291,4,FALSE)="","",VLOOKUP($A15,'Master vs SAP'!$A$8:$O$291,4,FALSE)) -> 1000470 | T15: =IF(VLOOKUP($A15,'Master vs SAP'!$A$8:$O$291,5,FALSE)="","",VLOOKUP($A15,'Master vs SAP'!$A$8:$O$291,5,FALSE)) -> PARACETAMOL COMP 1 GRAMO | U15: =IF(VLOOKUP($A15,'Master vs SAP'!$A$8:$O$291,7,FALSE)="","",VLOOKUP($A15,'Master vs SAP'!$A$8:$O$291,7,FALSE)) -> Baja | V15: =IF(VLOOKUP($A15,'Master vs SAP'!$A$8:$O$291,6,FALSE)="","",VLOOKUP($A15,'Master vs SAP'!$A$8:$O$291,6,FALSE)) -> Revisar presentación | W15: =IF(VLOOKUP($A15,'Master vs SAP'!$A$8:$O$291,15,FALSE)="Homologado",VLOOKUP($A15,'Master vs SAP'!$A$8:$O$291,10,FALSE),"")
A16: M01-009 | B16: Medicación | C16: Dipirona 500 mg comp. | D16: =IF(VLOOKUP($A16,Neuquén!$A$8:$O$291,4,FALSE)="","",VLOOKUP($A16,Neuquén!$A$8:$O$291,4,FALSE)) -> 94 | E16: =IF(VLOOKUP($A16,Neuquén!$A$8:$O$291,5,FALSE)="","",VLOOKUP($A16,Neuquén!$A$8:$O$291,5,FALSE)) -> DIPIRONACOMP | F16: =IF(VLOOKUP($A16,Neuquén!$A$8:$O$291,7,FALSE)="","",VLOOKUP($A16,Neuquén!$A$8:$O$291,7,FALSE)) -> Media | G16: =IF(VLOOKUP($A16,Neuquén!$A$8:$O$291,6,FALSE)="","",VLOOKUP($A16,Neuquén!$A$8:$O$291,6,FALSE)) -> Equivalencia a revisar | H16: =IF(VLOOKUP($A16,'San Juan'!$A$8:$O$291,4,FALSE)="","",VLOOKUP($A16,'San Juan'!$A$8:$O$291,4,FALSE)) | I16: =IF(VLOOKUP($A16,'San Juan'!$A$8:$O$291,5,FALSE)="","",VLOOKUP($A16,'San Juan'!$A$8:$O$291,5,FALSE)) | J16: =IF(VLOOKUP($A16,'San Juan'!$A$8:$O$291,7,FALSE)="","",VLOOKUP($A16,'San Juan'!$A$8:$O$291,7,FALSE)) -> Sin coincidencia | K16: =IF(VLOOKUP($A16,'San Juan'!$A$8:$O$291,6,FALSE)="","",VLOOKUP($A16,'San Juan'!$A$8:$O$291,6,FALSE)) -> Sin código encontrado | L16: =IF(VLOOKUP($A16,Salta!$A$8:$O$291,4,FALSE)="","",VLOOKUP($A16,Salta!$A$8:$O$291,4,FALSE)) -> 105 | M16: =IF(VLOOKUP($A16,Salta!$A$8:$O$291,5,FALSE)="","",VLOOKUP($A16,Salta!$A$8:$O$291,5,FALSE)) -> Dipirona comprimidos x500mg | N16: =IF(VLOOKUP($A16,Salta!$A$8:$O$291,7,FALSE)="","",VLOOKUP($A16,Salta!$A$8:$O$291,7,FALSE)) -> Alta | O16: =IF(VLOOKUP($A16,Salta!$A$8:$O$291,6,FALSE)="","",VLOOKUP($A16,Salta!$A$8:$O$291,6,FALSE)) -> Coincidencia | P16: =IF(VLOOKUP($A16,Neuquén!$A$8:$O$291,15,FALSE)="Homologado",VLOOKUP($A16,Neuquén!$A$8:$O$291,10,FALSE),"") | Q16: =IF(VLOOKUP($A16,'San Juan'!$A$8:$O$291,15,FALSE)="Homologado",VLOOKUP($A16,'San Juan'!$A$8:$O$291,10,FALSE),"") | R16: =IF(VLOOKUP($A16,Salta!$A$8:$O$291,15,FALSE)="Homologado",VLOOKUP($A16,Salta!$A$8:$O$291,10,FALSE),"") | S16: =IF(VLOOKUP($A16,'Master vs SAP'!$A$8:$O$291,4,FALSE)="","",VLOOKUP($A16,'Master vs SAP'!$A$8:$O$291,4,FALSE)) -> 1005149 | T16: =IF(VLOOKUP($A16,'Master vs SAP'!$A$8:$O$291,5,FALSE)="","",VLOOKUP($A16,'Master vs SAP'!$A$8:$O$291,5,FALSE)) -> DIPIRONA 500MG COMPRIMIDOS | U16: =IF(VLOOKUP($A16,'Master vs SAP'!$A$8:$O$291,7,FALSE)="","",VLOOKUP($A16,'Master vs SAP'!$A$8:$O$291,7,FALSE)) -> Alta | V16: =IF(VLOOKUP($A16,'Master vs SAP'!$A$8:$O$291,6,FALSE)="","",VLOOKUP($A16,'Master vs SAP'!$A$8:$O$291,6,FALSE)) -> Coincidencia | W16: =IF(VLOOKUP($A16,'Master vs SAP'!$A$8:$O$291,15,FALSE)="Homologado",VLOOKUP($A16,'Master vs SAP'!$A$8:$O$291,10,FALSE),"")
A17: M01-010 | B17: Medicación | C17: Dipirona 1 g/2 ml amp. | D17: =IF(VLOOKUP($A17,Neuquén!$A$8:$O$291,4,FALSE)="","",VLOOKUP($A17,Neuquén!$A$8:$O$291,4,FALSE)) -> 93 | E17: =IF(VLOOKUP($A17,Neuquén!$A$8:$O$291,5,FALSE)="","",VLOOKUP($A17,Neuquén!$A$8:$O$291,5,FALSE)) -> DIPIRONAAMP | F17: =IF(VLOOKUP($A17,Neuquén!$A$8:$O$291,7,FALSE)="","",VLOOKUP($A17,Neuquén!$A$8:$O$291,7,FALSE)) -> Media | G17: =IF(VLOOKUP($A17,Neuquén!$A$8:$O$291,6,FALSE)="","",VLOOKUP($A17,Neuquén!$A$8:$O$291,6,FALSE)) -> Equivalencia a revisar | H17: =IF(VLOOKUP($A17,'San Juan'!$A$8:$O$291,4,FALSE)="","",VLOOKUP($A17,'San Juan'!$A$8:$O$291,4,FALSE)) | I17: =IF(VLOOKUP($A17,'San Juan'!$A$8:$O$291,5,FALSE)="","",VLOOKUP($A17,'San Juan'!$A$8:$O$291,5,FALSE)) | J17: =IF(VLOOKUP($A17,'San Juan'!$A$8:$O$291,7,FALSE)="","",VLOOKUP($A17,'San Juan'!$A$8:$O$291,7,FALSE)) -> Sin coincidencia | K17: =IF(VLOOKUP($A17,'San Juan'!$A$8:$O$291,6,FALSE)="","",VLOOKUP($A17,'San Juan'!$A$8:$O$291,6,FALSE)) -> Sin código encontrado | L17: =IF(VLOOKUP($A17,Salta!$A$8:$O$291,4,FALSE)="","",VLOOKUP($A17,Salta!$A$8:$O$291,4,FALSE)) -> 106 | M17: =IF(VLOOKUP($A17,Salta!$A$8:$O$291,5,FALSE)="","",VLOOKUP($A17,Salta!$A$8:$O$291,5,FALSE)) -> Dipirona inyectable 1amp=2ml 1gr | N17: =IF(VLOOKUP($A17,Salta!$A$8:$O$291,7,FALSE)="","",VLOOKUP($A17,Salta!$A$8:$O$291,7,FALSE)) -> Alta | O17: =IF(VLOOKUP($A17,Salta!$A$8:$O$291,6,FALSE)="","",VLOOKUP($A17,Salta!$A$8:$O$291,6,FALSE)) -> Coincidencia | P17: =IF(VLOOKUP($A17,Neuquén!$A$8:$O$291,15,FALSE)="Homologado",VLOOKUP($A17,Neuquén!$A$8:$O$291,10,FALSE),"") | Q17: =IF(VLOOKUP($A17,'San Juan'!$A$8:$O$291,15,FALSE)="Homologado",VLOOKUP($A17,'San Juan'!$A$8:$O$291,10,FALSE),"") | R17: =IF(VLOOKUP($A17,Salta!$A$8:$O$291,15,FALSE)="Homologado",VLOOKUP($A17,Salta!$A$8:$O$291,10,FALSE),"") | S17: =IF(VLOOKUP($A17,'Master vs SAP'!$A$8:$O$291,4,FALSE)="","",VLOOKUP($A17,'Master vs SAP'!$A$8:$O$291,4,FALSE)) -> 1000022 | T17: =IF(VLOOKUP($A17,'Master vs SAP'!$A$8:$O$291,5,FALSE)="","",VLOOKUP($A17,'Master vs SAP'!$A$8:$O$291,5,FALSE)) -> DIPIRONA 1G AMPOLLA DE 2ML INYECTABLE | U17: =IF(VLOOKUP($A17,'Master vs SAP'!$A$8:$O$291,7,FALSE)="","",VLOOKUP($A17,'Master vs SAP'!$A$8:$O$291,7,FALSE)) -> Alta | V17: =IF(VLOOKUP($A17,'Master vs SAP'!$A$8:$O$291,6,FALSE)="","",VLOOKUP($A17,'Master vs SAP'!$A$8:$O$291,6,FALSE)) -> Coincidencia | W17: =IF(VLOOKUP($A17,'Master vs SAP'!$A$8:$O$291,15,FALSE)="Homologado",VLOOKUP($A17,'Master vs SAP'!$A$8:$O$291,10,FALSE),"")
A18: M01-011 | B18: Medicación | C18: Tramadol 100 mg/2 ml amp. | D18: =IF(VLOOKUP($A18,Neuquén!$A$8:$O$291,4,FALSE)="","",VLOOKUP($A18,Neuquén!$A$8:$O$291,4,FALSE)) -> 327 | E18: =IF(VLOOKUP($A18,Neuquén!$A$8:$O$291,5,FALSE)="","",VLOOKUP($A18,Neuquén!$A$8:$O$291,5,FALSE)) -> TRAMADOL100MGAMP | F18: =IF(VLOOKUP($A18,Neuquén!$A$8:$O$291,7,FALSE)="","",VLOOKUP($A18,Neuquén!$A$8:$O$291,7,FALSE)) -> Alta | G18: =IF(VLOOKUP($A18,Neuquén!$A$8:$O$291,6,FALSE)="","",VLOOKUP($A18,Neuquén!$A$8:$O$291,6,FALSE)) -> Coincidencia por validar | H18: =IF(VLOOKUP($A18,'San Juan'!$A$8:$O$291,4,FALSE)="","",VLOOKUP($A18,'San Juan'!$A$8:$O$291,4,FALSE)) -> MED181 | I18: =IF(VLOOKUP($A18,'San Juan'!$A$8:$O$291,5,FALSE)="","",VLOOKUP($A18,'San Juan'!$A$8:$O$291,5,FALSE)) -> Tramadol 50mg/2ml amp | J18: =IF(VLOOKUP($A18,'San Juan'!$A$8:$O$291,7,FALSE)="","",VLOOKUP($A18,'San Juan'!$A$8:$O$291,7,FALSE)) -> Baja | K18: =IF(VLOOKUP($A18,'San Juan'!$A$8:$O$291,6,FALSE)="","",VLOOKUP($A18,'San Juan'!$A$8:$O$291,6,FALSE)) -> Revisar presentación | L18: =IF(VLOOKUP($A18,Salta!$A$8:$O$291,4,FALSE)="","",VLOOKUP($A18,Salta!$A$8:$O$291,4,FALSE)) -> 240 | M18: =IF(VLOOKUP($A18,Salta!$A$8:$O$291,5,FALSE)="","",VLOOKUP($A18,Salta!$A$8:$O$291,5,FALSE)) -> Tramadol clorhidrato 1 amp=2ml/100mg | N18: =IF(VLOOKUP($A18,Salta!$A$8:$O$291,7,FALSE)="","",VLOOKUP($A18,Salta!$A$8:$O$291,7,FALSE)) -> Alta | O18: =IF(VLOOKUP($A18,Salta!$A$8:$O$291,6,FALSE)="","",VLOOKUP($A18,Salta!$A$8:$O$291,6,FALSE)) -> Coincidencia | P18: =IF(VLOOKUP($A18,Neuquén!$A$8:$O$291,15,FALSE)="Homologado",VLOOKUP($A18,Neuquén!$A$8:$O$291,10,FALSE),"") | Q18: =IF(VLOOKUP($A18,'San Juan'!$A$8:$O$291,15,FALSE)="Homologado",VLOOKUP($A18,'San Juan'!$A$8:$O$291,10,FALSE),"") | R18: =IF(VLOOKUP($A18,Salta!$A$8:$O$291,15,FALSE)="Homologado",VLOOKUP($A18,Salta!$A$8:$O$291,10,FALSE),"") | S18: =IF(VLOOKUP($A18,'Master vs SAP'!$A$8:$O$291,4,FALSE)="","",VLOOKUP($A18,'Master vs SAP'!$A$8:$O$291,4,FALSE)) -> 1000635 | T18: =IF(VLOOKUP($A18,'Master vs SAP'!$A$8:$O$291,5,FALSE)="","",VLOOKUP($A18,'Master vs SAP'!$A$8:$O$291,5,FALSE)) -> TRAMADOL 50MG AMPOLLA | U18: =IF(VLOOKUP($A18,'Master vs SAP'!$A$8:$O$291,7,FALSE)="","",VLOOKUP($A18,'Master vs SAP'!$A$8:$O$291,7,FALSE)) -> Baja | V18: =IF(VLOOKUP($A18,'Master vs SAP'!$A$8:$O$291,6,FALSE)="","",VLOOKUP($A18,'Master vs SAP'!$A$8:$O$291,6,FALSE)) -> Revisar presentación | W18: =IF(VLOOKUP($A18,'Master vs SAP'!$A$8:$O$291,15,FALSE)="Homologado",VLOOKUP($A18,'Master vs SAP'!$A$8:$O$291,10,FALSE),"")
A19: M01-012 | B19: Medicación | C19: Tramadol + Paracetamol comp. | D19: =IF(VLOOKUP($A19,Neuquén!$A$8:$O$291,4,FALSE)="","",VLOOKUP($A19,Neuquén!$A$8:$O$291,4,FALSE)) -> 484 | E19: =IF(VLOOKUP($A19,Neuquén!$A$8:$O$291,5,FALSE)="","",VLOOKUP($A19,Neuquén!$A$8:$O$291,5,FALSE)) -> Tramadol+Paracetamol | F19: =IF(VLOOKUP($A19,Neuquén!$A$8:$O$291,7,FALSE)="","",VLOOKUP($A19,Neuquén!$A$8:$O$291,7,FALSE)) -> Alta | G19: =IF(VLOOKUP($A19,Neuquén!$A$8:$O$291,6,FALSE)="","",VLOOKUP($A19,Neuquén!$A$8:$O$291,6,FALSE)) -> Coincidencia por validar | H19: =IF(VLOOKUP($A19,'San Juan'!$A$8:$O$291,4,FALSE)="","",VLOOKUP($A19,'San Juan'!$A$8:$O$291,4,FALSE)) | I19: =IF(VLOOKUP($A19,'San Juan'!$A$8:$O$291,5,FALSE)="","",VLOOKUP($A19,'San Juan'!$A$8:$O$291,5,FALSE)) | J19: =IF(VLOOKUP($A19,'San Juan'!$A$8:$O$291,7,FALSE)="","",VLOOKUP($A19,'San Juan'!$A$8:$O$291,7,FALSE)) -> Sin coincidencia | K19: =IF(VLOOKUP($A19,'San Juan'!$A$8:$O$291,6,FALSE)="","",VLOOKUP($A19,'San Juan'!$A$8:$O$291,6,FALSE)) -> Sin código encontrado | L19: =IF(VLOOKUP($A19,Salta!$A$8:$O$291,4,FALSE)="","",VLOOKUP($A19,Salta!$A$8:$O$291,4,FALSE)) -> 343 | M19: =IF(VLOOKUP($A19,Salta!$A$8:$O$291,5,FALSE)="","",VLOOKUP($A19,Salta!$A$8:$O$291,5,FALSE)) -> Tramadol clorhidrato + Paracetamol Comprimidos | N19: =IF(VLOOKUP($A19,Salta!$A$8:$O$291,7,FALSE)="","",VLOOKUP($A19,Salta!$A$8:$O$291,7,FALSE)) -> Alta | O19: =IF(VLOOKUP($A19,Salta!$A$8:$O$291,6,FALSE)="","",VLOOKUP($A19,Salta!$A$8:$O$291,6,FALSE)) -> Coincidencia | P19: =IF(VLOOKUP($A19,Neuquén!$A$8:$O$291,15,FALSE)="Homologado",VLOOKUP($A19,Neuquén!$A$8:$O$291,10,FALSE),"") | Q19: =IF(VLOOKUP($A19,'San Juan'!$A$8:$O$291,15,FALSE)="Homologado",VLOOKUP($A19,'San Juan'!$A$8:$O$291,10,FALSE),"") | R19: =IF(VLOOKUP($A19,Salta!$A$8:$O$291,15,FALSE)="Homologado",VLOOKUP($A19,Salta!$A$8:$O$291,10,FALSE),"") | S19: =IF(VLOOKUP($A19,'Master vs SAP'!$A$8:$O$291,4,FALSE)="","",VLOOKUP($A19,'Master vs SAP'!$A$8:$O$291,4,FALSE)) -> 1000673 | T19: =IF(VLOOKUP($A19,'Master vs SAP'!$A$8:$O$291,5,FALSE)="","",VLOOKUP($A19,'Master vs SAP'!$A$8:$O$291,5,FALSE)) -> TRAMADOL + PARACETAMOL COMP. | U19: =IF(VLOOKUP($A19,'Master vs SAP'!$A$8:$O$291,7,FALSE)="","",VLOOKUP($A19,'Master vs SAP'!$A$8:$O$291,7,FALSE)) -> Alta | V19: =IF(VLOOKUP($A19,'Master vs SAP'!$A$8:$O$291,6,FALSE)="","",VLOOKUP($A19,'Master vs SAP'!$A$8:$O$291,6,FALSE)) -> Coincidencia | W19: =IF(VLOOKUP($A19,'Master vs SAP'!$A$8:$O$291,15,FALSE)="Homologado",VLOOKUP($A19,'Master vs SAP'!$A$8:$O$291,10,FALSE),"")
... A291: K-290 | B291: Componentes de kit | C291: Antiparras | D291: =IF(VLOOKUP($A291,Neuquén!$A$8:$O$291,4,FALSE)="","",VLOOKUP($A291,Neuquén!$A$8:$O$291,4,FALSE)) -> 1002 | E291: =IF(VLOOKUP($A291,Neuquén!$A$8:$O$291,5,FALSE)="","",VLOOKUP($A291,Neuquén!$A$8:$O$291,5,FALSE)) -> ANTIPARRA | F291: =IF(VLOOKUP($A291,Neuquén!$A$8:$O$291,7,FALSE)="","",VLOOKUP($A291,Neuquén!$A$8:$O$291,7,FALSE)) -> Sin coincidencia | G291: =IF(VLOOKUP($A291,Neuquén!$A$8:$O$291,6,FALSE)="","",VLOOKUP($A291,Neuquén!$A$8:$O$291,6,FALSE)) -> Código compartido: revisar | H291: =IF(VLOOKUP($A291,'San Juan'!$A$8:$O$291,4,FALSE)="","",VLOOKUP($A291,'San Juan'!$A$8:$O$291,4,FALSE)) | I291: =IF(VLOOKUP($A291,'San Juan'!$A$8:$O$291,5,FALSE)="","",VLOOKUP($A291,'San Juan'!$A$8:$O$291,5,FALSE)) | J291: =IF(VLOOKUP($A291,'San Juan'!$A$8:$O$291,7,FALSE)="","",VLOOKUP($A291,'San Juan'!$A$8:$O$291,7,FALSE)) -> Sin coincidencia | K291: =IF(VLOOKUP($A291,'San Juan'!$A$8:$O$291,6,FALSE)="","",VLOOKUP($A291,'San Juan'!$A$8:$O$291,6,FALSE)) -> Sin código encontrado | L291: =IF(VLOOKUP($A291,Salta!$A$8:$O$291,4,FALSE)="","",VLOOKUP($A291,Salta!$A$8:$O$291,4,FALSE)) -> 273 | M291: =IF(VLOOKUP($A291,Salta!$A$8:$O$291,5,FALSE)="","",VLOOKUP($A291,Salta!$A$8:$O$291,5,FALSE)) -> Antiparras transparentes | N291: =IF(VLOOKUP($A291,Salta!$A$8:$O$291,7,FALSE)="","",VLOOKUP($A291,Salta!$A$8:$O$291,7,FALSE)) -> Alta | O291: =IF(VLOOKUP($A291,Salta!$A$8:$O$291,6,FALSE)="","",VLOOKUP($A291,Salta!$A$8:$O$291,6,FALSE)) -> Coincidencia | P291: =IF(VLOOKUP($A291,Neuquén!$A$8:$O$291,15,FALSE)="Homologado",VLOOKUP($A291,Neuquén!$A$8:$O$291,10,FALSE),"") | Q291: =IF(VLOOKUP($A291,'San Juan'!$A$8:$O$291,15,FALSE)="Homologado",VLOOKUP($A291,'San Juan'!$A$8:$O$291,10,FALSE),"") | R291: =IF(VLOOKUP($A291,Salta!$A$8:$O$291,15,FALSE)="Homologado",VLOOKUP($A291,Salta!$A$8:$O$291,10,FALSE),"") | S291: =IF(VLOOKUP($A291,'Master vs SAP'!$A$8:$O$291,4,FALSE)="","",VLOOKUP($A291,'Master vs SAP'!$A$8:$O$291,4,FALSE)) -> 2000010 | T291: =IF(VLOOKUP($A291,'Master vs SAP'!$A$8:$O$291,5,FALSE)="","",VLOOKUP($A291,'Master vs SAP'!$A$8:$O$291,5,FALSE)) -> ANTIPARRA DE PLASTICO | U291: =IF(VLOOKUP($A291,'Master vs SAP'!$A$8:$O$291,7,FALSE)="","",VLOOKUP($A291,'Master vs SAP'!$A$8:$O$291,7,FALSE)) -> Alta | V291: =IF(VLOOKUP($A291,'Master vs SAP'!$A$8:$O$291,6,FALSE)="","",VLOOKUP($A291,'Master vs SAP'!$A$8:$O$291,6,FALSE)) -> Coincidencia | W291: =IF(VLOOKUP($A291,'Master vs SAP'!$A$8:$O$291,15,FALSE)="Homologado",VLOOKUP($A291,'Master vs SAP'!$A$8:$O$291,10,FALSE),"")

Sheet Neuquén
A2: Revisión de Neuquén
A3: 284 ítems del master. Esta hoja registra únicamente las decisiones de Neuquén.
A4: 1. Comparar C con D/E. 2. Leer clasificación, confianza y observaciones en F:H. 3. Completar el amarillo I:N.
A5: Confianza del relevamiento original, ajustada cuando se detectó un conflicto. La confianza histórica íntegra está en Datos originales.
A6: Comparación con el master · propuestas pendientes de validación | I6: Completar por la base | O6: Estado actual
A7: ID común | B7: Tipo de ítem | C7: Ítem que pide el master | D7: Códigos Base Neuquén | E7: Nomenclatura Base Neuquén | F7: Clasificación del cruce | G7: Nivel de confianza | H7: Observaciones y qué revisar | I7: Decisión de la base | J7: Código AVAIN confirmado | K7: Nombre AVAIN confirmado | L7: Validó el producto (nombre) | M7: Validó el código AVAIN (nombre) | N7: Fecha de validación | O7: Estado de esta base
A8: M02-001 | B8: Medicación | C8: Midazolam 15 mg/3 ml | D8: 330 | E8: MIDAZOLAM5MGAMP | F8: Revisar presentación | G8: Baja | H8: Master midazolam 15 mg/3 ml; Neuquén dice 5 mg ampolla. No informa volumen. Confirmar cantidad total por ampolla y concentración; no sumar ampollas para homologar. Confianza histórica: Media; ajustada a Baja por el hallazgo indicado. Fuente: master original, fila 22. | I8: Pendiente | O8: =IF(I8="Pendiente","Pendiente",IF(I8="Equivalente confirmado",IF(OR(J8="",K8=""),"Falta código o nombre",IF(OR(L8="",M8=""),"Falta validación",IF(OR(NOT(ISNUMBER(N8)),N8<=0),"Falta fecha","Homologado"))),IF(I8="Sin equivalente en AVAIN",IF(OR(J8<>"",K8<>""),"Quitar código y nombre",IF(OR(L8="",M8=""),"Falta validación",IF(OR(NOT(ISNUMBER(N8)),N8<=0),"Falta fecha","Sin equivalente confirmado"))),"Revisar decisión"))) -> Pendiente
A9: M02-007 | B9: Medicación | C9: Succinilcolina 100 mg | D9: 262 | E9: SUCCINILCOLINA500MG | F9: Revisar presentación | G9: Baja | H9: Master succinilcolina 100 mg; Neuquén registra 500 mg. Misma sustancia, presentación de dosis distinta. Confianza histórica: Media; ajustada a Baja por el hallazgo indicado. Fuente: master original, fila 179. | I9: Pendiente | O9: =IF(I9="Pendiente","Pendiente",IF(I9="Equivalente confirmado",IF(OR(J9="",K9=""),"Falta código o nombre",IF(OR(L9="",M9=""),"Falta validación",IF(OR(NOT(ISNUMBER(N9)),N9<=0),"Falta fecha","Homologado"))),IF(I9="Sin equivalente en AVAIN",IF(OR(J9<>"",K9<>""),"Quitar código y nombre",IF(OR(L9="",M9=""),"Falta validación",IF(OR(NOT(ISNUMBER(N9)),N9<=0),"Falta fecha","Sin equivalente confirmado"))),"Revisar decisión"))) -> Pendiente
A10: M05-005 | B10: Medicación | C10: Solución hipertónica nasal (Hypersol) | D10: 123 | E10: GLUCOSADO HIPERTONICO AMP | F10: Producto distinto | G10: Baja | H10: El master pide solución hipertónica nasal. El código 123 dice glucosado hipertónico en ampolla. Buscar la solución nasal. Confianza histórica: Sin coincidencia; ajustada a Baja por el hallazgo indicado. Fuente: master original, fila 6. | I10: Pendiente | O10: =IF(I10="Pendiente","Pendiente",IF(I10="Equivalente confirmado",IF(OR(J10="",K10=""),"Falta código o nombre",IF(OR(L10="",M10=""),"Falta validación",IF(OR(NOT(ISNUMBER(N10)),N10<=0),"Falta fecha","Homologado"))),IF(I10="Sin equivalente en AVAIN",IF(OR(J10<>"",K10<>""),"Quitar código y nombre",IF(OR(L10="",M10=""),"Falta validación",IF(OR(NOT(ISNUMBER(N10)),N10<=0),"Falta fecha","Sin equivalente confirmado"))),"Revisar decisión"))) -> Pendiente
A11: M08-006 | B11: Medicación | C11: Omeprazol 40 mg fco. amp. | D11: 170 | E11: OMEPRAZOL 20 MG COMP | F11: Revisar presentación | G11: Baja | H11: Mismo principio activo, dosis y forma distintas: master omeprazol 40 mg en frasco ampolla; código 170, 20 mg en comprimidos. Buscar la presentación correcta. Confianza histórica: Sin coincidencia; ajustada a Baja por el hallazgo indicado. Fuente: master original, fila 11. | I11: Pendiente | O11: =IF(I11="Pendiente","Pendiente",IF(I11="Equivalente confirmado",IF(OR(J11="",K11=""),"Falta código o nombre",IF(OR(L11="",M11=""),"Falta validación",IF(OR(NOT(ISNUMBER(N11)),N11<=0),"Falta fecha","Homologado"))),IF(I11="Sin equivalente en AVAIN",IF(OR(J11<>"",K11<>""),"Quitar código y nombre",IF(OR(L11="",M11=""),"Falta validación",IF(OR(NOT(ISNUMBER(N11)),N11<=0),"Falta fecha","Sin equivalente confirmado"))),"Revisar decisión"))) -> Pendiente
A12: M09-003 | B12: Medicación | C12: Lorazepam 4 mg/1 ml amp. | D12: 329 | E12: LORAZEPAMSUBLINGUALCOMP | F12: Revisar presentación | G12: Baja | H12: Master lorazepam 4 mg/1 ml ampolla; Neuquén registra comprimidos sublinguales. Forma distinta; falta la presentación inyectable requerida. Fuente: master original, fila 196. | I12: Pendiente | O12: =IF(I12="Pendiente","Pendiente",IF(I12="Equivalente confirmado",IF(OR(J12="",K12=""),"Falta código o nombre",IF(OR(L12="",M12=""),"Falta validación",IF(OR(NOT(ISNUMBER(N12)),N12<=0),"Falta fecha","Homologado"))),IF(I12="Sin equivalente en AVAIN",IF(OR(J12<>"",K12<>""),"Quitar código y nombre",IF(OR(L12="",M12=""),"Falta validación",IF(OR(NOT(ISNUMBER(N12)),N12<=0),"Falta fecha","Sin equivalente confirmado"))),"Revisar decisión"))) -> Pendiente
A13: M11-013 | B13: Medicación | C13: Aciclovir 400 mg | D13: 1 | E13: ACICLOVIR 5% | F13: Revisar presentación | G13: Baja | H13: Master aciclovir 400 mg; Neuquén registra 5% tópico según la observación original. Forma y concentración distintas. Buscar la presentación oral requerida. Confianza histórica: Sin coincidencia; ajustada a Baja por el hallazgo indicado. Fuente: master original, fila 33. | I13: Pendiente | O13: =IF(I13="Pendiente","Pendiente",IF(I13="Equivalente confirmado",IF(OR(J13="",K13=""),"Falta código o nombre",IF(OR(L13="",M13=""),"Falta validación",IF(OR(NOT(ISNUMBER(N13)),N13<=0),"Falta fecha","Homologado"))),IF(I13="Sin equivalente en AVAIN",IF(OR(J13<>"",K13<>""),"Quitar código y nombre",IF(OR(L13="",M13=""),"Falta validación",IF(OR(NOT(ISNUMBER(N13)),N13<=0),"Falta fecha","Sin equivalente confirmado"))),"Revisar decisión"))) -> Pendiente
A14: M13-007 | B14: Medicación | C14: Insulina corriente humana | D14: 389 | E14: INSULINA HUMALOG MIX 25 100 U/ML X 3ML | F14: Producto distinto | G14: Baja | H14: Master insulina corriente humana; Neuquén registra Humalog Mix 25. No se trata sólo de una marca: la formulación es distinta. Confianza histórica: Sin coincidencia; ajustada a Baja por el hallazgo indicado. Fuente: master original, fila 53. | I14: Pendiente | O14: =IF(I14="Pendiente","Pendiente",IF(I14="Equivalente confirmado",IF(OR(J14="",K14=""),"Falta código o nombre",IF(OR(L14="",M14=""),"Falta validación",IF(OR(NOT(ISNUMBER(N14)),N14<=0),"Falta fecha","Homologado"))),IF(I14="Sin equivalente en AVAIN",IF(OR(J14<>"",K14<>""),"Quitar código y nombre",IF(OR(L14="",M14=""),"Falta validación",IF(OR(NOT(ISNUMBER(N14)),N14<=0),"Falta fecha","Sin equivalente confirmado"))),"Revisar decisión"))) -> Pendiente
A15: D-132 | B15: Descartables | C15: Guía microgotero | D15: 278 | E15: GUIAMACROGOTEROV13/14 | F15: Variante distinta | G15: Baja | H15: El master pide microgotero. El código 278 dice macrogotero. Buscar el código de microgotero. Confianza histórica: Alta; ajustada a Baja por el hallazgo indicado. Fuente: master original, fila 57. | I15: Pendiente | O15: =IF(I15="Pendiente","Pendiente",IF(I15="Equivalente confirmado",IF(OR(J15="",K15=""),"Falta código o nombre",IF(OR(L15="",M15=""),"Falta validación",IF(OR(NOT(ISNUMBER(N15)),N15<=0),"Falta fecha","Homologado"))),IF(I15="Sin equivalente en AVAIN",IF(OR(J15<>"",K15<>""),"Quitar código y nombre",IF(OR(L15="",M15=""),"Falta validación",IF(OR(NOT(ISNUMBER(N15)),N15<=0),"Falta fecha","Sin equivalente confirmado"))),"Revisar decisión"))) -> Pendiente
A16: D-141 | B16: Descartables | C16: Gasas estériles 10x10 | D16: 404 | E16: GUANTESESTERILES | F16: Producto distinto | G16: Baja | H16: El master pide gasas estériles 10x10. El código 404 dice guantes estériles. Buscar el código de gasas. Confianza histórica: Media; ajustada a Baja por el hallazgo indicado. Fuente: master original, fila 58. | I16: Pendiente | O16: =IF(I16="Pendiente","Pendiente",IF(I16="Equivalente confirmado",IF(OR(J16="",K16=""),"Falta código o nombre",IF(OR(L16="",M16=""),"Falta validación",IF(OR(NOT(ISNUMBER(N16)),N16<=0),"Falta fecha","Homologado"))),IF(I16="Sin equivalente en AVAIN",IF(OR(J16<>"",K16<>""),"Quitar código y nombre",IF(OR(L16="",M16=""),"Falta validación",IF(OR(NOT(ISNUMBER(N16)),N16<=0),"Falta fecha","Sin equivalente confirmado"))),"Revisar decisión"))) -> Pendiente
A17: E-184 | B17: Equipamiento | C17: Aspirador de secreciones (eléctrico) | D17: 405 | E17: ASPIRADORMANUAL | F17: Equipo distinto | G17: Baja | H17: El master pide aspirador eléctrico. El código 405 dice aspirador manual. Buscar el equipo eléctrico. Fuente: master original, fila 187. | I17: Pendiente | O17: =IF(I17="Pendiente","Pendiente",IF(I17="Equivalente confirmado",IF(OR(J17="",K17=""),"Falta código o nombre",IF(OR(L17="",M17=""),"Falta validación",IF(OR(NOT(ISNUMBER(N17)),N17<=0),"Falta fecha","Homologado"))),IF(I17="Sin equivalente en AVAIN",IF(OR(J17<>"",K17<>""),"Quitar código y nombre",IF(OR(L17="",M17=""),"Falta validación",IF(OR(NOT(ISNUMBER(N17)),N17<=0),"Falta fecha","Sin equivalente confirmado"))),"Revisar decisión"))) -> Pendiente
A18: K-282 | B18: Componentes de kit | C18: Tarjetas de trauma (triage) | D18: 424 | E18: TIJERA MULTIUSO | F18: Producto distinto | G18: Baja | H18: El master pide tarjetas de triage. El código 424 dice tijera multiuso. Buscar tarjetas de triage. Confianza histórica: Sin coincidencia; ajustada a Baja por el hallazgo indicado. Fuente: master original, fila 280. | I18: Pendiente | O18: =IF(I18="Pendiente","Pendiente",IF(I18="Equivalente confirmado",IF(OR(J18="",K18=""),"Falta código o nombre",IF(OR(L18="",M18=""),"Falta validación",IF(OR(NOT(ISNUMBER(N18)),N18<=0),"Falta fecha","Homologado"))),IF(I18="Sin equivalente en AVAIN",IF(OR(J18<>"",K18<>""),"Quitar código y nombre",IF(OR(L18="",M18=""),"Falta validación",IF(OR(NOT(ISNUMBER(N18)),N18<=0),"Falta fecha","Sin equivalente confirmado"))),"Revisar decisión"))) -> Pendiente
A19: M01-006 | B19: Medicación | C19: Ketorolac 10 mg SL | D19: 147 | E19: KETOROLAC | F19: Código compartido: revisar | G19: Media | H19: El código también aparece en M01-007. Confirmar si son el mismo producto o variantes distintas. No agrupar dosis, tamaños o equipos diferentes. Fuente: master original, fila 168. | I19: Pendiente | O19: =IF(I19="Pendiente","Pendiente",IF(I19="Equivalente confirmado",IF(OR(J19="",K19=""),"Falta código o nombre",IF(OR(L19="",M19=""),"Falta validación",IF(OR(NOT(ISNUMBER(N19)),N19<=0),"Falta fecha","Homologado"))),IF(I19="Sin equivalente en AVAIN",IF(OR(J19<>"",K19<>""),"Quitar código y nombre",IF(OR(L19="",M19=""),"Falta validación",IF(OR(NOT(ISNUMBER(N19)),N19<=0),"Falta fecha","Sin equivalente confirmado"))),"Revisar decisión"))) -> Pendiente
... A291: K-288 | B291: Componentes de kit | C291: Campos estériles | D291: 358 | E291: CAMPOESTERIL | F291: Coincidencia por validar | G291: Alta | H291: El relevamiento indica una coincidencia probable. Confirmar las características del producto y la existencia del código en esta base. Fuente: master original, fila 165. | I291: Pendiente | O291: =IF(I291="Pendiente","Pendiente",IF(I291="Equivalente confirmado",IF(OR(J291="",K291=""),"Falta código o nombre",IF(OR(L291="",M291=""),"Falta validación",IF(OR(NOT(ISNUMBER(N291)),N291<=0),"Falta fecha","Homologado"))),IF(I291="Sin equivalente en AVAIN",IF(OR(J291<>"",K291<>""),"Quitar código y nombre",IF(OR(L291="",M291=""),"Falta validación",IF(OR(NOT(ISNUMBER(N291)),N291<=0),"Falta fecha","Sin equivalente confirmado"))),"Revisar decisión"))) -> Pendiente

Sheet San Juan
A2: Revisión de San Juan
A3: 284 ítems del master. Esta hoja registra únicamente las decisiones de San Juan.
A4: 1. Comparar C con D/E. 2. Leer clasificación, confianza y observaciones en F:H. 3. Completar el amarillo I:N.
A5: Confianza del relevamiento original, ajustada cuando se detectó un conflicto. La confianza histórica íntegra está en Datos originales.
A6: Comparación con el master · propuestas pendientes de validación | I6: Completar por la base | O6: Estado actual
A7: ID común | B7: Tipo de ítem | C7: Ítem que pide el master | D7: Códigos Base San Juan | E7: Nomenclatura Base San Juan | F7: Clasificación del cruce | G7: Nivel de confianza | H7: Observaciones y qué revisar | I7: Decisión de la base | J7: Código AVAIN confirmado | K7: Nombre AVAIN confirmado | L7: Validó el producto (nombre) | M7: Validó el código AVAIN (nombre) | N7: Fecha de validación | O7: Estado de esta base
A8: M01-008 | B8: Medicación | C8: Paracetamol 500 mg | D8: MED150 | E8: Paracetamol Comp x 1 gr | F8: Revisar presentación | G8: Baja | H8: Master paracetamol 500 mg; San Juan registra 1 g. Misma sustancia, dosis distinta. Buscar 500 mg; no homologar por posibilidad de fraccionamiento. Fuente: master original, fila 12. | I8: Pendiente | O8: =IF(I8="Pendiente","Pendiente",IF(I8="Equivalente confirmado",IF(OR(J8="",K8=""),"Falta código o nombre",IF(OR(L8="",M8=""),"Falta validación",IF(OR(NOT(ISNUMBER(N8)),N8<=0),"Falta fecha","Homologado"))),IF(I8="Sin equivalente en AVAIN",IF(OR(J8<>"",K8<>""),"Quitar código y nombre",IF(OR(L8="",M8=""),"Falta validación",IF(OR(NOT(ISNUMBER(N8)),N8<=0),"Falta fecha","Sin equivalente confirmado"))),"Revisar decisión"))) -> Pendiente
A9: M01-011 | B9: Medicación | C9: Tramadol 100 mg/2 ml amp. | D9: MED181 | E9: Tramadol 50mg/2ml amp | F9: Revisar presentación | G9: Baja | H9: Mismo principio activo, dosis distinta: master tramadol 100 mg/2 ml; MED181, 50 mg/2 ml. Confirmar la descripción y buscar la dosis requerida. Confianza histórica: Alta; ajustada a Baja por el hallazgo indicado. Fuente: master original, fila 15. | I9: Pendiente | O9: =IF(I9="Pendiente","Pendiente",IF(I9="Equivalente confirmado",IF(OR(J9="",K9=""),"Falta código o nombre",IF(OR(L9="",M9=""),"Falta validación",IF(OR(NOT(ISNUMBER(N9)),N9<=0),"Falta fecha","Homologado"))),IF(I9="Sin equivalente en AVAIN",IF(OR(J9<>"",K9<>""),"Quitar código y nombre",IF(OR(L9="",M9=""),"Falta validación",IF(OR(NOT(ISNUMBER(N9)),N9<=0),"Falta fecha","Sin equivalente confirmado"))),"Revisar decisión"))) -> Pendiente
A10: M01-017 | B10: Medicación | C10: Caramelos con antibiótico | D10: MED30 | E10: Caramelos antigripales con benzocaina 20.7mg | F10: Producto distinto | G10: Baja | H10: Master caramelos con antibiótico; San Juan registra benzocaína. La descripción no acredita el antibiótico solicitado. Fuente: master original, fila 21. | I10: Pendiente | O10: =IF(I10="Pendiente","Pendiente",IF(I10="Equivalente confirmado",IF(OR(J10="",K10=""),"Falta código o nombre",IF(OR(L10="",M10=""),"Falta validación",IF(OR(NOT(ISNUMBER(N10)),N10<=0),"Falta fecha","Homologado"))),IF(I10="Sin equivalente en AVAIN",IF(OR(J10<>"",K10<>""),"Quitar código y nombre",IF(OR(L10="",M10=""),"Falta validación",IF(OR(NOT(ISNUMBER(N10)),N10<=0),"Falta fecha","Sin equivalente confirmado"))),"Revisar decisión"))) -> Pendiente
A11: M06-004 | B11: Medicación | C11: Betametasona retard amp. | D11: DES044 | E11: Dexametasona 1 amp=2ml | F11: Producto distinto | G11: Baja | H11: Master betametasona retard; San Juan registra dexametasona. Son principios activos distintos; la clase terapéutica no los hace equivalentes. Fuente: master original, fila 9. | I11: Pendiente | O11: =IF(I11="Pendiente","Pendiente",IF(I11="Equivalente confirmado",IF(OR(J11="",K11=""),"Falta código o nombre",IF(OR(L11="",M11=""),"Falta validación",IF(OR(NOT(ISNUMBER(N11)),N11<=0),"Falta fecha","Homologado"))),IF(I11="Sin equivalente en AVAIN",IF(OR(J11<>"",K11<>""),"Quitar código y nombre",IF(OR(L11="",M11=""),"Falta validación",IF(OR(NOT(ISNUMBER(N11)),N11<=0),"Falta fecha","Sin equivalente confirmado"))),"Revisar decisión"))) -> Pendiente
A12: M08-004 | B12: Medicación | C12: Butilbromuro de hioscina 10 mg comp. | D12: MED100 | E12: Hioscina x 20 mg Amp x 1 ml | F12: Revisar presentación | G12: Baja | H12: Master hioscina 10 mg comprimidos; San Juan registra 20 mg en ampolla. Forma y dosis distintas. Fuente: master original, fila 194. | I12: Pendiente | O12: =IF(I12="Pendiente","Pendiente",IF(I12="Equivalente confirmado",IF(OR(J12="",K12=""),"Falta código o nombre",IF(OR(L12="",M12=""),"Falta validación",IF(OR(NOT(ISNUMBER(N12)),N12<=0),"Falta fecha","Homologado"))),IF(I12="Sin equivalente en AVAIN",IF(OR(J12<>"",K12<>""),"Quitar código y nombre",IF(OR(L12="",M12=""),"Falta validación",IF(OR(NOT(ISNUMBER(N12)),N12<=0),"Falta fecha","Sin equivalente confirmado"))),"Revisar decisión"))) -> Pendiente
A13: M12-003 | B13: Medicación | C13: Hidroclorotiazida 25 mg | D13: MED95 | E13: Hidroclorotiazida Comp x 50 mg | F13: Revisar presentación | G13: Baja | H13: Master hidroclorotiazida 25 mg; San Juan registra 50 mg. Misma sustancia, dosis distinta. Fuente: master original, fila 105. | I13: Pendiente | O13: =IF(I13="Pendiente","Pendiente",IF(I13="Equivalente confirmado",IF(OR(J13="",K13=""),"Falta código o nombre",IF(OR(L13="",M13=""),"Falta validación",IF(OR(NOT(ISNUMBER(N13)),N13<=0),"Falta fecha","Homologado"))),IF(I13="Sin equivalente en AVAIN",IF(OR(J13<>"",K13<>""),"Quitar código y nombre",IF(OR(L13="",M13=""),"Falta validación",IF(OR(NOT(ISNUMBER(N13)),N13<=0),"Falta fecha","Sin equivalente confirmado"))),"Revisar decisión"))) -> Pendiente
A14: M13-004 | B14: Medicación | C14: Dextrosa 25% 500 ml | D14: MED58 | E14: Dextrosa al 5% x 500 ml sachet | F14: Revisar presentación | G14: Baja | H14: El master pide dextrosa 25% de 500 ml. MED58 dice dextrosa 5% de 500 ml. Misma sustancia, concentración distinta. Buscar la concentración correcta. Fuente: master original, fila 42. | I14: Pendiente | O14: =IF(I14="Pendiente","Pendiente",IF(I14="Equivalente confirmado",IF(OR(J14="",K14=""),"Falta código o nombre",IF(OR(L14="",M14=""),"Falta validación",IF(OR(NOT(ISNUMBER(N14)),N14<=0),"Falta fecha","Homologado"))),IF(I14="Sin equivalente en AVAIN",IF(OR(J14<>"",K14<>""),"Quitar código y nombre",IF(OR(L14="",M14=""),"Falta validación",IF(OR(NOT(ISNUMBER(N14)),N14<=0),"Falta fecha","Sin equivalente confirmado"))),"Revisar decisión"))) -> Pendiente
A15: D-132 | B15: Descartables | C15: Guía microgotero | D15: DESC73 | E15: Guia Macrogotero | F15: Variante distinta | G15: Baja | H15: El master pide microgotero. DESC73 dice macrogotero. Buscar el código de microgotero. Confianza histórica: Alta; ajustada a Baja por el hallazgo indicado. Fuente: master original, fila 57. | I15: Pendiente | O15: =IF(I15="Pendiente","Pendiente",IF(I15="Equivalente confirmado",IF(OR(J15="",K15=""),"Falta código o nombre",IF(OR(L15="",M15=""),"Falta validación",IF(OR(NOT(ISNUMBER(N15)),N15<=0),"Falta fecha","Homologado"))),IF(I15="Sin equivalente en AVAIN",IF(OR(J15<>"",K15<>""),"Quitar código y nombre",IF(OR(L15="",M15=""),"Falta validación",IF(OR(NOT(ISNUMBER(N15)),N15<=0),"Falta fecha","Sin equivalente confirmado"))),"Revisar decisión"))) -> Pendiente
A16: D-175 | B16: Descartables | C16: Iodopovidona 10% 1 L | D16: MED200 | E16: iodopovidona 100 ml sol/topica | F16: Revisar presentación | G16: Baja | H16: Master iodopovidona 10% de 1 litro; San Juan registra 100 ml y omite concentración. Volumen distinto; confirmar además 10%. Fuente: master original, fila 244. | I16: Pendiente | O16: =IF(I16="Pendiente","Pendiente",IF(I16="Equivalente confirmado",IF(OR(J16="",K16=""),"Falta código o nombre",IF(OR(L16="",M16=""),"Falta validación",IF(OR(NOT(ISNUMBER(N16)),N16<=0),"Falta fecha","Homologado"))),IF(I16="Sin equivalente en AVAIN",IF(OR(J16<>"",K16<>""),"Quitar código y nombre",IF(OR(L16="",M16=""),"Falta validación",IF(OR(NOT(ISNUMBER(N16)),N16<=0),"Falta fecha","Sin equivalente confirmado"))),"Revisar decisión"))) -> Pendiente
A17: D-176 | B17: Descartables | C17: Agua oxigenada 1000 ml | D17: DESC9 | E17: Agua oxigenada x 100ml | F17: Revisar presentación | G17: Baja | H17: Master agua oxigenada 1000 ml; San Juan registra 100 ml. Volumen distinto. Fuente: master original, fila 245. | I17: Pendiente | O17: =IF(I17="Pendiente","Pendiente",IF(I17="Equivalente confirmado",IF(OR(J17="",K17=""),"Falta código o nombre",IF(OR(L17="",M17=""),"Falta validación",IF(OR(NOT(ISNUMBER(N17)),N17<=0),"Falta fecha","Homologado"))),IF(I17="Sin equivalente en AVAIN",IF(OR(J17<>"",K17<>""),"Quitar código y nombre",IF(OR(L17="",M17=""),"Falta validación",IF(OR(NOT(ISNUMBER(N17)),N17<=0),"Falta fecha","Sin equivalente confirmado"))),"Revisar decisión"))) -> Pendiente
