Workbook

Sheet Resumen
A1: Inventario físico vs SAP · tablero
A2: Todos los indicadores son FÓRMULAS sobre la hoja «Casos»: si se corrige un dato allí, acá se actualiza solo.
A4: Generado | B4: 30/10/2026, 05:04:24
A5: Revisor | B5: (sin identificar)
A7: UNIVERSO ANALIZADO
A8: Casos totales | B8: =COUNTA(Casos!B5:B100000)
A9: Ítems de los inventarios físicos | B9: =COUNTIF(Casos!C:C,"Inventario físico")
A10: Unidades físicas contadas | B10: =SUMIF(Casos!C:C,"Inventario físico",Casos!O:O)
A12: CLASIFICACIÓN | B12: Casos | C12: Unidades físicas | D12: Stock SAP
A13: A · Identificado en SAP | B13: =COUNTIF(Casos!D:D,"A · Identificado en SAP") | C13: =SUMIF(Casos!D:D,"A · Identificado en SAP",Casos!O:O) | D13: =SUMIF(Casos!D:D,"A · Identificado en SAP",Casos!P:P)
A14: B · Candidato a alta | B14: =COUNTIF(Casos!D:D,"B · Candidato a alta") | C14: =SUMIF(Casos!D:D,"B · Candidato a alta",Casos!O:O) | D14: =SUMIF(Casos!D:D,"B · Candidato a alta",Casos!P:P)
A15: C · Candidato a baja | B15: =COUNTIF(Casos!D:D,"C · Candidato a baja") | C15: =SUMIF(Casos!D:D,"C · Candidato a baja",Casos!O:O) | D15: =SUMIF(Casos!D:D,"C · Candidato a baja",Casos!P:P)
A16: D · Requiere revisión | B16: =COUNTIF(Casos!D:D,"D · Requiere revisión") | C16: =SUMIF(Casos!D:D,"D · Requiere revisión",Casos!O:O) | D16: =SUMIF(Casos!D:D,"D · Requiere revisión",Casos!P:P)
A17: E · Fuera del alcance | B17: =COUNTIF(Casos!D:D,"E · Fuera del alcance") | C17: =SUMIF(Casos!D:D,"E · Fuera del alcance",Casos!O:O) | D17: =SUMIF(Casos!D:D,"E · Fuera del alcance",Casos!P:P)
A19: POR BASE | B19: A | C19: B | D19: C | E19: D | F19: E | G19: Ítems físicos | H19: Unidades físicas
A20: San Juan | B20: =COUNTIFS(Casos!G:G,"San Juan",Casos!D:D,"A · Identificado en SAP") | C20: =COUNTIFS(Casos!G:G,"San Juan",Casos!D:D,"B · Candidato a alta") | D20: =COUNTIFS(Casos!G:G,"San Juan",Casos!D:D,"C · Candidato a baja") | E20: =COUNTIFS(Casos!G:G,"San Juan",Casos!D:D,"D · Requiere revisión") | F20: =COUNTIFS(Casos!G:G,"San Juan",Casos!D:D,"E · Fuera del alcance") | G20: =COUNTIFS(Casos!G:G,"San Juan",Casos!C:C,"Inventario físico") | H20: =SUMIFS(Casos!O:O,Casos!G:G,"San Juan",Casos!C:C,"Inventario físico")
A21: Neuquén | B21: =COUNTIFS(Casos!G:G,"Neuquén",Casos!D:D,"A · Identificado en SAP") | C21: =COUNTIFS(Casos!G:G,"Neuquén",Casos!D:D,"B · Candidato a alta") | D21: =COUNTIFS(Casos!G:G,"Neuquén",Casos!D:D,"C · Candidato a baja") | E21: =COUNTIFS(Casos!G:G,"Neuquén",Casos!D:D,"D · Requiere revisión") | F21: =COUNTIFS(Casos!G:G,"Neuquén",Casos!D:D,"E · Fuera del alcance") | G21: =COUNTIFS(Casos!G:G,"Neuquén",Casos!C:C,"Inventario físico") | H21: =SUMIFS(Casos!O:O,Casos!G:G,"Neuquén",Casos!C:C,"Inventario físico")
A22: Salta | B22: =COUNTIFS(Casos!G:G,"Salta",Casos!D:D,"A · Identificado en SAP") | C22: =COUNTIFS(Casos!G:G,"Salta",Casos!D:D,"B · Candidato a alta") | D22: =COUNTIFS(Casos!G:G,"Salta",Casos!D:D,"C · Candidato a baja") | E22: =COUNTIFS(Casos!G:G,"Salta",Casos!D:D,"D · Requiere revisión") | F22: =COUNTIFS(Casos!G:G,"Salta",Casos!D:D,"E · Fuera del alcance") | G22: =COUNTIFS(Casos!G:G,"Salta",Casos!C:C,"Inventario físico") | H22: =SUMIFS(Casos!O:O,Casos!G:G,"Salta",Casos!C:C,"Inventario físico")
A24: POR TIPO DE MATERIAL | B24: A | C24: B | D24: C | E24: D | F24: E
A25: Descartable | B25: =COUNTIFS(Casos!K:K,"Descartable",Casos!D:D,"A · Identificado en SAP") | C25: =COUNTIFS(Casos!K:K,"Descartable",Casos!D:D,"B · Candidato a alta") | D25: =COUNTIFS(Casos!K:K,"Descartable",Casos!D:D,"C · Candidato a baja") | E25: =COUNTIFS(Casos!K:K,"Descartable",Casos!D:D,"D · Requiere revisión") | F25: =COUNTIFS(Casos!K:K,"Descartable",Casos!D:D,"E · Fuera del alcance")
A26: Equipamiento | B26: =COUNTIFS(Casos!K:K,"Equipamiento",Casos!D:D,"A · Identificado en SAP") | C26: =COUNTIFS(Casos!K:K,"Equipamiento",Casos!D:D,"B · Candidato a alta") | D26: =COUNTIFS(Casos!K:K,"Equipamiento",Casos!D:D,"C · Candidato a baja") | E26: =COUNTIFS(Casos!K:K,"Equipamiento",Casos!D:D,"D · Requiere revisión") | F26: =COUNTIFS(Casos!K:K,"Equipamiento",Casos!D:D,"E · Fuera del alcance")
A27: Indumentaria | B27: =COUNTIFS(Casos!K:K,"Indumentaria",Casos!D:D,"A · Identificado en SAP") | C27: =COUNTIFS(Casos!K:K,"Indumentaria",Casos!D:D,"B · Candidato a alta") | D27: =COUNTIFS(Casos!K:K,"Indumentaria",Casos!D:D,"C · Candidato a baja") | E27: =COUNTIFS(Casos!K:K,"Indumentaria",Casos!D:D,"D · Requiere revisión") | F27: =COUNTIFS(Casos!K:K,"Indumentaria",Casos!D:D,"E · Fuera del alcance")
A28: Medicamento | B28: =COUNTIFS(Casos!K:K,"Medicamento",Casos!D:D,"A · Identificado en SAP") | C28: =COUNTIFS(Casos!K:K,"Medicamento",Casos!D:D,"B · Candidato a alta") | D28: =COUNTIFS(Casos!K:K,"Medicamento",Casos!D:D,"C · Candidato a baja") | E28: =COUNTIFS(Casos!K:K,"Medicamento",Casos!D:D,"D · Requiere revisión") | F28: =COUNTIFS(Casos!K:K,"Medicamento",Casos!D:D,"E · Fuera del alcance")
A29: Repuesto / seguridad | B29: =COUNTIFS(Casos!K:K,"Repuesto / seguridad",Casos!D:D,"A · Identificado en SAP") | C29: =COUNTIFS(Casos!K:K,"Repuesto / seguridad",Casos!D:D,"B · Candidato a alta") | D29: =COUNTIFS(Casos!K:K,"Repuesto / seguridad",Casos!D:D,"C · Candidato a baja") | E29: =COUNTIFS(Casos!K:K,"Repuesto / seguridad",Casos!D:D,"D · Requiere revisión") | F29: =COUNTIFS(Casos!K:K,"Repuesto / seguridad",Casos!D:D,"E · Fuera del alcance")
A31: ESTADO DE LA GESTIÓN
A32: Pendientes de decidir | B32: =COUNTIF(Casos!AH:AH,"Sin decidir")
A33: Correspondencias confirmadas | B33: =COUNTIF(Casos!AH:AH,"Correspondencia confirmada")
A34: Propuestas aprobadas | B34: =COUNTIF(Casos!AH:AH,"Aprobado")
A35: Propuestas rechazadas | B35: =COUNTIF(Casos!AH:AH,"Rechazado")
A36: Marcados como revisados | B36: =COUNTIF(Casos!AG:AG,"Revisado")
A37: Pendientes de validación | B37: =COUNTIF(Casos!AG:AG,"Pendiente de validación")
A38: Casos con observación | B38: =COUNTIF(Casos!AK:AK,"?*")
A39: Códigos corregidos a mano | B39: =COUNTIF(Casos!U:U,"Sí")
A41: VALORIZACIÓN POR PRECIO DE ÚLTIMA COMPRA
A42: Materiales valorizados | B42: =COUNTIF(Casos!Z:Z,"Valorizado por última compra")
A43: Pendientes de valorización | B43: =COUNTIF(Casos!Z:Z,"Pendiente de valorización")
A44: Valorización total por última compra | B44: =SUMIF(Casos!Z:Z,"Valorizado por última compra",Casos!AD:AD)
A45: El precio de última compra no está en los archivos recibidos, así que el total de arriba es 0 y todos los casos figuran como pendientes. Ver la hoja «Metodología».
A47: REFERENCIA DE SAP · NO es precio de última compra
A48: Valor de stock de SAP de los casos, por clasificación. Es el valor contable dividido por las unidades. Se informa aparte y nunca se suma a la valorización por última compra.
...

Sheet Casos
A1: Conciliación de inventarios físicos contra SAP · detalle completo
A2: Una fila por caso. Los ítems de los inventarios físicos más los materiales de SAP que ningún inventario identificó. Las columnas Q, AD y AF son fórmulas. Exportado el 30/10/2026, 05:04:24.
A4: Nº | B4: ID del caso | C4: Origen del registro | D4: Clasificación | E4: Curso de acción sugerido | F4: Motivo de revisión | G4: Base | H4: Centro | I4: Sistema de origen | J4: Informe de origen | K4: Tipo | L4: Código en inventario físico | M4: Nomenclatura del inventario físico | N4: Presentación detectada | O4: Cantidad física · UNIDADES | P4: Stock SAP en la base · UNIDADES | Q4: Cantidad a valorizar · UNIDADES | R4: Nº de lotes | S4: Código SAP · análisis | T4: Código SAP · vigente | U4: ¿Código corregido a mano? | V4: Descripción en SAP | W4: Atributos verificados | X4: Confianza del cruce | Y4: Justificación de la correspondencia | Z4: Estado de valorización | AA4: Precio de última compra · $ | AB4: Fecha de la última compra | AC4: Fuente del precio | AD4: Valorización · $ | AE4: VU de referencia SAP · $ | AF4: Valor de referencia SAP · $ | AG4: Estado de revisión | AH4: Decisión registrada | AI4: Revisor | AJ4: Fecha de la decisión | AK4: Observaciones
A5: 1 | B5: 1120-DESC1 | C5: Inventario físico | D5: A · Identificado en SAP | E5: Registrar existencia en SAP en esta base | G5: San Juan | H5: 1120 | I5: AVAIN | J5: Stock en Almacén · BASE SAN JUAN | K5: Descartable | L5: DESC1 | M5: Abbocath Nº 14 | N5: calibre 14 | O5: 8 | P5: 0 | Q5: =IF(C5="Inventario físico",O5,P5) | R5: 1 | S5: 2000002 | T5: 2000002 | U5: No | V5: CATETER INTRAVENOSO 14G T/ABBOCATH | W5: calibre | X5: Media | Y5: Candidato 2000002 «CATETER INTRAVENOSO 14G T/ABBOCATH». Denominación: 100% del nombre del inventario explicado por el texto de SAP y 32% a la inversa. Atributos verificados: calibre. Sin contradicción en ningún atributo. | Z5: Pendiente de valorización | AC5: No disponible en los archivos recibidos | AD5: =IF(AA5="","Pendiente",AA5*Q5) | AE5: 254.79867 | AF5: =IF(AE5="","",AE5*Q5) | AG5: Pendiente | AH5: Sin decidir
A6: 2 | B6: 1120-DESC2 | C6: Inventario físico | D6: A · Identificado en SAP | E6: Mantener identificación | G6: San Juan | H6: 1120 | I6: AVAIN | J6: Stock en Almacén · BASE SAN JUAN | K6: Descartable | L6: DESC2 | M6: Abbocath Nº 16 | N6: calibre 16 | O6: 202 | P6: 60 | Q6: =IF(C6="Inventario físico",O6,P6) | R6: 2 | S6: 2000003 | T6: 2000003 | U6: No | V6: CATETER INTRAVENOSO 16G T/ABBOCATH | W6: calibre | X6: Media | Y6: Candidato 2000003 «CATETER INTRAVENOSO 16G T/ABBOCATH». Denominación: 100% del nombre del inventario explicado por el texto de SAP y 32% a la inversa. Atributos verificados: calibre. Sin contradicción en ningún atributo. | Z6: Pendiente de valorización | AC6: No disponible en los archivos recibidos | AD6: =IF(AA6="","Pendiente",AA6*Q6) | AE6: 214.29833 | AF6: =IF(AE6="","",AE6*Q6) | AG6: Pendiente | AH6: Sin decidir
A7: 3 | B7: 1120-DESC4 | C7: Inventario físico | D7: A · Identificado en SAP | E7: Mantener identificación | G7: San Juan | H7: 1120 | I7: AVAIN | J7: Stock en Almacén · BASE SAN JUAN | K7: Descartable | L7: DESC4 | M7: Abbocath Nº 20 | N7: calibre 20 | O7: 272 | P7: 870 | Q7: =IF(C7="Inventario físico",O7,P7) | R7: 3 | S7: 2000005 | T7: 2000005 | U7: No | V7: CATETER INTRAVENOSO 20G T/ABBOCATH | W7: calibre | X7: Media | Y7: Candidato 2000005 «CATETER INTRAVENOSO 20G T/ABBOCATH». Denominación: 100% del nombre del inventario explicado por el texto de SAP y 32% a la inversa. Atributos verificados: calibre. Sin contradicción en ningún atributo. | Z7: Pendiente de valorización | AC7: No disponible en los archivos recibidos | AD7: =IF(AA7="","Pendiente",AA7*Q7) | AE7: 176.58761 | AF7: =IF(AE7="","",AE7*Q7) | AG7: Pendiente | AH7: Sin decidir
A8: 4 | B8: 1120-DESC5 | C8: Inventario físico | D8: A · Identificado en SAP | E8: Mantener identificación | G8: San Juan | H8: 1120 | I8: AVAIN | J8: Stock en Almacén · BASE SAN JUAN | K8: Descartable | L8: DESC5 | M8: Abbocath Nº 22 | N8: calibre 22 | O8: 217 | P8: 500 | Q8: =IF(C8="Inventario físico",O8,P8) | R8: 2 | S8: 2000006 | T8: 2000006 | U8: No | V8: CATETER INTRAVENOSO 22G T/ABBOCATH | W8: calibre | X8: Media | Y8: Candidato 2000006 «CATETER INTRAVENOSO 22G T/ABBOCATH». Denominación: 100% del nombre del inventario explicado por el texto de SAP y 32% a la inversa. Atributos verificados: calibre. Sin contradicción en ningún atributo. | Z8: Pendiente de valorización | AC8: No disponible en los archivos recibidos | AD8: =IF(AA8="","Pendiente",AA8*Q8) | AE8: 170.50266 | AF8: =IF(AE8="","",AE8*Q8) | AG8: Pendiente | AH8: Sin decidir
A9: 5 | B9: 1120-MED4 | C9: Inventario físico | D9: D · Requiere revisión | E9: Revisar y decidir | F9: Coincidencia parcial de denominación | G9: San Juan | H9: 1120 | I9: AVAIN | J9: Stock en Almacén · BASE SAN JUAN | K9: Medicamento | L9: MED4 | M9: Acido Acetil Salicílico Comp x 100 mg | N9: concentración 100 mg · forma comprimido | O9: 100 | P9: 0 | Q9: =IF(C9="Inventario físico",O9,P9) | R9: 1 | U9: No | V9: ACIDO ACETILSALICILICO 100MG | W9: concentración | Y9: Candidato 1001237 «ACIDO ACETILSALICILICO 100MG». Denominación: 62% del nombre del inventario explicado por el texto de SAP y 94% a la inversa. Atributos verificados: concentración. La coincidencia de denominación no alcanza para dar la identificación por confirmada. | Z9: Pendiente de valorización | AC9: No disponible en los archivos recibidos | AD9: =IF(AA9="","Pendiente",AA9*Q9) | AF9: =IF(AE9="","",AE9*Q9) | AG9: Pendiente | AH9: Sin decidir
A10: 6 | B10: 1120-MED8 | C10: Inventario físico | D10: A · Identificado en SAP | E10: Mantener identificación | G10: San Juan | H10: 1120 | I10: AVAIN | J10: Stock en Almacén · BASE SAN JUAN | K10: Medicamento | L10: MED8 | M10: Adenosina Amp x 2 ml | N10: forma ampolla · volumen 2 ml | O10: 5 | P10: 7 | Q10: =IF(C10="Inventario físico",O10,P10) | R10: 1 | S10: 1000304 | T10: 1000304 | U10: No | V10: ADENOSINA 2 ML AMP 3 MG/1 ML | W10: forma farmacéutica, volumen / presentación | X10: Alta | Y10: Candidato 1000304 «ADENOSINA 2 ML AMP 3 MG/1 ML». Denominación: 100% del nombre del inventario explicado por el texto de SAP y 100% a la inversa. Atributos verificados: forma farmacéutica, volumen / presentación. Sin contradicción en ningún atributo. | Z10: Pendiente de valorización | AC10: No disponible en los archivos recibidos | AD10: =IF(AA10="","Pendiente",AA10*Q10) | AE10: 879.89714 | AF10: =IF(AE10="","",AE10*Q10) | AG10: Pendiente | AH10: Sin decidir
A11: 7 | B11: 1120-MED9 | C11: Inventario físico | D11: A · Identificado en SAP | E11: Mantener identificación | G11: San Juan | H11: 1120 | I11: AVAIN | J11: Stock en Almacén · BASE SAN JUAN | K11: Medicamento | L11: MED9 | M11: Adrenalina amp 1 ml | N11: forma ampolla · volumen 1 ml | O11: 41 | P11: 104 | Q11: =IF(C11="Inventario físico",O11,P11) | R11: 1 | S11: 1000002 | T11: 1000002 | U11: No | V11: ADRENALINA 1MG AMPOLLA DE 1 ML INYEC | W11: forma farmacéutica, volumen / presentación | X11: Alta | Y11: Candidato 1000002 «ADRENALINA 1MG AMPOLLA DE 1 ML INYEC». Denominación: 100% del nombre del inventario explicado por el texto de SAP y 100% a la inversa. Atributos verificados: forma farmacéutica, volumen / presentación. Sin contradicción en ningún atributo. | Z11: Pendiente de valorización | AC11: No disponible en los archivos recibidos | AD11: =IF(AA11="","Pendiente",AA11*Q11) | AE11: 310.67721 | AF11: =IF(AE11="","",AE11*Q11) | AG11: Pendiente | AH11: Sin decidir
A12: 8 | B12: 1120-DESC291 | C12: Inventario físico | D12: A · Identificado en SAP | E12: Registrar existencia en SAP en esta base | G12: San Juan | H12: 1120 | I12: AVAIN | J12: Stock en Almacén · BASE SAN JUAN | K12: Medicamento | L12: DESC291 | M12: Agua Oxigenada 10 Vol x 500 ml | N12: volumen 500 ml · cantidad sin unidad 10 | O12: 3 | P12: 0 | Q12: =IF(C12="Inventario físico",O12,P12) | R12: 2 | S12: 1000052 | T12: 1000052 | U12: No | V12: AGUA OXIGENADA 10 VOL. X 500ML | W12: volumen / presentación, cantidad o dosis sin unidad | X12: Alta | Y12: Candidato 1000052 «AGUA OXIGENADA 10 VOL. X 500ML». Denominación: 100% del nombre del inventario explicado por el texto de SAP y 100% a la inversa. Atributos verificados: volumen / presentación, cantidad o dosis sin unidad. Sin contradicción en ningún atributo. | Z12: Pendiente de valorización | AC12: No disponible en los archivos recibidos | AD12: =IF(AA12="","Pendiente",AA12*Q12) | AE12: 542.5805 | AF12: =IF(AE12="","",AE12*Q12) | AG12: Pendiente | AH12: Sin decidir
A13: 9 | B13: 1120-DESC9 | C13: Inventario físico | D13: A · Identificado en SAP | E13: Mantener identificación | G13: San Juan | H13: 1120 | I13: AVAIN | J13: Stock en Almacén · BASE SAN JUAN | K13: Medicamento | L13: DESC9 | M13: Agua oxigenada x 100ml | N13: volumen 100 ml | O13: 11 | P13: 15 | Q13: =IF(C13="Inventario físico",O13,P13) | R13: 1 | S13: 1000004 | T13: 1000004 | U13: No | V13: AGUA OXIGENADA 10 VOL. X 100ML | W13: volumen / presentación | X13: Alta | Y13: Candidato 1000004 «AGUA OXIGENADA 10 VOL. X 100ML». Denominación: 100% del nombre del inventario explicado por el texto de SAP y 64% a la inversa. Atributos verificados: volumen / presentación. Sin contradicción en ningún atributo. | Z13: Pendiente de valorización | AC13: No disponible en los archivos recibidos | AD13: =IF(AA13="","Pendiente",AA13*Q13) | AE13: 335.13333 | AF13: =IF(AE13="","",AE13*Q13) | AG13: Pendiente | AH13: Sin decidir
A14: 10 | B14: 1120-DESC10 | C14: Inventario físico | D14: A · Identificado en SAP | E14: Mantener identificación | G14: San Juan | H14: 1120 | I14: AVAIN | J14: Stock en Almacén · BASE SAN JUAN | K14: Medicamento | L14: DESC10 | M14: Aguja 40/12 | N14: calibre 40/12 | O14: 20 | P14: 95 | Q14: =IF(C14="Inventario físico",O14,P14) | R14: 1 | S14: 1000772 | T14: 1000772 | U14: No | V14: AGUJA 40/12 | W14: calibre | X14: Alta | Y14: Candidato 1000772 «AGUJA 40/12». Denominación: 100% del nombre del inventario explicado por el texto de SAP y 100% a la inversa. Atributos verificados: calibre. Sin contradicción en ningún atributo. | Z14: Pendiente de valorización | AC14: No disponible en los archivos recibidos | AD14: =IF(AA14="","Pendiente",AA14*Q14) | AE14: 174.82526 | AF14: =IF(AE14="","",AE14*Q14) | AG14: Pendiente | AH14: Sin decidir
A15: 11 | B15: 1120-DESC11 | C15: Inventario físico | D15: A · Identificado en SAP | E15: Mantener identificación | G15: San Juan | H15: 1120 | I15: AVAIN | J15: Stock en Almacén · BASE SAN JUAN | K15: Descartable | L15: DESC11 | M15: Agujas 16/5 | N15: calibre 16/5 | O15: 300 | P15: 1020 | Q15: =IF(C15="Inventario físico",O15,P15) | R15: 1 | S15: 2000007 | T15: 2000007 | U15: No | V15: AGUJA HIPODERMICA 25G x ⅝ - 16/5 | W15: calibre | X15: Media | Y15: Candidato 2000007 «AGUJA HIPODERMICA 25G x ⅝ - 16/5». Denominación: 90% del nombre del inventario explicado por el texto de SAP y 41% a la inversa. Atributos verificados: calibre. Sin contradicción en ningún atributo. | Z15: Pendiente de valorización | AC15: No disponible en los archivos recibidos | AD15: =IF(AA15="","Pendiente",AA15*Q15) | AE15: 27.725941 | AF15: =IF(AE15="","",AE15*Q15) | AG15: Pendiente | AH15: Sin decidir
A16: 12 | B16: 1120-DESC12 | C16: Inventario físico | D16: A · Identificado en SAP | E16: Mantener identificación | G16: San Juan | H16: 1120 | I16: AVAIN | J16: Stock en Almacén · BASE SAN JUAN | K16: Descartable | L16: DESC12 | M16: Agujas 25/8 | N16: calibre 25/8 | O16: 975 | P16: 1548 | Q16: =IF(C16="Inventario físico",O16,P16) | R16: 1 | S16: 2000008 | T16: 2000008 | U16: No | V16: AGUJA HIPODERMICA 21G x 1 - 25/8 | W16: calibre | X16: Media | Y16: Candidato 2000008 «AGUJA HIPODERMICA 21G x 1 - 25/8». Denominación: 90% del nombre del inventario explicado por el texto de SAP y 41% a la inversa. Atributos verificados: calibre. Sin contradicción en ningún atributo. | Z16: Pendiente de valorización | AC16: No disponible en los archivos recibidos | AD16: =IF(AA16="","Pendiente",AA16*Q16) | AE16: 24.974767 | AF16: =IF(AE16="","",AE16*Q16) | AG16: Pendiente | AH16: Sin decidir
A17: 13 | B17: 1120-DESC13 | C17: Inventario físico | D17: A · Identificado en SAP | E17: Mantener identificación | G17: San Juan | H17: 1120 | I17: AVAIN | J17: Stock en Almacén · BASE SAN JUAN | K17: Descartable | L17: DESC13 | M17: Agujas 40/8 | N17: calibre 40/8 | O17: 100 | P17: 1229 | Q17: =IF(C17="Inventario físico",O17,P17) | R17: 1 | S17: 2000009 | T17: 2000009 | U17: No | V17: AGUJA HIPODERMICA 21G x 1 ½ - 40/8 | W17: calibre | X17: Media | Y17: Candidato 2000009 «AGUJA HIPODERMICA 21G x 1 ½ - 40/8». Denominación: 90% del nombre del inventario explicado por el texto de SAP y 41% a la inversa. Atributos verificados: calibre. Sin contradicción en ningún atributo. | Z17: Pendiente de valorización | AC17: No disponible en los archivos recibidos | AD17: =IF(AA17="","Pendiente",AA17*Q17) | AE17: 55.786672 | AF17: =IF(AE17="","",AE17*Q17) | AG17: Pendiente | AH17: Sin decidir
A18: 14 | B18: 1120-DESC14 | C18: Inventario físico | D18: A · Identificado en SAP | E18: Mantener identificación | G18: San Juan | H18: 1120 | I18: AVAIN | J18: Stock en Almacén · BASE SAN JUAN | K18: Medicamento | L18: DESC14 | M18: Alcohol 70% x 1000 ml | N18: concentración 70% · volumen 1000 ml | O18: 9 | P18: 91 | Q18: =IF(C18="Inventario físico",O18,P18) | R18: 1 | S18: 1000017 | T18: 1000017 | U18: No | V18: ALCOHOL AL 70% X 1000ML | W18: concentración, volumen / presentación | X18: Alta | Y18: Candidato 1000017 «ALCOHOL AL 70% X 1000ML». Denominación: 100% del nombre del inventario explicado por el texto de SAP y 100% a la inversa. Atributos verificados: concentración, volumen / presentación. Sin contradicción en ningún atributo. | Z18: Pendiente de valorización | AC18: No disponible en los archivos recibidos | AD18: =IF(AA18="","Pendiente",AA18*Q18) | AE18: 2977.7323 | AF18: =IF(AE18="","",AE18*Q18) | AG18: Pendiente | AH18: Sin decidir
A19: 15 | B19: 1120-DESC15 | C19: Inventario físico | D19: A · Identificado en SAP | E19: Mantener identificación | G19: San Juan | H19: 1120 | I19: AVAIN | J19: Stock en Almacén · BASE SAN JUAN | K19: Medicamento | L19: DESC15 | M19: Alcohol 96% x 1000ml | N19: concentración 96% · volumen 1000 ml | O19: 3 | P19: 51 | Q19: =IF(C19="Inventario físico",O19,P19) | R19: 1 | S19: 1000053 | T19: 1000053 | U19: No | V19: ALCOHOL AL 96% X 1000ML | W19: concentración, volumen / presentación | X19: Alta | Y19: Candidato 1000053 «ALCOHOL AL 96% X 1000ML». Denominación: 100% del nombre del inventario explicado por el texto de SAP y 100% a la inversa. Atributos verificados: concentración, volumen / presentación. Sin contradicción en ningún atributo. | Z19: Pendiente de valorización | AC19: No disponible en los archivos recibidos | AD19: =IF(AA19="","Pendiente",AA19*Q19) | AE19: 2606.5129 | AF19: =IF(AE19="","",AE19*Q19) | AG19: Pendiente | AH19: Sin decidir
A20: 16 | B20: 1120-DESC16 | C20: Inventario físico | D20: A · Identificado en SAP | E20: Registrar existencia en SAP en esta base | G20: San Juan | H20: 1120 | I20: AVAIN | J20: Stock en Almacén · BASE SAN JUAN | K20: Medicamento | L20: DESC16 | M20: Alcohol 96% x 500ml | N20: concentración 96% · volumen 500 ml | O20: 2 | P20: 0 | Q20: =IF(C20="Inventario físico",O20,P20) | R20: 1 | S20: 1000054 | T20: 1000054 | U20: No | V20: ALCOHOL AL 96% X 500ML | W20: concentración, volumen / presentación | X20: Alta | Y20: Candidato 1000054 «ALCOHOL AL 96% X 500ML». Denominación: 100% del nombre del inventario explicado por el texto de SAP y 100% a la inversa. Atributos verificados: concentración, volumen / presentación. Sin contradicción en ningún atributo. | Z20: Pendiente de valorización | AC20: No disponible en los archivos recibidos | AD20: =IF(AA20="","Pendiente",AA20*Q20) | AE20: 449.91858 | AF20: =IF(AE20="","",AE20*Q20) | AG20: Pendiente | AH20: Sin decidir
A21: 17 | B21: 1120-DESC18 | C21: Inventario físico | D21: A · Identificado en SAP | E21: Mantener identificación | G21: San Juan | H21: 1120 | I21: AVAIN | J21: Stock en Almacén · BASE SAN JUAN | K21: Medicamento | L21: DESC18 | M21: Alcohol en gel x 500 ml | N21: forma crema · volumen 500 ml | O21: 16 | P21: 48 | Q21: =IF(C21="Inventario físico",O21,P21) | R21: 1 | S21: 1000058 | T21: 1000058 | U21: No | V21: ALCOHOL EN GEL X 500ML | W21: forma farmacéutica, volumen / presentación | X21: Alta | Y21: Candidato 1000058 «ALCOHOL EN GEL X 500ML». Denominación: 100% del nombre del inventario explicado por el texto de SAP y 100% a la inversa. Atributos verificados: forma farmacéutica, volumen / presentación. Sin contradicción en ningún atributo. | Z21: Pendiente de valorización | AC21: No disponible en los archivos recibidos | AD21: =IF(AA21="","Pendiente",AA21*Q21) | AE21: 1052.1065 | AF21: =IF(AE21="","",AE21*Q21) | AG21: Pendiente | AH21: Sin decidir
... A23: 19 | B23: 1120-MED11 | C23: Inventario físico | D23: A · Identificado en SAP | E23: Mantener identificación | G23: San Juan | H23: 1120 | I23: AVAIN | J23: Stock en Almacén · BASE SAN JUAN | K23: Medicamento | L23: MED11 | M23: Amiodarona 150 mg Amp x 3 ml | N23: concentración 150 mg · forma ampolla · volumen 3 ml | O23: 75 | P23: 55 | Q23: =IF(C23="Inventario físico",O23,P23) | R23: 1 | S23: 1000005 | T23: 1000005 | U23: No | V23: AMIODARONA 150MG AMPOLLA DE 3 ML INYEC | W23: concentración, forma farmacéutica, volumen / presentación | X23: Alta | Y23: Candidato 1000005 «AMIODARONA 150MG AMPOLLA DE 3 ML INYEC». Denominación: 100% del nombre del inventario explicado por el texto de SAP y 100% a la inversa. Atributos verificados: concentración, forma farmacéutica, volumen / presentación. Sin contradicción en ningún atributo. | Z23: Pendiente de valorización | AC23: No disponible en los archivos recibidos | AD23: =IF(AA23="","Pendiente",AA23*Q23) | AE23: 1983.4744 | AF23: =IF(AE23="","",AE23*Q23) | AG23: Pendiente | AH23: Sin decidir
A24: 20 | B24: 1120-MED186 | C24: Inventario físico | D24: D · Requiere revisión | E24: Revisar y decidir | F24: Conflicto de presentación | G24: San Juan | H24: 1120 | I24: AVAIN | J24: Stock en Almacén · BASE SAN JUAN | K24: Medicamento | L24: MED186 | M24: amiodarona 200mg comp | N24: concentración 200 mg · forma comprimido | O24: 20 | P24: 0 | Q24: =IF(C24="Inventario físico",O24,P24) | R24: 1 | U24: No | Y24: El candidato más parecido es 1000005 «AMIODARONA 150MG AMPOLLA DE 3 ML INYEC», pero difiere en concentración, forma farmacéutica. No se asigna el código: una diferencia de presentación significa que no es el mismo material. | Z24: Pendiente de valorización | AC24: No disponible en los archivos recibidos | AD24: =IF(AA24="","Pendiente",AA24*Q24) | AF24: =IF(AE24="","",AE24*Q24) | AG24: Pendiente | AH24: Sin decidir
A25: 21 | B25: 1120-MED14 | C25: Inventario físico | D25: D · Requiere revisión | E25: Revisar y decidir | F25: Conflicto de presentación | G25: San Juan | H25: 1120 | I25: AVAIN | J25: Stock en Almacén · BASE SAN JUAN | K25: Medicamento | L25: MED14 | M25: Amoxicilina + Clavulanato Comp x 1 mg | N25: concentración 1 mg · forma comprimido | O25: 371 | P25: 0 | Q25: =IF(C25="Inventario físico",O25,P25) | R25: 1 | U25: No | Y25: El candidato más parecido es 1005299 «AMOXICILINA +AC. CLAVULONICO 1GR COMP», pero difiere en concentración. No se asigna el código: una diferencia de presentación significa que no es el mismo material. | Z25: Pendiente de valorización | AC25: No disponible en los archivos recibidos | AD25: =IF(AA25="","Pendiente",AA25*Q25) | AF25: =IF(AE25="","",AE25*Q25) | AG25: Pendiente | AH25: Sin decidir
A26: 22 | B26: 1120-MED156 | C26: Inventario físico | D26: D · Requiere revisión | E26: Revisar y decidir | F26: Varios códigos SAP posibles | G26: San Juan | H26: 1120 | I26: AVAIN | J26: Stock en Almacén · BASE SAN JUAN | K26: Medicamento | L26: MED156 | M26: Antigripal comp | N26: forma comprimido | O26: 60 | P26: 0 | Q26: =IF(C26="Inventario físico",O26,P26) | R26: 1 | U26: No | W26: forma farmacéutica | Y26: Candidato 1001216 «TAVINEX ANTIGRIPAL COMP.». Denominación: 100% del nombre del inventario explicado por el texto de SAP y 48% a la inversa. Atributos verificados: forma farmacéutica. Pero 1001297 «PULMONIX ANTIGRIP 20 COMP» es igual de plausible. Hay que elegir cuál corresponde. | Z26: Pendiente de valorización | AC26: No disponible en los archivos recibidos | AD26: =IF(AA26="","Pendiente",AA26*Q26) | AF26: =IF(AE26="","",AE26*Q26) | AG26: Pendiente | AH26: Sin decidir
A27: 23 | B27: 1120-DESC21 | C27: Inventario físico | D27: D · Requiere revisión | E27: Revisar y decidir | F27: Falta un atributo para confirmar la presentación | G27: San Juan | H27: 1120 | I27: AVAIN | J27: Stock en Almacén · BASE SAN JUAN | K27: Descartable | L27: DESC21 | M27: Apositos estériles | O27: 160 | P27: 0 | Q27: =IF(C27="Inventario físico",O27,P27) | R27: 1 | U27: No | V27: APOSITO NO ESTERIL (G+A) 10X20CM | Y27: Candidato 2000095 «APOSITO NO ESTERIL (G+A) 10X20CM». Denominación: 52% del nombre del inventario explicado por el texto de SAP y 42% a la inversa. Sap declara la presentación y el inventario físico no, así que la equivalencia no puede confirmarse con la información disponible. | Z27: Pendiente de valorización | AC27: No disponible en los archivos recibidos | AD27: =IF(AA27="","Pendiente",AA27*Q27) | AF27: =IF(AE27="","",AE27*Q27) | AG27: Pendiente | AH27: Sin decidir
A28: 24 | B28: 1120-MED16 | C28: Inventario físico | D28: A · Identificado en SAP | E28: Mantener identificación | G28: San Juan | H28: 1120 | I28: AVAIN | J28: Stock en Almacén · BASE SAN JUAN | K28: Medicamento | L28: MED16 | M28: Atenolol Comp x 50 mg | N28: concentración 50 mg · forma comprimido | O28: 25 | P28: 29 | Q28: =IF(C28="Inventario físico",O28,P28) | R28: 2 | S28: 1005233 | T28: 1005233 | U28: No | V28: ATENOLOL 50MG X 10COMP | W28: concentración, forma farmacéutica | X28: Alta | Y28: Candidato 1005233 «ATENOLOL 50MG X 10COMP». Denominación: 100% del nombre del inventario explicado por el texto de SAP y 49% a la inversa. Atributos verificados: concentración, forma farmacéutica. Sin contradicción en ningún atributo. | Z28: Pendiente de valorización | AC28: No disponible en los archivos recibidos | AD28: =IF(AA28="","Pendiente",AA28*Q28) | AE28: 800.31586 | AF28: =IF(AE28="","",AE28*Q28) | AG28: Pendiente | AH28: Sin decidir
A29: 25 | B29: 1120-MED18 | C29: Inventario físico | D29: A · Identificado en SAP | E29: Mantener identificación | G29: San Juan | H29: 1120 | I29: AVAIN | J29: Stock en Almacén · BASE SAN JUAN | K29: Medicamento | L29: MED18 | M29: Azitromicina Comp x 500 mg | N29: concentración 500 mg · forma comprimido | O29: 6 | P29: 164 | Q29: =IF(C29="Inventario físico",O29,P29) | R29: 1 | S29: 1000486 | T29: 1000486 | U29: No | V29: AZITROMICINA 500 MG COMP | W29: concentración, forma farmacéutica | X29: Alta | Y29: Candidato 1000486 «AZITROMICINA 500 MG COMP». Denominación: 100% del nombre del inventario explicado por el texto de SAP y 100% a la inversa. Atributos verificados: concentración, forma farmacéutica. Sin contradicción en ningún atributo. | Z29: Pendiente de valorización | AC29: No disponible en los archivos recibidos | AD29: =IF(AA29="","Pendiente",AA29*Q29) | AE29: 441.36567 | AF29: =IF(AE29="","",AE29*Q29) | AG29: Pendiente | AH29: Sin decidir
A30: 26 | B30: 1120-DESC22 | C30: Inventario físico | D30: D · Requiere revisión | E30: Revisar y decidir | F30: Coincidencia parcial de denominación | G30: San Juan | H30: 1120 | I30: AVAIN | J30: Stock en Almacén · BASE SAN JUAN | K30: Descartable | L30: DESC22 | M30: Bajalenguas x 1 ud | O30: 1800 | P30: 0 | Q30: =IF(C30="Inventario físico",O30,P30) | R30: 1 | U30: No | V30: BAJALENGUAS DE MADERA | Y30: Candidato 2000011 «BAJALENGUAS DE MADERA». Denominación: 100% del nombre del inventario explicado por el texto de SAP y 48% a la inversa. La coincidencia de denominación no alcanza para dar la identificación por confirmada. | Z30: Pendiente de valorización | AC30: No disponible en los archivos recibidos | AD30: =IF(AA30="","Pendiente",AA30*Q30) | AF30: =IF(AE30="","",AE30*Q30) | AG30: Pendiente | AH30: Sin decidir
A31: 27 | B31: 1120-DESC24 | C31: Inventario físico | D31: D · Requiere revisión | E31: Revisar y decidir | F31: Coincidencia parcial de denominación | G31: San Juan | H31: 1120 | I31: AVAIN | J31: Stock en Almacén · BASE SAN JUAN | K31: Descartable | L31: DESC24 | M31: Barbijos N95 c/válvula | O31: 10 | P31: 0 | Q31: =IF(C31="Inventario físico",O31,P31) | R31: 1 | U31: No | V31: VALVULA ESPIRATORIA | Y31: Candidato 2001024 «VALVULA ESPIRATORIA». Denominación: 33% del nombre del inventario explicado por el texto de SAP y 48% a la inversa. La coincidencia de denominación no alcanza para dar la identificación por confirmada. | Z31: Pendiente de valorización | AC31: No disponible en los archivos recibidos | AD31: =IF(AA31="","Pendiente",AA31*Q31) | AF31: =IF(AE31="","",AE31*Q31) | AG31: Pendiente | AH31: Sin decidir
A32: 28 | B32: 1120-DESC25 | C32: Inventario físico | D32: D · Requiere revisión | E32: Revisar y decidir | F32: Coincidencia parcial de denominación | G32: San Juan | H32: 1120 | I32: AVAIN | J32: Stock en Almacén · BASE SAN JUAN | K32: Descartable | L32: DESC25 | M32: Barbijos quirúrgicos x 1 ud | O32: 350 | P32: 0 | Q32: =IF(C32="Inventario físico",O32,P32) | R32: 1 | U32: No | V32: TIJERA QUIRURGICA | Y32: Candidato 2001378 «TIJERA QUIRURGICA». Denominación: 46% del nombre del inventario explicado por el texto de SAP y 47% a la inversa. La coincidencia de denominación no alcanza para dar la identificación por confirmada. | Z32: Pendiente de valorización | AC32: No disponible en los archivos recibidos | AD32: =IF(AA32="","Pendiente",AA32*Q32) | AF32: =IF(AE32="","",AE32*Q32) | AG32: Pendiente | AH32: Sin decidir
A33: 29 | B33: 1120-DESC26 | C33: Inventario físico | D33: D · Requiere revisión | E33: Revisar y decidir | F33: Falta un atributo para confirmar la presentación | G33: San Juan | H33: 1120 | I33: AVAIN | J33: Stock en Almacén · BASE SAN JUAN | K33: Descartable | L33: DESC26 | M33: Bolsa Colectora de orina T/K-207 | N33: modelo K207 | O33: 3 | P33: 0 | Q33: =IF(C33="Inventario físico",O33,P33) | R33: 1 | U33: No | V33: BOLSA COLECTORA DE ORINA X 2000 ML | Y33: Candidato 2000100 «BOLSA COLECTORA DE ORINA X 2000 ML». Denominación: 100% del nombre del inventario explicado por el texto de SAP y 100% a la inversa. El inventario físico declara la presentación y SAP no, así que la equivalencia no puede confirmarse con la información disponible. | Z33: Pendiente de valorización | AC33: No disponible en los archivos recibidos | AD33: =IF(AA33="","Pendiente",AA33*Q33) | AF33: =IF(AE33="","",AE33*Q33) | AG33: Pendiente | AH33: Sin decidir
A34: 30 | B34: 1120-DESC27 | C34: Inventario físico | D34: D · Requiere revisión | E34: Revisar y decidir | F34: Coincidencia parcial de denominación | G34: San Juan | H34: 1120 | I34: AVAIN | J34: Stock en Almacén · BASE SAN JUAN | K34: Descartable | L34: DESC27 | M34: Bolsa de Resucitación manual (tipo Ambú) con reservorio adulto | N34: población adulto | O34: 6 | P34: 0 | Q34: =IF(C34="Inventario físico",O34,P34) | R34: 1 | U34: No | V34: MASCARA PARA O2 ADULTO CON RESERVORIO | W34: población | Y34: Candidato 2000363 «MASCARA PARA O2 ADULTO CON RESERVORIO». Denominación: 39% del nombre del inventario explicado por el texto de SAP y 68% a la inversa. Atributos verificados: población. La coincidencia de denominación no alcanza para dar la identificación por confirmada. | Z34: Pendiente de valorización | AC34: No disponible en los archivos recibidos | AD34: =IF(AA34="","Pendiente",AA34*Q34) | AF34: =IF(AE34="","",AE34*Q34) | AG34: Pendiente | AH34: Sin decidir
A35: 31 | B35: 1120-DESC285 | C35: Inventario físico | D35: D · Requiere revisión | E35: Revisar y decidir | F35: Falta un atributo para confirmar la presentación | G35: San Juan | H35: 1120 | I35: AVAIN | J35: Stock en Almacén · BASE SAN JUAN | K35: Descartable | L35: DESC285 | M35: Brazalete para Tensiómetro | O35: 2 | P35: 0 | Q35: =IF(C35="Inventario físico",O35,P35) | R35: 1 | U35: No | V35: BRAZALETE ADULTO | Y35: Candidato 2001483 «BRAZALETE ADULTO». Denominación: 54% del nombre del inventario explicado por el texto de SAP y 59% a la inversa. Sap declara la presentación y el inventario físico no, así que la equivalencia no puede confirmarse con la información disponible. | Z35: Pendiente de valorización | AC35: No disponible en los archivos recibidos | AD35: =IF(AA35="","Pendiente",AA35*Q35) | AF35: =IF(AE35="","",AE35*Q35) | AG35: Pendiente | AH35: Sin decidir
A36: 32 | B36: 1120-MED25 | C36: Inventario físico | D36: A · Identificado en SAP | E36: Mantener identificación | G36: San Juan | H36: 1120 | I36: AVAIN | J36: Stock en Almacén · BASE SAN JUAN | K36: Medicamento | L36: MED25 | M36: Budesonide (gotas para NBZ) x 20ml | N36: forma gotas · volumen 20 ml | O36: 2 | P36: 20 | Q36: =IF(C36="Inventario físico",O36,P36) | R36: 1 | S36: 1000381 | T36: 1000381 | U36: No | V36: BUDESONIDA DENVER SOL 20ML | W36: volumen / presentación | X36: Media | Y36: Candidato 1000381 «BUDESONIDA DENVER SOL 20ML». Denominación: 90% del nombre del inventario explicado por el texto de SAP y 32% a la inversa. Atributos verificados: volumen / presentación. Sin contradicción en ningún atributo. | Z36: Pendiente de valorización | AC36: No disponible en los archivos recibidos | AD36: =IF(AA36="","Pendiente",AA36*Q36) | AE36: 8615.0595 | AF36: =IF(AE36="","",AE36*Q36) | AG36: Pendiente | AH36: Sin decidir
A37: 33 | B37: 1120-DESC35 | C37: Inventario físico | D37: B · Candidato a alta | E37: Proponer alta de material nuevo | G37: San Juan | H37: 1120 | I37: AVAIN | J37: Stock en Almacén · BASE SAN JUAN | K37: Descartable | L37: DESC35 | M37: Canula de Yankauer T/K 67 | N37: modelo K67 | O37: 6 | P37: 0 | Q37: =IF(C37="Inventario físico",O37,P37) | R37: 2 | U37: No | Y37: No se encontró en SAP ningún material cuya denominación y presentación se correspondan con este ítem. | Z37: Pendiente de valorización | AC37: No disponible en los archivos recibidos | AD37: =IF(AA37="","Pendiente",AA37*Q37) | AF37: =IF(AE37="","",AE37*Q37) | AG37: Pendiente | AH37: Sin decidir
A38: 34 | B38: 1120-DESC36 | C38: Inventario físico | D38: D · Requiere revisión | E38: Revisar y decidir | F38: Falta un atributo para confirmar la presentación | G38: San Juan | H38: 1120 | I38: AVAIN | J38: Stock en Almacén · BASE SAN JUAN | K38: Descartable | L38: DESC36 | M38: Canula nasal | O38: 1316 | P38: 0 | Q38: =IF(C38="Inventario físico",O38,P38) | R38: 2 | U38: No | V38: CANULA NASAL O2T SIL 100% COD 230-09 PED | Y38: Candidato 2000103 «CANULA NASAL O2T SIL 100% COD 230-09 PED». Denominación: 100% del nombre del inventario explicado por el texto de SAP y 30% a la inversa. Sap declara la presentación y el inventario físico no, así que la equivalencia no puede confirmarse con la información disponible. | Z38: Pendiente de valorización | AC38: No disponible en los archivos recibidos | AD38: =IF(AA38="","Pendiente",AA38*Q38) | AF38: =IF(AE38="","",AE38*Q38) | AG38: Pendiente | AH38: Sin decidir
A39: 35 | B39: 1120-DESC280 | C39: Inventario físico | D39: D · Requiere revisión | E39: Revisar y decidir | F39: Falta un atributo para confirmar la presentación | G39: San Juan | H39: 1120 | I39: AVAIN | J39: Stock en Almacén · BASE SAN JUAN | K39: Descartable | L39: DESC280 | M39: Canula Orofaringea N° 8 | N39: calibre N° 8 | O39: 3 | P39: 0 | Q39: =IF(C39="Inventario físico",O39,P39) | R39: 1 | U39: No | V39: KIT CANULAS OROFARINGEAS (TUBOS DE MAYO) | Y39: Candidato 2000659 «KIT CANULAS OROFARINGEAS (TUBOS DE MAYO)». Denominación: 90% del nombre del inventario explicado por el texto de SAP y 63% a la inversa. El inventario físico declara la presentación y SAP no, así que la equivalencia no puede confirmarse con la información disponible. | Z39: Pendiente de valorización | AC39: No disponible en los archivos recibidos | AD39: =IF(AA39="","Pendiente",AA39*Q39) | AF39: =IF(AE39="","",AE39*Q39) | AG39: Pendiente | AH39: Sin decidir
A40: 36 | B40: 1120-MED30 | C40: Inventario físico | D40: D · Requiere revisión | E40: Revisar y decidir | F40: Falta un atributo para confirmar la presentación | G40: San Juan | H40: 1120 | I40: AVAIN | J40: Stock en Almacén · BASE SAN JUAN | K40: Medicamento | L40: MED30 | M40: Caramelos antigripales con benzocaina 20.7mg | N40: concentración 20,7 mg | O40: 351 | P40: 0 | Q40: =IF(C40="Inventario físico",O40,P40) | R40: 1 | U40: No | V40: PULMONIX ANTIGRIP 20 COMP | Y40: Candidato 1001297 «PULMONIX ANTIGRIP 20 COMP». Denominación: 31% del nombre del inventario explicado por el texto de SAP y 45% a la inversa. El inventario físico declara la presentación y SAP no, así que la equivalencia no puede confirmarse con la información disponible. | Z40: Pendiente de valorización | AC40: No disponible en los archivos recibidos | AD40: =IF(AA40="","Pendiente",AA40*Q40) | AF40: =IF(AE40="","",AE40*Q40) | AG40: Pendiente | AH40: Sin decidir
A41: 37 | B41: 1120-DESC281 | C41: Inventario físico | D41: D · Requiere revisión | E41: Revisar y decidir | F41: Coincidencia parcial de denominación | G41: San Juan | H41: 1120 | I41: AVAIN | J41: Stock en Almacén · BASE SAN JUAN | K41: Descartable | L41: DESC281 | M41: Chata Plástica | O41: 5 | P41: 0 | Q41: =IF(C41="Inventario físico",O41,P41) | R41: 1 | U41: No | V41: ANTIPARRA DE PLASTICO | Y41: Candidato 2000010 «ANTIPARRA DE PLASTICO». Denominación: 45% del nombre del inventario explicado por el texto de SAP y 45% a la inversa. La coincidencia de denominación no alcanza para dar la identificación por confirmada. | Z41: Pendiente de valorización | AC41: No disponible en los archivos recibidos | AD41: =IF(AA41="","Pendiente",AA41*Q41) | AF41: =IF(AE41="","",AE41*Q41) | AG41: Pendiente | AH41: Sin decidir
A42: 38 | B42: 1120-DESC43 | C42: Inventario físico | D42: B · Candidato a alta | E42: Proponer alta de material nuevo | G42: San Juan | H42: 1120 | I42: AVAIN | J42: Stock en Almacén · BASE SAN JUAN | K42: Descartable | L42: DESC43 | M42: Cintas de aproximacion tipo SteriStrip (3 mm x 7,5 cm) | N42: longitud 0,3 cm, 7,5 cm | O42: 2 | P42: 0 | Q42: =IF(C42="Inventario físico",O42,P42) | R42: 1 | U42: No | Y42: No se encontró en SAP ningún material cuya denominación y presentación se correspondan con este ítem. | Z42: Pendiente de valorización | AC42: No disponible en los archivos recibidos | AD42: =IF(AA42="","Pendiente",AA42*Q42) | AF42: =IF(AE42="","",AE42*Q42) | AG42: Pendiente | AH42: Sin decidir
...

Sheet A Identificados
A1: Materiales físicos identificados en SAP
A2: Existen en el inventario físico y tienen un código de SAP cuya nomenclatura y presentación se corresponden. No hay que darlos de alta.
A4: Nº | B4: Base | C4: Tipo | D4: Código SAP | E4: Descripción en SAP | F4: Código inventario físico | G4: Nomenclatura del inventario físico | H4: Presentación | I4: Cantidad física · UNIDADES | J4: Stock SAP · UNIDADES | K4: Atributos verificados | L4: Confianza | M4: Justificación | N4: Estado de valorización | O4: VU de referencia SAP · $ | P4: Valor de referencia SAP · $ | Q4: Estado de revisión | R4: Decisión registrada | S4: Revisor | T4: Observaciones
A5: 1 | B5: San Juan | C5: Descartable | D5: 2000002 | E5: CATETER INTRAVENOSO 14G T/ABBOCATH | F5: DESC1 | G5: Abbocath Nº 14 | H5: calibre 14 | I5: 8 | J5: 0 | K5: calibre | L5: Media | M5: Candidato 2000002 «CATETER INTRAVENOSO 14G T/ABBOCATH». Denominación: 100% del nombre del inventario explicado por el texto de SAP y 32% a la inversa. Atributos verificados: calibre. Sin contradicción en ningún atributo. | N5: Pendiente de valorización | O5: 254.79867 | P5: =IF(O5="","",O5*MAX(I5,J5)) | Q5: Pendiente | R5: Sin decidir
A6: 2 | B6: San Juan | C6: Descartable | D6: 2000003 | E6: CATETER INTRAVENOSO 16G T/ABBOCATH | F6: DESC2 | G6: Abbocath Nº 16 | H6: calibre 16 | I6: 202 | J6: 60 | K6: calibre | L6: Media | M6: Candidato 2000003 «CATETER INTRAVENOSO 16G T/ABBOCATH». Denominación: 100% del nombre del inventario explicado por el texto de SAP y 32% a la inversa. Atributos verificados: calibre. Sin contradicción en ningún atributo. | N6: Pendiente de valorización | O6: 214.29833 | P6: =IF(O6="","",O6*MAX(I6,J6)) | Q6: Pendiente | R6: Sin decidir
A7: 3 | B7: San Juan | C7: Descartable | D7: 2000005 | E7: CATETER INTRAVENOSO 20G T/ABBOCATH | F7: DESC4 | G7: Abbocath Nº 20 | H7: calibre 20 | I7: 272 | J7: 870 | K7: calibre | L7: Media | M7: Candidato 2000005 «CATETER INTRAVENOSO 20G T/ABBOCATH». Denominación: 100% del nombre del inventario explicado por el texto de SAP y 32% a la inversa. Atributos verificados: calibre. Sin contradicción en ningún atributo. | N7: Pendiente de valorización | O7: 176.58761 | P7: =IF(O7="","",O7*MAX(I7,J7)) | Q7: Pendiente | R7: Sin decidir
A8: 4 | B8: San Juan | C8: Descartable | D8: 2000006 | E8: CATETER INTRAVENOSO 22G T/ABBOCATH | F8: DESC5 | G8: Abbocath Nº 22 | H8: calibre 22 | I8: 217 | J8: 500 | K8: calibre | L8: Media | M8: Candidato 2000006 «CATETER INTRAVENOSO 22G T/ABBOCATH». Denominación: 100% del nombre del inventario explicado por el texto de SAP y 32% a la inversa. Atributos verificados: calibre. Sin contradicción en ningún atributo. | N8: Pendiente de valorización | O8: 170.50266 | P8: =IF(O8="","",O8*MAX(I8,J8)) | Q8: Pendiente | R8: Sin decidir
A9: 6 | B9: San Juan | C9: Medicamento | D9: 1000304 | E9: ADENOSINA 2 ML AMP 3 MG/1 ML | F9: MED8 | G9: Adenosina Amp x 2 ml | H9: forma ampolla · volumen 2 ml | I9: 5 | J9: 7 | K9: forma farmacéutica, volumen / presentación | L9: Alta | M9: Candidato 1000304 «ADENOSINA 2 ML AMP 3 MG/1 ML». Denominación: 100% del nombre del inventario explicado por el texto de SAP y 100% a la inversa. Atributos verificados: forma farmacéutica, volumen / presentación. Sin contradicción en ningún atributo. | N9: Pendiente de valorización | O9: 879.89714 | P9: =IF(O9="","",O9*MAX(I9,J9)) | Q9: Pendiente | R9: Sin decidir
A10: 7 | B10: San Juan | C10: Medicamento | D10: 1000002 | E10: ADRENALINA 1MG AMPOLLA DE 1 ML INYEC | F10: MED9 | G10: Adrenalina amp 1 ml | H10: forma ampolla · volumen 1 ml | I10: 41 | J10: 104 | K10: forma farmacéutica, volumen / presentación | L10: Alta | M10: Candidato 1000002 «ADRENALINA 1MG AMPOLLA DE 1 ML INYEC». Denominación: 100% del nombre del inventario explicado por el texto de SAP y 100% a la inversa. Atributos verificados: forma farmacéutica, volumen / presentación. Sin contradicción en ningún atributo. | N10: Pendiente de valorización | O10: 310.67721 | P10: =IF(O10="","",O10*MAX(I10,J10)) | Q10: Pendiente | R10: Sin decidir
A11: 8 | B11: San Juan | C11: Medicamento | D11: 1000052 | E11: AGUA OXIGENADA 10 VOL. X 500ML | F11: DESC291 | G11: Agua Oxigenada 10 Vol x 500 ml | H11: volumen 500 ml · cantidad sin unidad 10 | I11: 3 | J11: 0 | K11: volumen / presentación, cantidad o dosis sin unidad | L11: Alta | M11: Candidato 1000052 «AGUA OXIGENADA 10 VOL. X 500ML». Denominación: 100% del nombre del inventario explicado por el texto de SAP y 100% a la inversa. Atributos verificados: volumen / presentación, cantidad o dosis sin unidad. Sin contradicción en ningún atributo. | N11: Pendiente de valorización | O11: 542.5805 | P11: =IF(O11="","",O11*MAX(I11,J11)) | Q11: Pendiente | R11: Sin decidir
A12: 9 | B12: San Juan | C12: Medicamento | D12: 1000004 | E12: AGUA OXIGENADA 10 VOL. X 100ML | F12: DESC9 | G12: Agua oxigenada x 100ml | H12: volumen 100 ml | I12: 11 | J12: 15 | K12: volumen / presentación | L12: Alta | M12: Candidato 1000004 «AGUA OXIGENADA 10 VOL. X 100ML». Denominación: 100% del nombre del inventario explicado por el texto de SAP y 64% a la inversa. Atributos verificados: volumen / presentación. Sin contradicción en ningún atributo. | N12: Pendiente de valorización | O12: 335.13333 | P12: =IF(O12="","",O12*MAX(I12,J12)) | Q12: Pendiente | R12: Sin decidir
A13: 10 | B13: San Juan | C13: Medicamento | D13: 1000772 | E13: AGUJA 40/12 | F13: DESC10 | G13: Aguja 40/12 | H13: calibre 40/12 | I13: 20 | J13: 95 | K13: calibre | L13: Alta | M13: Candidato 1000772 «AGUJA 40/12». Denominación: 100% del nombre del inventario explicado por el texto de SAP y 100% a la inversa. Atributos verificados: calibre. Sin contradicción en ningún atributo. | N13: Pendiente de valorización | O13: 174.82526 | P13: =IF(O13="","",O13*MAX(I13,J13)) | Q13: Pendiente | R13: Sin decidir
A14: 11 | B14: San Juan | C14: Descartable | D14: 2000007 | E14: AGUJA HIPODERMICA 25G x ⅝ - 16/5 | F14: DESC11 | G14: Agujas 16/5 | H14: calibre 16/5 | I14: 300 | J14: 1020 | K14: calibre | L14: Media | M14: Candidato 2000007 «AGUJA HIPODERMICA 25G x ⅝ - 16/5». Denominación: 90% del nombre del inventario explicado por el texto de SAP y 41% a la inversa. Atributos verificados: calibre. Sin contradicción en ningún atributo. | N14: Pendiente de valorización | O14: 27.725941 | P14: =IF(O14="","",O14*MAX(I14,J14)) | Q14: Pendiente | R14: Sin decidir
A15: 12 | B15: San Juan | C15: Descartable | D15: 2000008 | E15: AGUJA HIPODERMICA 21G x 1 - 25/8 | F15: DESC12 | G15: Agujas 25/8 | H15: calibre 25/8 | I15: 975 | J15: 1548 | K15: calibre | L15: Media | M15: Candidato 2000008 «AGUJA HIPODERMICA 21G x 1 - 25/8». Denominación: 90% del nombre del inventario explicado por el texto de SAP y 41% a la inversa. Atributos verificados: calibre. Sin contradicción en ningún atributo. | N15: Pendiente de valorización | O15: 24.974767 | P15: =IF(O15="","",O15*MAX(I15,J15)) | Q15: Pendiente | R15: Sin decidir
A16: 13 | B16: San Juan | C16: Descartable | D16: 2000009 | E16: AGUJA HIPODERMICA 21G x 1 ½ - 40/8 | F16: DESC13 | G16: Agujas 40/8 | H16: calibre 40/8 | I16: 100 | J16: 1229 | K16: calibre | L16: Media | M16: Candidato 2000009 «AGUJA HIPODERMICA 21G x 1 ½ - 40/8». Denominación: 90% del nombre del inventario explicado por el texto de SAP y 41% a la inversa. Atributos verificados: calibre. Sin contradicción en ningún atributo. | N16: Pendiente de valorización | O16: 55.786672 | P16: =IF(O16="","",O16*MAX(I16,J16)) | Q16: Pendiente | R16: Sin decidir
... A49: 113 | B49: San Juan | C49: Medicamento | D49: 1000133 | E49: OMEPRAZOL DE 20MG COMPRIMIDOS | F49: MED148 | G49: Omeprazol Comp x 20 mg | H49: concentración 20 mg · forma comprimido | I49: 25 | J49: 84 | K49: concentración, forma farmacéutica | L49: Alta | M49: Candidato 1000133 «OMEPRAZOL DE 20MG COMPRIMIDOS». Denominación: 100% del nombre del inventario explicado por el texto de SAP y 100% a la inversa. Atributos verificados: concentración, forma farmacéutica. Sin contradicción en ningún atributo. | N49: Pendiente de valorización | O49: 52.137619 | P49: =IF(O49="","",O49*MAX(I49,J49)) | Q49: Pendiente | R49: Sin decidir
A50: 115 | B50: San Juan | C50: Descartable | D50: 2000470 | E50: OTOSCOPIO | F50: DESC94 | G50: Otoscopio | I50: 5 | J50: 0 | L50: Alta | M50: Candidato 2000470 «OTOSCOPIO». Denominación: 100% del nombre del inventario explicado por el texto de SAP y 100% a la inversa. Sin contradicción en ningún atributo. | N50: Pendiente de valorización | O50: 38539.108 | P50: =IF(O50="","",O50*MAX(I50,J50)) | Q50: Pendiente | R50: Sin decidir
A51: 116 | B51: San Juan | C51: Medicamento | D51: 1000470 | E51: PARACETAMOL COMP 1 GRAMO | F51: MED150 | G51: Paracetamol Comp x 1 gr | H51: concentración 1 g · forma comprimido | I51: 1048 | J51: 3831 | K51: concentración, forma farmacéutica | L51: Alta | M51: Candidato 1000470 «PARACETAMOL COMP 1 GRAMO». Denominación: 100% del nombre del inventario explicado por el texto de SAP y 45% a la inversa. Atributos verificados: concentración, forma farmacéutica. Sin contradicción en ningún atributo. | N51: Pendiente de valorización | O51: 87.157123 | P51: =IF(O51="","",O51*MAX(I51,J51)) | Q51: Pendiente | R51: Sin decidir
A52: 122 | B52: San Juan | C52: Medicamento | D52: 1000106 | E52: RIFAMICINA SPRAY 30ML | F52: DES104 | G52: Rifamicina Spray x 30ml | H52: forma aerosol · volumen 30 ml | I52: 3 | J52: 0 | K52: forma farmacéutica, volumen / presentación | L52: Alta | M52: Candidato 1000106 «RIFAMICINA SPRAY 30ML». Denominación: 100% del nombre del inventario explicado por el texto de SAP y 100% a la inversa. Atributos verificados: forma farmacéutica, volumen / presentación. Sin contradicción en ningún atributo. | N52: Pendiente de valorización | O52: 2216.5473 | P52: =IF(O52="","",O52*MAX(I52,J52)) | Q52: Pendiente | R52: Sin decidir
A53: 128 | B53: San Juan | C53: Medicamento | D53: 1001118 | E53: SALES REHIDRATANTES SOBRE POLVO | F53: MED162 | G53: Sales de Rehidratación (FM) sobre x 28gr | H53: concentración 28 g · forma sobre | I53: 2 | J53: 70 | K53: forma farmacéutica | L53: Alta | M53: Candidato 1001118 «SALES REHIDRATANTES SOBRE POLVO». Denominación: 95% del nombre del inventario explicado por el texto de SAP y 95% a la inversa. Atributos verificados: forma farmacéutica. Sin contradicción en ningún atributo. | N53: Pendiente de valorización | O53: 1601.2671 | P53: =IF(O53="","",O53*MAX(I53,J53)) | Q53: Pendiente | R53: Sin decidir
A54: 132 | B54: San Juan | C54: Medicamento | D54: 1000089 | E54: SOLUCION FISIOLOGICA DE 500CC | F54: MED168 | G54: Solucion fisiológica x 500 ml | H54: forma solucion · volumen 500 ml | I54: 249 | J54: 1271 | K54: forma farmacéutica, volumen / presentación | L54: Alta | M54: Candidato 1000089 «SOLUCION FISIOLOGICA DE 500CC». Denominación: 100% del nombre del inventario explicado por el texto de SAP y 100% a la inversa. Atributos verificados: forma farmacéutica, volumen / presentación. Sin contradicción en ningún atributo. | N54: Pendiente de valorización | O54: 1447.5172 | P54: =IF(O54="","",O54*MAX(I54,J54)) | Q54: Pendiente | R54: Sin decidir
A55: 133 | B55: San Juan | C55: Medicamento | D55: 1000035 | E55: SOLUCIÓN RINGER LACTATO 500 ML | F55: MED169 | G55: Solución ringer lactato x 500 ml | H55: forma solucion · volumen 500 ml | I55: 292 | J55: 630 | K55: forma farmacéutica, volumen / presentación | L55: Alta | M55: Candidato 1000035 «SOLUCIÓN RINGER LACTATO 500 ML». Denominación: 100% del nombre del inventario explicado por el texto de SAP y 100% a la inversa. Atributos verificados: forma farmacéutica, volumen / presentación. Sin contradicción en ningún atributo. | N55: Pendiente de valorización | O55: 2155.479 | P55: =IF(O55="","",O55*MAX(I55,J55)) | Q55: Pendiente | R55: Sin decidir
A56: 136 | B56: San Juan | C56: Descartable | D56: 2000867 | E56: SONDA NASOGASTRICA K-10 | F56: DESC116 | G56: Sonda nasogástrica K 10 | H56: modelo K10 | I56: 6 | J56: 0 | K56: modelo / referencia | L56: Alta | M56: Candidato 2000867 «SONDA NASOGASTRICA K-10». Denominación: 100% del nombre del inventario explicado por el texto de SAP y 100% a la inversa. Atributos verificados: modelo / referencia. Sin contradicción en ningún atributo. | N56: Pendiente de valorización | O56: 178.2835 | P56: =IF(O56="","",O56*MAX(I56,J56)) | Q56: Pendiente | R56: Sin decidir
A57: 137 | B57: San Juan | C57: Descartable | D57: 2000031 | E57: SONDA NASOGASTRICA K-30 KOLLER | F57: DESC117 | G57: Sonda nasogástrica K 30 | H57: modelo K30 | I57: 1 | J57: 0 | K57: modelo / referencia | L57: Alta | M57: Candidato 2000031 «SONDA NASOGASTRICA K-30 KOLLER». Denominación: 100% del nombre del inventario explicado por el texto de SAP y 62% a la inversa. Atributos verificados: modelo / referencia. Sin contradicción en ningún atributo. | N57: Pendiente de valorización | O57: 247.40631 | P57: =IF(O57="","",O57*MAX(I57,J57)) | Q57: Pendiente | R57: Sin decidir
A58: 138 | B58: San Juan | C58: Descartable | D58: 2001863 | E58: SONDA P/ ASPIRACION K29 | F58: DESC119 | G58: Sonda para aspiración K 29 | H58: modelo K29 | I58: 6 | J58: 0 | K58: modelo / referencia | L58: Alta | M58: Candidato 2001863 «SONDA P/ ASPIRACION K29». Denominación: 100% del nombre del inventario explicado por el texto de SAP y 58% a la inversa. Atributos verificados: modelo / referencia. Sin contradicción en ningún atributo. | N58: Pendiente de valorización | O58: 353.04 | P58: =IF(O58="","",O58*MAX(I58,J58)) | Q58: Pendiente | R58: Sin decidir
A59: 139 | B59: San Juan | C59: Descartable | D59: 2000093 | E59: SONDA VESICAL DE 2 VIAS Nº 16 (LÁTEX) | F59: DESC120 | G59: Sonda vesical Nº 16 | H59: calibre 16 | I59: 3 | J59: 0 | K59: calibre | L59: Alta | M59: Candidato 2000093 «SONDA VESICAL DE 2 VIAS Nº 16 (LÁTEX)». Denominación: 100% del nombre del inventario explicado por el texto de SAP y 65% a la inversa. Atributos verificados: calibre. Sin contradicción en ningún atributo. | N59: Pendiente de valorización | O59: 438.5 | P59: =IF(O59="","",O59*MAX(I59,J59)) | Q59: Pendiente | R59: Sin decidir
A60: 143 | B60: San Juan | C60: Descartable | D60: 2001052 | E60: SUTURA MONONYLON 4-0 AGUJA REDONDA | F60: DESC122 | G60: Sutura Mononylon 4-0 | H60: cantidad sin unidad 4 | I60: 7 | J60: 0 | K60: cantidad o dosis sin unidad | L60: Media | M60: Candidato 2001052 «SUTURA MONONYLON 4-0 AGUJA REDONDA». Denominación: 100% del nombre del inventario explicado por el texto de SAP y 50% a la inversa. Atributos verificados: cantidad o dosis sin unidad. Sin contradicción en ningún atributo. | N60: Pendiente de valorización | O60: 189 | P60: =IF(O60="","",O60*MAX(I60,J60)) | Q60: Pendiente | R60: Sin decidir
A61: 144 | B61: San Juan | C61: Descartable | D61: 2001053 | E61: SUTURA MONONYLON 5-0 AGUJA REDONDA | F61: DESC123 | G61: Sutura Mononylon 5-0 | H61: cantidad sin unidad 5 | I61: 1 | J61: 0 | K61: cantidad o dosis sin unidad | L61: Media | M61: Candidato 2001053 «SUTURA MONONYLON 5-0 AGUJA REDONDA». Denominación: 100% del nombre del inventario explicado por el texto de SAP y 50% a la inversa. Atributos verificados: cantidad o dosis sin unidad. Sin contradicción en ningún atributo. | N61: Pendiente de valorización | O61: 189 | P61: =IF(O61="","",O61*MAX(I61,J61)) | Q61: Pendiente | R61: Sin decidir
A62: 148 | B62: San Juan | C62: Descartable | D62: 2000034 | E62: TELA ADHESIVA 2.5CM HOSPITALARIA | F62: DESC132 | G62: Tela Adhesiva Hospitalaria 2.5 cm | H62: longitud 2,5 cm | I62: 22 | J62: 0 | K62: longitud | L62: Alta | M62: Candidato 2000034 «TELA ADHESIVA 2.5CM HOSPITALARIA». Denominación: 100% del nombre del inventario explicado por el texto de SAP y 100% a la inversa. Atributos verificados: longitud. Sin contradicción en ningún atributo. | N62: Pendiente de valorización | O62: 480.35338 | P62: =IF(O62="","",O62*MAX(I62,J62)) | Q62: Pendiente | R62: Sin decidir
A63: 152 | B63: San Juan | C63: Descartable | D63: 2000037 | E63: TERMOMETRO DIGITAL | F63: DESC138 | G63: Termómetro digital | I63: 3 | J63: 0 | L63: Alta | M63: Candidato 2000037 «TERMOMETRO DIGITAL». Denominación: 100% del nombre del inventario explicado por el texto de SAP y 100% a la inversa. Sin contradicción en ningún atributo. | N63: Pendiente de valorización | O63: 3388.4724 | P63: =IF(O63="","",O63*MAX(I63,J63)) | Q63: Pendiente | R63: Sin decidir
A64: 163 | B64: San Juan | C64: Descartable | D64: 2002475 | E64: VENDAS TIPO CAMBRIC - 7CM | F64: DESC171 | G64: Vendas de 7 cm. | H64: longitud 7 cm | I64: 8 | J64: 0 | K64: longitud | L64: Media | M64: Candidato 2002475 «VENDAS TIPO CAMBRIC - 7CM». Denominación: 100% del nombre del inventario explicado por el texto de SAP y 54% a la inversa. Atributos verificados: longitud. Sin contradicción en ningún atributo. | N64: Pendiente de valorización | O64: 319.65818 | P64: =IF(O64="","",O64*MAX(I64,J64)) | Q64: Pendiente | R64: Sin decidir
A65: 164 | B65: Neuquén | C65: Descartable | D65: 2000006 | E65: CATETER INTRAVENOSO 22G T/ABBOCATH | F65: 522 | G65: Abbocath n° 22 | H65: calibre 22 | I65: 90 | J65: 300 | K65: calibre | L65: Media | M65: Candidato 2000006 «CATETER INTRAVENOSO 22G T/ABBOCATH». Denominación: 100% del nombre del inventario explicado por el texto de SAP y 34% a la inversa. Atributos verificados: calibre. Sin contradicción en ningún atributo. | N65: Pendiente de valorización | O65: 296.9348 | P65: =IF(O65="","",O65*MAX(I65,J65)) | Q65: Pendiente | R65: Sin decidir
A66: 170 | B66: Neuquén | C66: Medicamento | D66: 1000002 | E66: ADRENALINA 1MG AMPOLLA DE 1 ML INYEC | F66: 2 | G66: ADRENALINA INY | H66: forma ampolla | I66: 279 | J66: 5588 | K66: forma farmacéutica | L66: Alta | M66: Candidato 1000002 «ADRENALINA 1MG AMPOLLA DE 1 ML INYEC». Denominación: 100% del nombre del inventario explicado por el texto de SAP y 100% a la inversa. Atributos verificados: forma farmacéutica. Sin contradicción en ningún atributo. | N66: Pendiente de valorización | O66: 287.35597 | P66: =IF(O66="","",O66*MAX(I66,J66)) | Q66: Pendiente | R66: Sin decidir
A67: 175 | B67: Neuquén | C67: Descartable | D67: 2000008 | E67: AGUJA HIPODERMICA 21G x 1 - 25/8 | F67: 273 | G67: Aguja 25/8 | H67: calibre 25/8 | I67: 3188 | J67: 12581 | K67: calibre | L67: Media | M67: Candidato 2000008 «AGUJA HIPODERMICA 21G x 1 - 25/8». Denominación: 100% del nombre del inventario explicado por el texto de SAP y 44% a la inversa. Atributos verificados: calibre. Sin contradicción en ningún atributo. | N67: Pendiente de valorización | O67: 23.068594 | P67: =IF(O67="","",O67*MAX(I67,J67)) | Q67: Pendiente | R67: Sin decidir
