Workbook

Sheet Guía paso a paso
A2: Guía paso a paso
A3: Cómo usar este archivo, explicado desde cero. No hace falta conocer el proceso: cada paso dice qué mirar y en qué hoja.
A5: 1 · ¿Qué hace este archivo?
A7: Compara DOS listas de lo mismo y muestra en qué no coinciden:
B8: La lista | C8: De dónde sale | D8: Qué dice
B9: 1) Stock SAP | C9: Bajada del sistema SAP al 02/10 | D9: Las unidades que SAP cree que hay en cada base
B10: 2) Inventario físico | C10: Lo que Avain contó a mano, en los PDF | D10: Las unidades que realmente hay en el depósito
A12: Cuando los dos números no coinciden, hay que corregir SAP: sacarle lo que sobra o agregarle lo que falta. Este archivo dice exactamente qué y cuánto.
A14: Hay un problema en el medio: SAP y Avain le ponen nombres distintos al mismo producto. SAP dice «JERINGA 10 ML» y Avain dice «Jeringas 10 cc». Emparejar esos nombres es lo que llamamos HOMOLOGAR. Por eso cada fila trae un nivel de confianza: dice cuán seguro es que esos dos nombres sean el mismo producto.
A16: 2 · Dos reglas para no confundirse nunca
A18: REGLA 1 — Unidades o pesos: el encabezado siempre lo aclara.
B19: Si el encabezado dice… | C19: Entonces el número es… | D19: Se ve así
B20: UNIDADES | C20: una cantidad de cosas: frascos, comprimidos, jeringas | D20: 2.367
B21: IMPORTE $ | C21: plata, pesos argentinos | D21: $ 137.512,84
A23: Todos los importes se muestran con el signo $ adelante. Si no tiene $, son unidades.
A25: REGLA 2 — El signo de la diferencia dice qué hacer.
A26: La cuenta es siempre la misma: Diferencia = lo que dice SAP − lo que se contó.
B27: Si la diferencia es… | C27: Significa que… | D27: Hay que…
B28: POSITIVA (ej. 1.449) | C28: SAP tiene más de lo que hay en el depósito | D28: DAR DE BAJA en SAP esas unidades
B29: NEGATIVA (ej. −350) | C29: hay más en el depósito de lo que SAP registra | D29: DAR DE ALTA en SAP esas unidades
B30: CERO | C30: SAP y el depósito coinciden | D30: no hacer nada
A33: 3 · Qué hay en cada hoja
B35: Hoja | C35: Para qué sirve | D35: Cuándo la uso
B36: Resumen del cruce | C36: Los números grandes de cada base, en una sola fila | D36: Para contar el resultado en una reunión
B37: Conciliación | C37: UNA FILA POR MATERIAL. El corazón del archivo | D37: Para buscar un material y ver todo junto
B38: Dar de baja en SAP | C38: Los materiales a los que hay que restar unidades | D38: Para hacer los ajustes de baja
B39: Dar de alta en SAP | C39: Los materiales a los que hay que sumar unidades | D39: Para hacer los ajustes de alta
B40: Sin correspondencia SAP | C40: Lo que Avain contó y no existe en SAP | D40: Para dar de alta materiales nuevos
B41: 1120 SJ · 1060 NQN · 1130 Salta | C41: El detalle fino de SAP, fila por lote y almacén. Es el archivo de SAP original con el cruce agregado | D41: Para Contabilidad y para auditar una fila
B42: Control de cantidades | C42: Prueba de que los totales coinciden con los archivos originales | D42: Para verificar que nada se perdió
B43: Posibles duplicidades | C43: Casos donde dos códigos de SAP podrían ser el mismo producto | D43: Para que alguien decida cuál es el correcto
B44: Fuera del Master | C44: Materiales contados que no estaban en el Master de Seba | D44: Para completar el Master
B45: Metodología | C45: El detalle técnico de cómo se hizo todo | D45: Si alguien pregunta «¿cómo lo calcularon?»
A47: Si sólo vas a abrir una hoja, abrí CONCILIACIÓN.
A49: 4 · Paso a paso: quiero revisar UN material
A51: Ejemplo real del archivo: las jeringas de 10 ml de San Juan.
A53: 1 | B53: Abrí la hoja CONCILIACIÓN.
A54: 2 | B54: Apretá Ctrl+B (Buscar) y escribí lo que conozcas: el código de SAP «2000028», o el nombre «JERINGA», o el nombre que usa Avain «Jeringas 10 cc». Cualquiera de los tres te lleva a la misma fila.
A55: 3 | B55: Mirá las tres columnas del medio, que son las que importan:
B56: Columna | C56: Dice | D56: En el ejemplo
...

Sheet Resumen del cruce
A2: Stock SAP vs inventario físico Avain · indicadores
A3: La base es el stock de SAP. El inventario físico se cruzó sobre esa base. Todos los valores son fórmulas sobre la hoja Conciliación, de modo que respetan cualquier corrección que se haga allí.
A5: Base / Centro | B5: 1. Stock SAP · Libre utilización UNIDADES | C5: 2. Inventario físico Avain · todo el inventario UNIDADES | D5: 3. Diferencia = 1 − 2 UNIDADES | E5: 4. Stock SAP de los materiales que SÍ se contaron UNIDADES | F5: 5. Diferencia neta de esos materiales contados (= 6 − 7) UNIDADES | G5: 6. A DAR DE BAJA en SAP (sobra en SAP) UNIDADES | H5: 7. A DAR DE ALTA en SAP (falta en SAP) UNIDADES | I5: 8. Ítems sin correspondencia en SAP CANTIDAD DE ÍTEMS | J5: 9. Unidades sin correspondencia en SAP UNIDADES | K5: 10. Diferencia económica (total de la columna S) IMPORTE $ | L5: 11. Diferencia económica de los materiales contados IMPORTE $ | M5: 12. De 11, con alerta de valorización IMPORTE $ | N5: 13. Diferencia económica confiable (11 − 12) IMPORTE $
A6: San Juan | B6: =SUMIFS('Conciliación'!$K$6:$K$1683,'Conciliación'!$A$6:$A$1683,"San Juan",'Conciliación'!$C$6:$C$1683,"Stock SAP") | C6: =SUMIFS('Conciliación'!$L$6:$L$1683,'Conciliación'!$A$6:$A$1683,"San Juan") | D6: =$B6-$C6 | E6: =SUMIFS('Conciliación'!$K$6:$K$1683,'Conciliación'!$A$6:$A$1683,"San Juan",'Conciliación'!$U$6:$U$1683,"Dar de baja en SAP")+SUMIFS('Conciliación'!$K$6:$K$1683,'Conciliación'!$A$6:$A$1683,"San Juan",'Conciliación'!$U$6:$U$1683,"Dar de alta en SAP")+SUMIFS('Conciliación'!$K$6:$K$1683,'Conciliación'!$A$6:$A$1683,"San Juan",'Conciliación'!$U$6:$U$1683,"Sin diferencia") | F6: =SUMIFS('Conciliación'!$M$6:$M$1683,'Conciliación'!$A$6:$A$1683,"San Juan",'Conciliación'!$U$6:$U$1683,"Dar de baja en SAP")+SUMIFS('Conciliación'!$M$6:$M$1683,'Conciliación'!$A$6:$A$1683,"San Juan",'Conciliación'!$U$6:$U$1683,"Dar de alta en SAP")+SUMIFS('Conciliación'!$M$6:$M$1683,'Conciliación'!$A$6:$A$1683,"San Juan",'Conciliación'!$U$6:$U$1683,"Sin diferencia") | G6: =SUMIFS('Conciliación'!$M$6:$M$1683,'Conciliación'!$A$6:$A$1683,"San Juan",'Conciliación'!$U$6:$U$1683,"Dar de baja en SAP") | H6: =-SUMIFS('Conciliación'!$M$6:$M$1683,'Conciliación'!$A$6:$A$1683,"San Juan",'Conciliación'!$U$6:$U$1683,"Dar de alta en SAP") | I6: =COUNTIFS('Conciliación'!$A$6:$A$1683,"San Juan",'Conciliación'!$C$6:$C$1683,"Inventario físico sin código SAP") | J6: =SUMIFS('Conciliación'!$L$6:$L$1683,'Conciliación'!$A$6:$A$1683,"San Juan",'Conciliación'!$C$6:$C$1683,"Inventario físico sin código SAP") | K6: =SUM('1120 SJ'!$S$2:$S$731) | L6: =SUMIFS('Conciliación'!$Q$6:$Q$1683,'Conciliación'!$A$6:$A$1683,"San Juan",'Conciliación'!$U$6:$U$1683,"Dar de baja en SAP")+SUMIFS('Conciliación'!$Q$6:$Q$1683,'Conciliación'!$A$6:$A$1683,"San Juan",'Conciliación'!$U$6:$U$1683,"Dar de alta en SAP") | M6: =SUMIFS('Conciliación'!$Q$6:$Q$1683,'Conciliación'!$A$6:$A$1683,"San Juan",'Conciliación'!$U$6:$U$1683,"Dar de baja en SAP",'Conciliación'!$R$6:$R$1683,"?*")+SUMIFS('Conciliación'!$Q$6:$Q$1683,'Conciliación'!$A$6:$A$1683,"San Juan",'Conciliación'!$U$6:$U$1683,"Dar de alta en SAP",'Conciliación'!$R$6:$R$1683,"?*") | N6: =$L6-$M6
A7: Neuquén | B7: =SUMIFS('Conciliación'!$K$6:$K$1683,'Conciliación'!$A$6:$A$1683,"Neuquén",'Conciliación'!$C$6:$C$1683,"Stock SAP") | C7: =SUMIFS('Conciliación'!$L$6:$L$1683,'Conciliación'!$A$6:$A$1683,"Neuquén") | D7: =$B7-$C7 | E7: =SUMIFS('Conciliación'!$K$6:$K$1683,'Conciliación'!$A$6:$A$1683,"Neuquén",'Conciliación'!$U$6:$U$1683,"Dar de baja en SAP")+SUMIFS('Conciliación'!$K$6:$K$1683,'Conciliación'!$A$6:$A$1683,"Neuquén",'Conciliación'!$U$6:$U$1683,"Dar de alta en SAP")+SUMIFS('Conciliación'!$K$6:$K$1683,'Conciliación'!$A$6:$A$1683,"Neuquén",'Conciliación'!$U$6:$U$1683,"Sin diferencia") | F7: =SUMIFS('Conciliación'!$M$6:$M$1683,'Conciliación'!$A$6:$A$1683,"Neuquén",'Conciliación'!$U$6:$U$1683,"Dar de baja en SAP")+SUMIFS('Conciliación'!$M$6:$M$1683,'Conciliación'!$A$6:$A$1683,"Neuquén",'Conciliación'!$U$6:$U$1683,"Dar de alta en SAP")+SUMIFS('Conciliación'!$M$6:$M$1683,'Conciliación'!$A$6:$A$1683,"Neuquén",'Conciliación'!$U$6:$U$1683,"Sin diferencia") | G7: =SUMIFS('Conciliación'!$M$6:$M$1683,'Conciliación'!$A$6:$A$1683,"Neuquén",'Conciliación'!$U$6:$U$1683,"Dar de baja en SAP") | H7: =-SUMIFS('Conciliación'!$M$6:$M$1683,'Conciliación'!$A$6:$A$1683,"Neuquén",'Conciliación'!$U$6:$U$1683,"Dar de alta en SAP") | I7: =COUNTIFS('Conciliación'!$A$6:$A$1683,"Neuquén",'Conciliación'!$C$6:$C$1683,"Inventario físico sin código SAP") | J7: =SUMIFS('Conciliación'!$L$6:$L$1683,'Conciliación'!$A$6:$A$1683,"Neuquén",'Conciliación'!$C$6:$C$1683,"Inventario físico sin código SAP") | K7: =SUM('1060 NQN'!$S$2:$S$2074) | L7: =SUMIFS('Conciliación'!$Q$6:$Q$1683,'Conciliación'!$A$6:$A$1683,"Neuquén",'Conciliación'!$U$6:$U$1683,"Dar de baja en SAP")+SUMIFS('Conciliación'!$Q$6:$Q$1683,'Conciliación'!$A$6:$A$1683,"Neuquén",'Conciliación'!$U$6:$U$1683,"Dar de alta en SAP") | M7: =SUMIFS('Conciliación'!$Q$6:$Q$1683,'Conciliación'!$A$6:$A$1683,"Neuquén",'Conciliación'!$U$6:$U$1683,"Dar de baja en SAP",'Conciliación'!$R$6:$R$1683,"?*")+SUMIFS('Conciliación'!$Q$6:$Q$1683,'Conciliación'!$A$6:$A$1683,"Neuquén",'Conciliación'!$U$6:$U$1683,"Dar de alta en SAP",'Conciliación'!$R$6:$R$1683,"?*") | N7: =$L7-$M7
A8: Salta | B8: =SUMIFS('Conciliación'!$K$6:$K$1683,'Conciliación'!$A$6:$A$1683,"Salta",'Conciliación'!$C$6:$C$1683,"Stock SAP") | C8: =SUMIFS('Conciliación'!$L$6:$L$1683,'Conciliación'!$A$6:$A$1683,"Salta") | D8: =$B8-$C8 | E8: =SUMIFS('Conciliación'!$K$6:$K$1683,'Conciliación'!$A$6:$A$1683,"Salta",'Conciliación'!$U$6:$U$1683,"Dar de baja en SAP")+SUMIFS('Conciliación'!$K$6:$K$1683,'Conciliación'!$A$6:$A$1683,"Salta",'Conciliación'!$U$6:$U$1683,"Dar de alta en SAP")+SUMIFS('Conciliación'!$K$6:$K$1683,'Conciliación'!$A$6:$A$1683,"Salta",'Conciliación'!$U$6:$U$1683,"Sin diferencia") | F8: =SUMIFS('Conciliación'!$M$6:$M$1683,'Conciliación'!$A$6:$A$1683,"Salta",'Conciliación'!$U$6:$U$1683,"Dar de baja en SAP")+SUMIFS('Conciliación'!$M$6:$M$1683,'Conciliación'!$A$6:$A$1683,"Salta",'Conciliación'!$U$6:$U$1683,"Dar de alta en SAP")+SUMIFS('Conciliación'!$M$6:$M$1683,'Conciliación'!$A$6:$A$1683,"Salta",'Conciliación'!$U$6:$U$1683,"Sin diferencia") | G8: =SUMIFS('Conciliación'!$M$6:$M$1683,'Conciliación'!$A$6:$A$1683,"Salta",'Conciliación'!$U$6:$U$1683,"Dar de baja en SAP") | H8: =-SUMIFS('Conciliación'!$M$6:$M$1683,'Conciliación'!$A$6:$A$1683,"Salta",'Conciliación'!$U$6:$U$1683,"Dar de alta en SAP") | I8: =COUNTIFS('Conciliación'!$A$6:$A$1683,"Salta",'Conciliación'!$C$6:$C$1683,"Inventario físico sin código SAP") | J8: =SUMIFS('Conciliación'!$L$6:$L$1683,'Conciliación'!$A$6:$A$1683,"Salta",'Conciliación'!$C$6:$C$1683,"Inventario físico sin código SAP") | K8: =SUM('1130 Salta'!$S$2:$S$578) | L8: =SUMIFS('Conciliación'!$Q$6:$Q$1683,'Conciliación'!$A$6:$A$1683,"Salta",'Conciliación'!$U$6:$U$1683,"Dar de baja en SAP")+SUMIFS('Conciliación'!$Q$6:$Q$1683,'Conciliación'!$A$6:$A$1683,"Salta",'Conciliación'!$U$6:$U$1683,"Dar de alta en SAP") | M8: =SUMIFS('Conciliación'!$Q$6:$Q$1683,'Conciliación'!$A$6:$A$1683,"Salta",'Conciliación'!$U$6:$U$1683,"Dar de baja en SAP",'Conciliación'!$R$6:$R$1683,"?*")+SUMIFS('Conciliación'!$Q$6:$Q$1683,'Conciliación'!$A$6:$A$1683,"Salta",'Conciliación'!$U$6:$U$1683,"Dar de alta en SAP",'Conciliación'!$R$6:$R$1683,"?*") | N8: =$L8-$M8
A9: TOTAL | B9: =SUM(B6:B8) | C9: =SUM(C6:C8) | D9: =SUM(D6:D8) | E9: =SUM(E6:E8) | F9: =SUM(F6:F8) | G9: =SUM(G6:G8) | H9: =SUM(H6:H8) | I9: =SUM(I6:I8) | ... N9: =SUM(N6:N8)
A11: Cómo leer estos indicadores
A12: Para una explicación desde cero, ver la hoja «Guía paso a paso».
A13: • Las columnas 1 a 9 están en UNIDADES. Las columnas 10 a 13 son IMPORTES en pesos y se muestran con el signo $.
A14: • Columna 3, diferencia = Stock SAP − inventario físico, con el inventario físico completo: los ítems con código SAP y los que todavía no lo tienen.
A15: • Diferencia POSITIVA: SAP informa más unidades que el recuento → cantidad a DAR DE BAJA en SAP (columna 6).
A16: • Diferencia NEGATIVA: el recuento supera lo informado en SAP → cantidad a DAR DE ALTA en SAP (columna 7).
A17: • Columna 5: es el ajuste NETO en unidades de los materiales que SÍ se contaron, es decir la columna 6 menos la columna 7. En Salta da −1.027 porque se contó más de lo que SAP informa.
A18: • La diferencia de la columna 3 incluye materiales que el inventario no contó; ésos no son faltantes. El ajuste operativo son las columnas 6 y 7, que sólo consideran materiales con recuento.
A19: • Columna 10: es la suma de la columna S «Diferencia economica» de las hojas de detalle. Incluye los materiales sin recuento.
A20: • Columna 11: la misma valorización, pero sólo de los materiales contados. Es el importe del ajuste.
A21: • Columnas 12 y 13: de ese importe, cuánto cae en filas con alerta de valorización (posible distinta unidad de medida entre SAP y el recuento) y cuánto queda como importe confiable. Mientras la alerta no se valide, usar la columna 13.
A22: • Los ítems sin correspondencia en SAP no tienen valor unitario, así que su diferencia económica no puede calcularse: figuran como dato faltante.
... A25: Se mantiene como información de respaldo del estado de la homologación. No forma parte del tablero principal.
A26: Base | B26: Ítems del inventario físico | C26: Alta | D26: Media | E26: Baja | F26: Sin correspondencia en SAP | G26: Materiales SAP | H26: Materiales con recuento | I26: Materiales fuera del alcance | J26: Materiales sin recuento (dentro del alcance)
A27: San Juan | B27: 156 | C27: 55 | D27: 21 | E27: 28 | F27: 52 | G27: 424 | H27: 104 | I27: 87 | J27: 233
A28: Neuquén | B28: 218 | C28: 56 | D28: 64 | E28: 47 | F28: 51 | G28: 655 | H28: 167 | I28: 202 | J28: 286
A29: Salta | B29: 255 | C29: 72 | D29: 40 | E29: 50 | F29: 93 | G29: 403 | H29: 162 | I29: 121 | J29: 120

Sheet Conciliación
A2: Conciliación unificada · una fila por material
A3: Permite tomar un material y verificar cantidad SAP, cantidad física, diferencia, valorización y estado de homologación. Filtrable por base, clasificación, código SAP, acción y estado. Las cantidades se traen por SUMIF de las hojas de detalle, de modo que todo queda trazable hasta la fila de SAP.
A5: Base | B5: Centro | C5: Origen del registro | D5: Clasificación SAP | E5: Tipo material SAP | F5: Alcance del inventario físico | G5: Código SAP (Material) | H5: Nomenclatura SAP | I5: Código Avain | J5: Nombre en inventario físico Avain | K5: Cantidad SAP (Libre utilización) · UNIDADES | L5: Cantidad física Avain · UNIDADES | M5: Diferencia (SAP − físico) · UNIDADES | N5: VU promedio ponderado · IMPORTE $ por unidad | O5: Valor SAP · IMPORTE $ | P5: Valor del recuento físico · IMPORTE $ | Q5: Diferencia económica · IMPORTE $ | R5: Alerta de valorización | S5: Nivel de coincidencia | T5: Estado de homologación / validación | U5: Acción en SAP | V5: Método de cruce | W5: ¿Posible duplicidad SAP? | X5: Códigos SAP posibles equivalentes | Y5: ¿Informado en Master de Seba? | Z5: ID común (Master) | AA5: Observaciones
A6: San Juan | B6: 1120 | C6: Stock SAP | D6: Medicamentos | E6: ZMED | F6: Dentro del alcance | G6: 1000124 | H6: IBUPROFENO COMP 600MG | I6: MED102 | J6: Ibuprofeno Comp x 600 mg | K6: =SUMIF('1120 SJ'!$A$2:$A$679,$G6,'1120 SJ'!$I$2:$I$679) | L6: =SUMIF('1120 SJ'!$A$2:$A$679,$G6,'1120 SJ'!$Q$2:$Q$679) | M6: =$K6-$L6 | N6: =IFERROR(SUMIF('1120 SJ'!$A$2:$A$679,$G6,'1120 SJ'!$M$2:$M$679)/$K6,0) | O6: =IFERROR($K6*$N6,"") | P6: =IFERROR($L6*$N6,"") | Q6: =$M6*$N6 | S6: Alta | T6: Homologado – confianza Alta | U6: Dar de baja en SAP | V6: Homologación por código Avain (master M01-005) | W6: No | Y6: Sí | Z6: M01-005 | AA6: Homologación: confianza base Alta + confianza SAP Alta → Alta. El material ocupa 16 filas en la hoja 1120 SJ (lote/almacén). La cantidad SAP y la física de esta vista son el total del material.
A7: San Juan | B7: 1120 | C7: Stock SAP | D7: Descartables | E7: ZDES | F7: Dentro del alcance | G7: 2001555 | H7: SONDA T/K-27 | K7: =SUMIF('1120 SJ'!$A$2:$A$679,$G7,'1120 SJ'!$I$2:$I$679) | L7: =SUMIF('1120 SJ'!$A$2:$A$679,$G7,'1120 SJ'!$Q$2:$Q$679) | M7: =$K7-$L7 | N7: =IFERROR(SUMIF('1120 SJ'!$A$2:$A$679,$G7,'1120 SJ'!$M$2:$M$679)/$K7,0) | O7: =IFERROR($K7*$N7,"") | P7: =IFERROR($L7*$N7,"") | Q7: =$M7*$N7 | T7: Sin recuento físico en el inventario de Avain | U7: Sin recuento físico
A8: San Juan | B8: 1120 | C8: Stock SAP | D8: Medicamentos | E8: ZMED | F8: Dentro del alcance | G8: 1000470 | H8: PARACETAMOL COMP 1 GRAMO | I8: MED150 | J8: Paracetamol Comp x 1 gr | K8: =SUMIF('1120 SJ'!$A$2:$A$679,$G8,'1120 SJ'!$I$2:$I$679) | L8: =SUMIF('1120 SJ'!$A$2:$A$679,$G8,'1120 SJ'!$Q$2:$Q$679) | M8: =$K8-$L8 | N8: =IFERROR(SUMIF('1120 SJ'!$A$2:$A$679,$G8,'1120 SJ'!$M$2:$M$679)/$K8,0) | O8: =IFERROR($K8*$N8,"") | P8: =IFERROR($L8*$N8,"") | Q8: =$M8*$N8 | S8: Baja | T8: Homologado – confianza Baja – pendiente de validación | U8: Dar de baja en SAP | V8: Homologación por código Avain (master M01-008) | W8: No | Y8: Sí | Z8: M01-008 | AA8: Homologación: confianza base Baja + confianza SAP Baja → Baja. El material ocupa 6 filas en la hoja 1120 SJ (lote/almacén). La cantidad SAP y la física de esta vista son el total del material.
A9: San Juan | B9: 1120 | C9: Stock SAP | D9: Descartables | E9: ZDES | F9: Dentro del alcance | G9: 2000158 | H9: GUANTES DE EXAMINACIÓN TALLE M | I9: DESC68 | J9: Guantes de examinacion M c/u | K9: =SUMIF('1120 SJ'!$A$2:$A$679,$G9,'1120 SJ'!$I$2:$I$679) | L9: =SUMIF('1120 SJ'!$A$2:$A$679,$G9,'1120 SJ'!$Q$2:$Q$679) | M9: =$K9-$L9 | N9: =IFERROR(SUMIF('1120 SJ'!$A$2:$A$679,$G9,'1120 SJ'!$M$2:$M$679)/$K9,0) | O9: =IFERROR($K9*$N9,"") | P9: =IFERROR($L9*$N9,"") | Q9: =$M9*$N9 | S9: Alta | T9: Homologado – confianza Alta | U9: Dar de baja en SAP | V9: Cruce por nomenclatura SAP | W9: No | Y9: Sí | AA9: Cruce por nomenclatura: similitud 0.88.
A10: San Juan | B10: 1120 | C10: Stock SAP | D10: Descartables | E10: ZDES | F10: Dentro del alcance | G10: 2000363 | H10: MASCARA PARA O2 ADULTO CON RESERVORIO | I10: DESC93 | J10: Mascaras para oxigeno c/ reservorio | K10: =SUMIF('1120 SJ'!$A$2:$A$679,$G10,'1120 SJ'!$I$2:$I$679) | L10: =SUMIF('1120 SJ'!$A$2:$A$679,$G10,'1120 SJ'!$Q$2:$Q$679) | M10: =$K10-$L10 | N10: =IFERROR(SUMIF('1120 SJ'!$A$2:$A$679,$G10,'1120 SJ'!$M$2:$M$679)/$K10,0) | O10: =IFERROR($K10*$N10,"") | P10: =IFERROR($L10*$N10,"") | Q10: =$M10*$N10 | R10: Valorización a validar: relación de cantidades 58 a 1 entre SAP y el recuento físico. Sugiere distinta unidad de medida (SAP por caja o envase y el recuento por unidad). La diferencia económica de esta fila no debe tomarse como definitiva. | S10: Media | T10: Homologado – confianza Media – pendiente de validación | U10: Dar de baja en SAP | V10: Homologación por código Avain (master D-159) | W10: No | Y10: Sí | Z10: D-159 | AA10: Homologación: confianza base Media + confianza SAP Media → Media. Otros códigos SAP del master no están en el stock de este centro: 2000364.
A11: San Juan | B11: 1120 | C11: Stock SAP | D11: Medicamentos | E11: ZMED | F11: Dentro del alcance | G11: 1000478 | H11: DEXAMETASONA 8MG/2ML AMP(DESCONTINUADO) | I11: MED55 | J11: Dexametasona 8mg Amp x 2 ml | K11: =SUMIF('1120 SJ'!$A$2:$A$679,$G11,'1120 SJ'!$I$2:$I$679) | L11: =SUMIF('1120 SJ'!$A$2:$A$679,$G11,'1120 SJ'!$Q$2:$Q$679) | M11: =$K11-$L11 | N11: =IFERROR(SUMIF('1120 SJ'!$A$2:$A$679,$G11,'1120 SJ'!$M$2:$M$679)/$K11,0) | O11: =IFERROR($K11*$N11,"") | P11: =IFERROR($L11*$N11,"") | Q11: =$M11*$N11 | S11: Alta | T11: Homologado – confianza Alta | U11: Dar de baja en SAP | V11: Homologación por código Avain (master M06-001) | W11: No | Y11: Sí | Z11: M06-001 | AA11: Homologación: confianza base Alta + confianza SAP Alta → Alta. El material ocupa 12 filas en la hoja 1120 SJ (lote/almacén). La cantidad SAP y la física de esta vista son el total del material.
A12: San Juan | B12: 1120 | C12: Stock SAP | D12: Descartables | E12: ZDES | F12: Dentro del alcance | G12: 2000011 | H12: BAJALENGUAS DE MADERA | I12: DESC22 | J12: Bajalenguas x 1 ud | K12: =SUMIF('1120 SJ'!$A$2:$A$679,$G12,'1120 SJ'!$I$2:$I$679) | L12: =SUMIF('1120 SJ'!$A$2:$A$679,$G12,'1120 SJ'!$Q$2:$Q$679) | M12: =$K12-$L12 | N12: =IFERROR(SUMIF('1120 SJ'!$A$2:$A$679,$G12,'1120 SJ'!$M$2:$M$679)/$K12,0) | O12: =IFERROR($K12*$N12,"") | P12: =IFERROR($L12*$N12,"") | Q12: =$M12*$N12 | S12: Media | T12: Homologado – confianza Media – pendiente de validación | U12: Dar de baja en SAP | V12: Cruce por nomenclatura SAP | W12: No | Y12: No | AA12: Cruce por nomenclatura: similitud 0.62.
A13: San Juan | B13: 1120 | C13: Stock SAP | D13: Descartables | E13: ZDES | F13: Dentro del alcance | G13: 2000270 | H13: GUANTES DE EXAMINACION TALLE S | I13: DESC66; DESC67; 32 | J13: Guantes de examinacion Ch c/u; Guantes de examinacion G c/u; GUANTES DE EXAMINACIÓN TALLE S | K13: =SUMIF('1120 SJ'!$A$2:$A$679,$G13,'1120 SJ'!$I$2:$I$679) | L13: =SUMIF('1120 SJ'!$A$2:$A$679,$G13,'1120 SJ'!$Q$2:$Q$679) | M13: =$K13-$L13 | N13: =IFERROR(SUMIF('1120 SJ'!$A$2:$A$679,$G13,'1120 SJ'!$M$2:$M$679)/$K13,0) | O13: =IFERROR($K13*$N13,"") | P13: =IFERROR($L13*$N13,"") | Q13: =$M13*$N13 | S13: Media | T13: Homologado – confianza Media – pendiente de validación | U13: Dar de alta en SAP | V13: Cruce por nomenclatura SAP; Homologación por código Avain (master D-152); Homologación por código Avain (master K-234) | W13: Sí | X13: 2000270, 2000158, 2000157 | Y13: Sí | Z13: D-152; K-234 | AA13: Varias denominaciones del inventario físico corresponden a este material SAP (DESC66 Guantes de examinacion Ch c/u; DESC67 Guantes de examinacion G c/u; 32 GUANTES DE EXAMINACIÓN TALLE S). Se sumaron las cantidades físicas. Cruce por nomenclatura: similitud 0.60. Homologación: confianza base Media + confianza SAP Media → Media. El cruce SAP–Avain identificó 3 códigos SAP como posibles equivalentes del mismo ítem de Avain (2000270, 2000158, 2000157). Se imputó al primero (lógica BUSCARV); requiere validación posterior. Homologación: confianza base Media + confianza SAP Media → Media. El cruce SAP–Avain identificó 3 códigos SAP como posibles equivalentes del mismo ítem de Avain (2000270, 2000158, 2000157). Se imputó al primero (lógica BUSCARV); requiere validación posterior.
A14: San Juan | B14: 1120 | C14: Stock SAP | D14: Descartables | E14: ZDES | F14: Dentro del alcance | G14: 2000028 | H14: JERINGA 10 ML | I14: DESC78 | J14: Jeringas 10 cc | K14: =SUMIF('1120 SJ'!$A$2:$A$679,$G14,'1120 SJ'!$I$2:$I$679) | L14: =SUMIF('1120 SJ'!$A$2:$A$679,$G14,'1120 SJ'!$Q$2:$Q$679) | M14: =$K14-$L14 | N14: =IFERROR(SUMIF('1120 SJ'!$A$2:$A$679,$G14,'1120 SJ'!$M$2:$M$679)/$K14,0) | O14: =IFERROR($K14*$N14,"") | P14: =IFERROR($L14*$N14,"") | Q14: =$M14*$N14 | S14: Alta | T14: Homologado – confianza Alta | U14: Dar de baja en SAP | V14: Homologación por código Avain (master D-136) | W14: No | Y14: Sí | Z14: D-136 | AA14: Homologación: confianza base Alta + confianza SAP Alta → Alta. El material ocupa 2 filas en la hoja 1120 SJ (lote/almacén). La cantidad SAP y la física de esta vista son el total del material.
A15: San Juan | B15: 1120 | C15: Stock SAP | D15: Medicamentos | E15: ZMED | F15: Dentro del alcance | G15: 1000125 | H15: DICLOFENAC 75 MG COMPRIMIDOS | I15: MED64 | J15: Diclofenac Comp x 75 mg | K15: =SUMIF('1120 SJ'!$A$2:$A$679,$G15,'1120 SJ'!$I$2:$I$679) | L15: =SUMIF('1120 SJ'!$A$2:$A$679,$G15,'1120 SJ'!$Q$2:$Q$679) | M15: =$K15-$L15 | N15: =IFERROR(SUMIF('1120 SJ'!$A$2:$A$679,$G15,'1120 SJ'!$M$2:$M$679)/$K15,0) | O15: =IFERROR($K15*$N15,"") | P15: =IFERROR($L15*$N15,"") | Q15: =$M15*$N15 | S15: Alta | T15: Homologado – confianza Alta | U15: Dar de baja en SAP | V15: Homologación por nombre Avain (master M01-002) | W15: No | Y15: Sí | Z15: M01-002 | AA15: Homologación: confianza base Alta + confianza SAP Alta → Alta. El material ocupa 7 filas en la hoja 1120 SJ (lote/almacén). La cantidad SAP y la física de esta vista son el total del material.
A16: San Juan | B16: 1120 | C16: Stock SAP | D16: Descartables | E16: ZDES | F16: Dentro del alcance | G16: 2000041 | H16: BARBIJO TRIPLE RECTO C/ELÁSTI | K16: =SUMIF('1120 SJ'!$A$2:$A$679,$G16,'1120 SJ'!$I$2:$I$679) | L16: =SUMIF('1120 SJ'!$A$2:$A$679,$G16,'1120 SJ'!$Q$2:$Q$679) | M16: =$K16-$L16 | N16: =IFERROR(SUMIF('1120 SJ'!$A$2:$A$679,$G16,'1120 SJ'!$M$2:$M$679)/$K16,0) | O16: =IFERROR($K16*$N16,"") | P16: =IFERROR($L16*$N16,"") | Q16: =$M16*$N16 | T16: Sin recuento físico en el inventario de Avain | U16: Sin recuento físico
A17: San Juan | B17: 1120 | C17: Stock SAP | D17: Descartables | E17: ZDES | F17: Dentro del alcance | G17: 2000023 | H17: GUIA MACROGOTERO Nª14 | I17: DESC73 | J17: Guia Macrogotero | K17: =SUMIF('1120 SJ'!$A$2:$A$679,$G17,'1120 SJ'!$I$2:$I$679) | L17: =SUMIF('1120 SJ'!$A$2:$A$679,$G17,'1120 SJ'!$Q$2:$Q$679) | M17: =$K17-$L17 | N17: =IFERROR(SUMIF('1120 SJ'!$A$2:$A$679,$G17,'1120 SJ'!$M$2:$M$679)/$K17,0) | O17: =IFERROR($K17*$N17,"") | P17: =IFERROR($L17*$N17,"") | Q17: =$M17*$N17 | S17: Media | T17: Homologado – confianza Media – pendiente de validación | U17: Dar de baja en SAP | V17: Homologación por código Avain (master D-131) | W17: No | Y17: Sí | Z17: D-131 | AA17: Homologación: confianza base Media + confianza SAP Alta → Media.
A18: San Juan | B18: 1120 | C18: Stock SAP | D18: Medicamentos | E18: ZMED | F18: Dentro del alcance | G18: 1000045 | H18: DICLOFENAC 75MG AMPOLLA 3ML | I18: MED62 | J18: Diclofenac 75mg Amp x 3ml | K18: =SUMIF('1120 SJ'!$A$2:$A$679,$G18,'1120 SJ'!$I$2:$I$679) | L18: =SUMIF('1120 SJ'!$A$2:$A$679,$G18,'1120 SJ'!$Q$2:$Q$679) | M18: =$K18-$L18 | N18: =IFERROR(SUMIF('1120 SJ'!$A$2:$A$679,$G18,'1120 SJ'!$M$2:$M$679)/$K18,0) | O18: =IFERROR($K18*$N18,"") | P18: =IFERROR($L18*$N18,"") | Q18: =$M18*$N18 | S18: Alta | T18: Homologado – confianza Alta | U18: Dar de baja en SAP | V18: Homologación por código Avain (master M01-003) | W18: No | Y18: Sí | Z18: M01-003 | AA18: Homologación: confianza base Alta + confianza SAP Alta → Alta. El material ocupa 7 filas en la hoja 1120 SJ (lote/almacén). La cantidad SAP y la física de esta vista son el total del material.
A19: San Juan | B19: 1120 | C19: Stock SAP | D19: Medicamentos | E19: ZMED | F19: Dentro del alcance | G19: 1000105 | H19: METOCLOPRAMIDA 10MG/2ML AMPOLLA | I19: MED130 | J19: Metoclopramida 10 mg Amp x 2 ml | K19: =SUMIF('1120 SJ'!$A$2:$A$679,$G19,'1120 SJ'!$I$2:$I$679) | L19: =SUMIF('1120 SJ'!$A$2:$A$679,$G19,'1120 SJ'!$Q$2:$Q$679) | M19: =$K19-$L19 | N19: =IFERROR(SUMIF('1120 SJ'!$A$2:$A$679,$G19,'1120 SJ'!$M$2:$M$679)/$K19,0) | O19: =IFERROR($K19*$N19,"") | P19: =IFERROR($L19*$N19,"") | Q19: =$M19*$N19 | S19: Alta | T19: Homologado – confianza Alta | U19: Dar de baja en SAP | V19: Homologación por código Avain (master M08-001) | W19: No | Y19: Sí | Z19: M08-001 | AA19: Homologación: confianza base Alta + confianza SAP Alta → Alta. El material ocupa 7 filas en la hoja 1120 SJ (lote/almacén). La cantidad SAP y la física de esta vista son el total del material.
A20: San Juan | B20: 1120 | C20: Stock SAP | D20: Medicamentos | E20: ZMED | F20: Dentro del alcance | G20: 1000129 | H20: KETOROLAC 10MG SUBLINGUAL | I20: MED110 | J20: Ketorolac Comp SL X 10 mg | K20: =SUMIF('1120 SJ'!$A$2:$A$679,$G20,'1120 SJ'!$I$2:$I$679) | L20: =SUMIF('1120 SJ'!$A$2:$A$679,$G20,'1120 SJ'!$Q$2:$Q$679) | M20: =$K20-$L20 | N20: =IFERROR(SUMIF('1120 SJ'!$A$2:$A$679,$G20,'1120 SJ'!$M$2:$M$679)/$K20,0) | O20: =IFERROR($K20*$N20,"") | P20: =IFERROR($L20*$N20,"") | Q20: =$M20*$N20 | S20: Alta | T20: Homologado – confianza Alta | U20: Dar de baja en SAP | V20: Homologación por código Avain (master M01-006) | W20: No | Y20: Sí | Z20: M01-006 | AA20: Homologación: confianza base Alta + confianza SAP Alta → Alta. El material ocupa 7 filas en la hoja 1120 SJ (lote/almacén). La cantidad SAP y la física de esta vista son el total del material.
A21: San Juan | B21: 1120 | C21: Stock SAP | D21: Descartables | E21: ZDES | F21: Dentro del alcance | G21: 2000008 | H21: AGUJA HIPODERMICA 21G x 1 - 25/8 | I21: DESC12 | J21: Agujas 25/8 | K21: =SUMIF('1120 SJ'!$A$2:$A$679,$G21,'1120 SJ'!$I$2:$I$679) | L21: =SUMIF('1120 SJ'!$A$2:$A$679,$G21,'1120 SJ'!$Q$2:$Q$679) | M21: =$K21-$L21 | N21: =IFERROR(SUMIF('1120 SJ'!$A$2:$A$679,$G21,'1120 SJ'!$M$2:$M$679)/$K21,0) | O21: =IFERROR($K21*$N21,"") | P21: =IFERROR($L21*$N21,"") | Q21: =$M21*$N21 | S21: Alta | T21: Homologado – confianza Alta | U21: Dar de baja en SAP | V21: Homologación por código Avain (master D-138) | W21: No | Y21: Sí | Z21: D-138 | AA21: Homologación: confianza base Alta + confianza SAP Alta → Alta.
A22: San Juan | B22: 1120 | C22: Stock SAP | D22: Medicamentos | E22: ZMED | F22: Dentro del alcance | G22: 1000182 | H22: METOCLOPRAMIDA COMPRIMIDO | I22: MED132 | J22: Metoclopramida S/L comp | K22: =SUMIF('1120 SJ'!$A$2:$A$679,$G22,'1120 SJ'!$I$2:$I$679) | L22: =SUMIF('1120 SJ'!$A$2:$A$679,$G22,'1120 SJ'!$Q$2:$Q$679) | M22: =$K22-$L22 | N22: =IFERROR(SUMIF('1120 SJ'!$A$2:$A$679,$G22,'1120 SJ'!$M$2:$M$679)/$K22,0) | O22: =IFERROR($K22*$N22,"") | P22: =IFERROR($L22*$N22,"") | Q22: =$M22*$N22 | S22: Alta | T22: Homologado – confianza Alta | U22: Dar de baja en SAP | V22: Cruce por nomenclatura SAP | W22: No | Y22: No | AA22: Cruce por nomenclatura: similitud 0.87.
A23: San Juan | B23: 1120 | C23: Stock SAP | D23: Medicamentos | E23: ZMED | F23: Dentro del alcance | G23: 1000816 | H23: AMOXICILINA+AC.CLA 875MG/125MG x 14 COMP | K23: =SUMIF('1120 SJ'!$A$2:$A$679,$G23,'1120 SJ'!$I$2:$I$679) | L23: =SUMIF('1120 SJ'!$A$2:$A$679,$G23,'1120 SJ'!$Q$2:$Q$679) | M23: =$K23-$L23 | N23: =IFERROR(SUMIF('1120 SJ'!$A$2:$A$679,$G23,'1120 SJ'!$M$2:$M$679)/$K23,0) | O23: =IFERROR($K23*$N23,"") | P23: =IFERROR($L23*$N23,"") | Q23: =$M23*$N23 | T23: Sin recuento físico en el inventario de Avain | U23: Sin recuento físico | AA23: El material ocupa 2 filas en la hoja 1120 SJ (lote/almacén). La cantidad SAP y la física de esta vista son el total del material.
A24: San Juan | B24: 1120 | C24: Stock SAP | D24: Medicamentos | E24: ZMED | F24: Dentro del alcance | G24: 1000089 | H24: SOLUCION FISIOLOGICA DE 500CC | I24: MED168 | J24: Solucion fisiológica x 500 ml | K24: =SUMIF('1120 SJ'!$A$2:$A$679,$G24,'1120 SJ'!$I$2:$I$679) | L24: =SUMIF('1120 SJ'!$A$2:$A$679,$G24,'1120 SJ'!$Q$2:$Q$679) | M24: =$K24-$L24 | N24: =IFERROR(SUMIF('1120 SJ'!$A$2:$A$679,$G24,'1120 SJ'!$M$2:$M$679)/$K24,0) | O24: =IFERROR($K24*$N24,"") | P24: =IFERROR($L24*$N24,"") | Q24: =$M24*$N24 | S24: Media | T24: Homologado – confianza Media – pendiente de validación | U24: Dar de baja en SAP | V24: Homologación por código Avain (master M13-001) | W24: No | Y24: Sí | Z24: M13-001 | AA24: Homologación: confianza base Media + confianza SAP Alta → Media. Otros códigos SAP del master no están en el stock de este centro: 1005145. El material ocupa 11 filas en la hoja 1120 SJ (lote/almacén). La cantidad SAP y la física de esta vista son el total del material.
A25: San Juan | B25: 1120 | C25: Stock SAP | D25: Descartables | E25: ZDES | F25: Dentro del alcance | G25: 2000009 | H25: AGUJA HIPODERMICA 21G x 1 ½ - 40/8 | I25: DESC13 | J25: Agujas 40/8 | K25: =SUMIF('1120 SJ'!$A$2:$A$679,$G25,'1120 SJ'!$I$2:$I$679) | L25: =SUMIF('1120 SJ'!$A$2:$A$679,$G25,'1120 SJ'!$Q$2:$Q$679) | M25: =$K25-$L25 | N25: =IFERROR(SUMIF('1120 SJ'!$A$2:$A$679,$G25,'1120 SJ'!$M$2:$M$679)/$K25,0) | O25: =IFERROR($K25*$N25,"") | P25: =IFERROR($L25*$N25,"") | Q25: =$M25*$N25 | S25: Alta | T25: Homologado – confianza Alta | U25: Dar de baja en SAP | V25: Homologación por código Avain (master D-139) | W25: No | Y25: Sí | Z25: D-139 | AA25: Homologación: confianza base Alta + confianza SAP Alta → Alta.
A26: San Juan | B26: 1120 | C26: Stock SAP | D26: Medicamentos | E26: ZMED | F26: Dentro del alcance | G26: 1000144 | H26: LORATADINA 10 MG COMP | K26: =SUMIF('1120 SJ'!$A$2:$A$679,$G26,'1120 SJ'!$I$2:$I$679) | L26: =SUMIF('1120 SJ'!$A$2:$A$679,$G26,'1120 SJ'!$Q$2:$Q$679) | M26: =$K26-$L26 | N26: =IFERROR(SUMIF('1120 SJ'!$A$2:$A$679,$G26,'1120 SJ'!$M$2:$M$679)/$K26,0) | O26: =IFERROR($K26*$N26,"") | P26: =IFERROR($L26*$N26,"") | Q26: =$M26*$N26 | T26: Sin recuento físico en el inventario de Avain | U26: Sin recuento físico | AA26: El material ocupa 2 filas en la hoja 1120 SJ (lote/almacén). La cantidad SAP y la física de esta vista son el total del material.
A27: San Juan | B27: 1120 | C27: Stock SAP | D27: Medicamentos | E27: ZMED | F27: Dentro del alcance | G27: 1000597 | H27: LOPERAMIDA 2MG COMPRIMIDO | I27: MED118 | J27: Loperamida Comp x 2 mg | K27: =SUMIF('1120 SJ'!$A$2:$A$679,$G27,'1120 SJ'!$I$2:$I$679) | L27: =SUMIF('1120 SJ'!$A$2:$A$679,$G27,'1120 SJ'!$Q$2:$Q$679) | M27: =$K27-$L27 | N27: =IFERROR(SUMIF('1120 SJ'!$A$2:$A$679,$G27,'1120 SJ'!$M$2:$M$679)/$K27,0) | O27: =IFERROR($K27*$N27,"") | P27: =IFERROR($L27*$N27,"") | Q27: =$M27*$N27 | S27: Alta | T27: Homologado – confianza Alta | U27: Dar de baja en SAP | V27: Cruce por nomenclatura SAP | W27: No | Y27: Sí | AA27: Cruce por nomenclatura: dosis coincide; similitud 0.97. El material ocupa 5 filas en la hoja 1120 SJ (lote/almacén). La cantidad SAP y la física de esta vista son el total del material.
A28: San Juan | B28: 1120 | C28: Stock SAP | D28: Descartables | E28: ZDES | F28: Dentro del alcance | G28: 2000007 | H28: AGUJA HIPODERMICA 25G x ⅝ - 16/5 | I28: DESC11 | J28: Agujas 16/5 | K28: =SUMIF('1120 SJ'!$A$2:$A$679,$G28,'1120 SJ'!$I$2:$I$679) | L28: =SUMIF('1120 SJ'!$A$2:$A$679,$G28,'1120 SJ'!$Q$2:$Q$679) | M28: =$K28-$L28 | N28: =IFERROR(SUMIF('1120 SJ'!$A$2:$A$679,$G28,'1120 SJ'!$M$2:$M$679)/$K28,0) | O28: =IFERROR($K28*$N28,"") | P28: =IFERROR($L28*$N28,"") | Q28: =$M28*$N28 | S28: Alta | T28: Homologado – confianza Alta | U28: Dar de baja en SAP | V28: Homologación por código Avain (master D-140) | W28: No | Y28: Sí | Z28: D-140 | AA28: Homologación: confianza base Alta + confianza SAP Alta → Alta.
A29: San Juan | B29: 1120 | C29: Stock SAP | D29: Medicamentos | E29: ZMED | F29: Dentro del alcance | G29: 1000529 | H29: DEXAMETASONA 4 MG COMPRIMIDOS | K29: =SUMIF('1120 SJ'!$A$2:$A$679,$G29,'1120 SJ'!$I$2:$I$679) | L29: =SUMIF('1120 SJ'!$A$2:$A$679,$G29,'1120 SJ'!$Q$2:$Q$679) | M29: =$K29-$L29 | N29: =IFERROR(SUMIF('1120 SJ'!$A$2:$A$679,$G29,'1120 SJ'!$M$2:$M$679)/$K29,0) | O29: =IFERROR($K29*$N29,"") | P29: =IFERROR($L29*$N29,"") | Q29: =$M29*$N29 | T29: Sin recuento físico en el inventario de Avain | U29: Sin recuento físico | AA29: El material ocupa 5 filas en la hoja 1120 SJ (lote/almacén). La cantidad SAP y la física de esta vista son el total del material.
A30: San Juan | B30: 1120 | C30: Stock SAP | D30: Medicamentos | E30: ZMED | F30: Dentro del alcance | G30: 1001129 | H30: BUCOANGIN CARAM ANTIB X9 | I30: MED30 | J30: Caramelos antigripales con benzocaina 20.7mg | K30: =SUMIF('1120 SJ'!$A$2:$A$679,$G30,'1120 SJ'!$I$2:$I$679) | L30: =SUMIF('1120 SJ'!$A$2:$A$679,$G30,'1120 SJ'!$Q$2:$Q$679) | M30: =$K30-$L30 | N30: =IFERROR(SUMIF('1120 SJ'!$A$2:$A$679,$G30,'1120 SJ'!$M$2:$M$679)/$K30,0) | O30: =IFERROR($K30*$N30,"") | P30: =IFERROR($L30*$N30,"") | Q30: =$M30*$N30 | S30: Baja | T30: Homologado – confianza Baja – pendiente de validación | U30: Dar de baja en SAP | V30: Homologación por código Avain (master M01-017) | W30: No | Y30: Sí | Z30: M01-017 | AA30: Homologación: confianza base Baja + confianza SAP Alta → Baja. La nomenclatura del material imputado no respalda por sí sola la equivalencia (similitud 0.09); el vínculo proviene sólo de la homologación. Nivel degradado a Baja. El material ocupa 15 filas en la hoja 1120 SJ (lote/almacén). La cantidad SAP y la física de esta vista son el total del material.
A31: San Juan | B31: 1120 | C31: Stock SAP | D31: Medicamentos | E31: ZMED | F31: Dentro del alcance | G31: 1000122 | H31: METOCLOPRAMIDA DE 10MG SL | I31: MED131 | J31: Metoclopramida Comp x 10 mg | K31: =SUMIF('1120 SJ'!$A$2:$A$679,$G31,'1120 SJ'!$I$2:$I$679) | L31: =SUMIF('1120 SJ'!$A$2:$A$679,$G31,'1120 SJ'!$Q$2:$Q$679) | M31: =$K31-$L31 | N31: =IFERROR(SUMIF('1120 SJ'!$A$2:$A$679,$G31,'1120 SJ'!$M$2:$M$679)/$K31,0) | O31: =IFERROR($K31*$N31,"") | P31: =IFERROR($L31*$N31,"") | Q31: =$M31*$N31 | S31: Alta | T31: Homologado – confianza Alta | U31: Dar de baja en SAP | V31: Homologación por código Avain (master M08-002) | W31: No | Y31: Sí | Z31: M08-002 | AA31: Homologación: confianza base Alta + confianza SAP Alta → Alta. El material ocupa 3 filas en la hoja 1120 SJ (lote/almacén). La cantidad SAP y la física de esta vista son el total del material.
A32: San Juan | B32: 1120 | C32: Stock SAP | D32: Medicamentos | E32: ZMED | F32: Dentro del alcance | G32: 1000196 | H32: KETOROLAC 30 MG/1ML AMP | I32: MED109 | J32: Ketorolac 30mg Amp x 1 ml | K32: =SUMIF('1120 SJ'!$A$2:$A$679,$G32,'1120 SJ'!$I$2:$I$679) | L32: =SUMIF('1120 SJ'!$A$2:$A$679,$G32,'1120 SJ'!$Q$2:$Q$679) | M32: =$K32-$L32 | N32: =IFERROR(SUMIF('1120 SJ'!$A$2:$A$679,$G32,'1120 SJ'!$M$2:$M$679)/$K32,0) | O32: =IFERROR($K32*$N32,"") | P32: =IFERROR($L32*$N32,"") | Q32: =$M32*$N32 | S32: Alta | T32: Homologado – confianza Alta | U32: Dar de baja en SAP | V32: Homologación por código Avain (master M01-007) | W32: No | Y32: Sí | Z32: M01-007 | AA32: Homologación: confianza base Alta + confianza SAP Alta → Alta. El material ocupa 2 filas en la hoja 1120 SJ (lote/almacén). La cantidad SAP y la física de esta vista son el total del material.
A33: San Juan | B33: 1120 | C33: Stock SAP | D33: Descartables | E33: ZDES | F33: Dentro del alcance | G33: 2000005 | H33: CATETER INTRAVENOSO 20G T/ABBOCATH | I33: DESC4 | J33: Abbocath Nº 20 | K33: =SUMIF('1120 SJ'!$A$2:$A$679,$G33,'1120 SJ'!$I$2:$I$679) | L33: =SUMIF('1120 SJ'!$A$2:$A$679,$G33,'1120 SJ'!$Q$2:$Q$679) | M33: =$K33-$L33 | N33: =IFERROR(SUMIF('1120 SJ'!$A$2:$A$679,$G33,'1120 SJ'!$M$2:$M$679)/$K33,0) | O33: =IFERROR($K33*$N33,"") | P33: =IFERROR($L33*$N33,"") | Q33: =$M33*$N33 | S33: Alta | T33: Homologado – confianza Alta | U33: Dar de baja en SAP | V33: Homologación por código Avain (master D-128) | W33: No | Y33: Sí | Z33: D-128 | AA33: Homologación: confianza base Alta + confianza SAP Alta → Alta.
A34: San Juan | B34: 1120 | C34: Stock SAP | D34: Medicamentos | E34: ZMED | F34: Dentro del alcance | G34: 1001291 | H34: KETOROLAC 30 MG/2ML AMP | K34: =SUMIF('1120 SJ'!$A$2:$A$679,$G34,'1120 SJ'!$I$2:$I$679) | L34: =SUMIF('1120 SJ'!$A$2:$A$679,$G34,'1120 SJ'!$Q$2:$Q$679) | M34: =$K34-$L34 | N34: =IFERROR(SUMIF('1120 SJ'!$A$2:$A$679,$G34,'1120 SJ'!$M$2:$M$679)/$K34,0) | O34: =IFERROR($K34*$N34,"") | P34: =IFERROR($L34*$N34,"") | Q34: =$M34*$N34 | T34: Sin recuento físico en el inventario de Avain | U34: Sin recuento físico | AA34: El material ocupa 4 filas en la hoja 1120 SJ (lote/almacén). La cantidad SAP y la física de esta vista son el total del material.
A35: San Juan | B35: 1120 | C35: Stock SAP | D35: Descartables | E35: ZDES | F35: Dentro del alcance | G35: 2000522 | H35: APOSITO 10X20 SYRA | K35: =SUMIF('1120 SJ'!$A$2:$A$679,$G35,'1120 SJ'!$I$2:$I$679) | L35: =SUMIF('1120 SJ'!$A$2:$A$679,$G35,'1120 SJ'!$Q$2:$Q$679) | M35: =$K35-$L35 | N35: =IFERROR(SUMIF('1120 SJ'!$A$2:$A$679,$G35,'1120 SJ'!$M$2:$M$679)/$K35,0) | O35: =IFERROR($K35*$N35,"") | P35: =IFERROR($L35*$N35,"") | Q35: =$M35*$N35 | T35: Sin recuento físico en el inventario de Avain | U35: Sin recuento físico
A36: San Juan | B36: 1120 | C36: Stock SAP | D36: Descartables | E36: ZDES | F36: Dentro del alcance | G36: 2000027 | H36: JERINGA DE 5 ML | I36: DESC80 | J36: Jeringas 5 cc | K36: =SUMIF('1120 SJ'!$A$2:$A$679,$G36,'1120 SJ'!$I$2:$I$679) | L36: =SUMIF('1120 SJ'!$A$2:$A$679,$G36,'1120 SJ'!$Q$2:$Q$679) | M36: =$K36-$L36 | N36: =IFERROR(SUMIF('1120 SJ'!$A$2:$A$679,$G36,'1120 SJ'!$M$2:$M$679)/$K36,0) | O36: =IFERROR($K36*$N36,"") | P36: =IFERROR($L36*$N36,"") | Q36: =$M36*$N36 | S36: Alta | T36: Homologado – confianza Alta | U36: Dar de baja en SAP | V36: Homologación por código Avain (master D-135) | W36: No | Y36: Sí | Z36: D-135 | AA36: Homologación: confianza base Alta + confianza SAP Alta → Alta.
A37: San Juan | B37: 1120 | C37: Stock SAP | D37: Medicamentos | E37: ZMED | F37: Dentro del alcance | G37: 1001297 | H37: PULMONIX ANTIGRIP 20 COMP | I37: MED156 | J37: Antigripal comp | K37: =SUMIF('1120 SJ'!$A$2:$A$679,$G37,'1120 SJ'!$I$2:$I$679) | L37: =SUMIF('1120 SJ'!$A$2:$A$679,$G37,'1120 SJ'!$Q$2:$Q$679) | M37: =$K37-$L37 | N37: =IFERROR(SUMIF('1120 SJ'!$A$2:$A$679,$G37,'1120 SJ'!$M$2:$M$679)/$K37,0) | O37: =IFERROR($K37*$N37,"") | P37: =IFERROR($L37*$N37,"") | Q37: =$M37*$N37 | S37: Media | T37: Homologado – confianza Media – pendiente de validación | U37: Dar de baja en SAP | V37: Cruce por nomenclatura SAP | W37: No | Y37: No | AA37: Cruce por nomenclatura: similitud 0.62. El material ocupa 3 filas en la hoja 1120 SJ (lote/almacén). La cantidad SAP y la física de esta vista son el total del material.
A38: San Juan | B38: 1120 | C38: Stock SAP | D38: Medicamentos | E38: ZMED | F38: Dentro del alcance | G38: 1000022 | H38: DIPIRONA 1G AMPOLLA DE 2ML INYECTABLE | I38: MED69 | J38: Dipirona 1gr Amp x 2 ml | K38: =SUMIF('1120 SJ'!$A$2:$A$679,$G38,'1120 SJ'!$I$2:$I$679) | L38: =SUMIF('1120 SJ'!$A$2:$A$679,$G38,'1120 SJ'!$Q$2:$Q$679) | M38: =$K38-$L38 | N38: =IFERROR(SUMIF('1120 SJ'!$A$2:$A$679,$G38,'1120 SJ'!$M$2:$M$679)/$K38,0) | O38: =IFERROR($K38*$N38,"") | P38: =IFERROR($L38*$N38,"") | Q38: =$M38*$N38 | S38: Alta | T38: Homologado – confianza Alta | U38: Dar de baja en SAP | V38: Cruce por nomenclatura SAP | W38: No | Y38: Sí | AA38: Cruce por nomenclatura: dosis coincide; similitud 0.77. El material ocupa 4 filas en la hoja 1120 SJ (lote/almacén). La cantidad SAP y la física de esta vista son el total del material.
A39: San Juan | B39: 1120 | C39: Stock SAP | D39: Medicamentos | E39: ZMED | F39: Dentro del alcance | G39: 1000035 | H39: SOLUCIÓN RINGER LACTATO 500 ML | I39: MED169 | J39: Solución ringer lactato x 500 ml | K39: =SUMIF('1120 SJ'!$A$2:$A$679,$G39,'1120 SJ'!$I$2:$I$679) | L39: =SUMIF('1120 SJ'!$A$2:$A$679,$G39,'1120 SJ'!$Q$2:$Q$679) | M39: =$K39-$L39 | N39: =IFERROR(SUMIF('1120 SJ'!$A$2:$A$679,$G39,'1120 SJ'!$M$2:$M$679)/$K39,0) | O39: =IFERROR($K39*$N39,"") | P39: =IFERROR($L39*$N39,"") | Q39: =$M39*$N39 | S39: Alta | T39: Homologado – confianza Alta | U39: Dar de baja en SAP | V39: Homologación por código Avain (master M13-003) | W39: No | Y39: Sí | Z39: M13-003 | AA39: Homologación: confianza base Alta + confianza SAP Alta → Alta. El material ocupa 6 filas en la hoja 1120 SJ (lote/almacén). La cantidad SAP y la física de esta vista son el total del material.
A40: San Juan | B40: 1120 | C40: Stock SAP | D40: Medicamentos | E40: ZMED | F40: Dentro del alcance | G40: 1000059 | H40: BUTIL BROMURO DE HIOSCINA 20MG AMPOLLA | I40: MED100 | J40: Hioscina x 20 mg Amp x 1 ml | K40: =SUMIF('1120 SJ'!$A$2:$A$679,$G40,'1120 SJ'!$I$2:$I$679) | L40: =SUMIF('1120 SJ'!$A$2:$A$679,$G40,'1120 SJ'!$Q$2:$Q$679) | M40: =$K40-$L40 | N40: =IFERROR(SUMIF('1120 SJ'!$A$2:$A$679,$G40,'1120 SJ'!$M$2:$M$679)/$K40,0) | O40: =IFERROR($K40*$N40,"") | P40: =IFERROR($L40*$N40,"") | Q40: =$M40*$N40 | S40: Media | T40: Homologado – confianza Media – pendiente de validación | U40: Dar de baja en SAP | V40: Homologación por código Avain (master M08-003) | W40: No | Y40: Sí | Z40: M08-003 | AA40: Homologación: confianza base Media + confianza SAP Alta → Media. El material ocupa 6 filas en la hoja 1120 SJ (lote/almacén). La cantidad SAP y la física de esta vista son el total del material.
A41: San Juan | B41: 1120 | C41: Stock SAP | D41: Medicamentos | E41: ZMED | F41: Dentro del alcance | G41: 1000520 | H41: DICLOFENAC 50MG + PRIDINOL 4MG | K41: =SUMIF('1120 SJ'!$A$2:$A$679,$G41,'1120 SJ'!$I$2:$I$679) | L41: =SUMIF('1120 SJ'!$A$2:$A$679,$G41,'1120 SJ'!$Q$2:$Q$679) | M41: =$K41-$L41 | N41: =IFERROR(SUMIF('1120 SJ'!$A$2:$A$679,$G41,'1120 SJ'!$M$2:$M$679)/$K41,0) | O41: =IFERROR($K41*$N41,"") | P41: =IFERROR($L41*$N41,"") | Q41: =$M41*$N41 | T41: Sin recuento físico en el inventario de Avain | U41: Sin recuento físico | AA41: El material ocupa 2 filas en la hoja 1120 SJ (lote/almacén). La cantidad SAP y la física de esta vista son el total del material.
A42: San Juan | B42: 1120 | C42: Stock SAP | D42: Descartables | E42: ZDES | F42: Dentro del alcance | G42: 2001536 | H42: CATETER ARGYLE N° 20 | K42: =SUMIF('1120 SJ'!$A$2:$A$679,$G42,'1120 SJ'!$I$2:$I$679) | L42: =SUMIF('1120 SJ'!$A$2:$A$679,$G42,'1120 SJ'!$Q$2:$Q$679) | M42: =$K42-$L42 | N42: =IFERROR(SUMIF('1120 SJ'!$A$2:$A$679,$G42,'1120 SJ'!$M$2:$M$679)/$K42,0) | O42: =IFERROR($K42*$N42,"") | P42: =IFERROR($L42*$N42,"") | Q42: =$M42*$N42 | T42: Sin recuento físico en el inventario de Avain | U42: Sin recuento físico
...

Sheet Dar de baja en SAP
A2: Materiales a dar de baja en SAP
A3: Materiales con recuento físico donde SAP informa MÁS unidades que el recuento. La cantidad a ajustar es la diferencia y se valoriza al valor promedio ponderado. Ordenado por impacto económico.
A5: Base | B5: Centro | C5: Clasificación SAP | D5: Código SAP (Material) | E5: Nomenclatura SAP | F5: Código Avain | G5: Nombre en inventario físico Avain | H5: Cantidad SAP · UNIDADES | I5: Cantidad física · UNIDADES | J5: Cantidad a ajustar · UNIDADES | K5: VU promedio ponderado · IMPORTE $ por unidad | L5: Valor económico del ajuste · IMPORTE $ | M5: Nivel de coincidencia | N5: Estado de homologación / validación | O5: Alerta de valorización | P5: Observaciones
A6: Neuquén | B6: 1060 | C6: Descartables | D6: 2001249 | E6: TIRAS REACTIVAS OPTIUM NEO H | F6: 340; 385 | G6: TIRAS REACTIVAS HGT; TIRAS REACTIVAS OPTIUM NEO H (CAJA X 50) | H6: 25947 | I6: 0 | J6: 25947 | K6: 415.07167 | L6: =$J6*$K6 | M6: Media | N6: Homologado – confianza Media – pendiente de validación | P6: Varias denominaciones del inventario físico corresponden a este material SAP (340 TIRAS REACTIVAS HGT; 385 TIRAS REACTIVAS OPTIUM NEO H (CAJA X 50)). Se sumaron las cantidades físicas. Homologación: confianza base Alta + confianza SAP Media → Media. Otros códigos SAP del master no están en el stock de este centro: 2001327, 2001422. Cruce por nomenclatura: similitud 0.88. El material ocupa 2 filas en la hoja 1060 NQN (lote/almacén). La cantidad SAP y la física de esta vista son el total del material.
A7: Neuquén | B7: 1060 | C7: Descartables | D7: 2001752 | E7: TEST 6 DROGAS x saliva | F7: 374 | G7: TEST DE DROGA SALIVA (CAJA X 25 UNIDADES) | H7: 340 | I7: 8 | J7: 332 | K7: 27080.835 | L7: =$J7*$K7 | M7: Baja | N7: Homologado – confianza Baja – pendiente de validación | P7: Cruce por nomenclatura: calibre/talle/medida distinta; similitud 0.62. El material ocupa 2 filas en la hoja 1060 NQN (lote/almacén). La cantidad SAP y la física de esta vista son el total del material.
A8: San Juan | B8: 1120 | C8: Descartables | D8: 2000363 | E8: MASCARA PARA O2 ADULTO CON RESERVORIO | F8: DESC93 | G8: Mascaras para oxigeno c/ reservorio | H8: 2912 | I8: 50 | J8: 2862 | K8: 1594.028 | L8: =$J8*$K8 | M8: Media | N8: Homologado – confianza Media – pendiente de validación | O8: Valorización a validar: relación de cantidades 58 a 1 entre SAP y el recuento físico. Sugiere distinta unidad de medida (SAP por caja o envase y el recuento por unidad). La diferencia económica de esta fila no debe tomarse como definitiva. | P8: Homologación: confianza base Media + confianza SAP Media → Media. Otros códigos SAP del master no están en el stock de este centro: 2000364.
A9: Neuquén | B9: 1060 | C9: Medicamentos | D9: 1000089 | E9: SOLUCION FISIOLOGICA DE 500CC | F9: 212 | G9: SOLUCIÓN FISIOLÓGICA | H9: 3471 | I9: 0 | J9: 3471 | K9: 1081.6857 | L9: =$J9*$K9 | M9: Media | N9: Homologado – confianza Media – pendiente de validación | P9: Homologación: confianza base Media + confianza SAP Alta → Media. Otros códigos SAP del master no están en el stock de este centro: 1005145. El material ocupa 23 filas en la hoja 1060 NQN (lote/almacén). La cantidad SAP y la física de esta vista son el total del material.
A10: Neuquén | B10: 1060 | C10: Medicamentos | D10: 1000010 | E10: HIDROCORTISONA 500MG AMPOLLA | F10: 130 | G10: HIDROCORTISONA 500 MG AMP | H10: 2010 | I10: 343 | J10: 1667 | K10: 2174.7838 | L10: =$J10*$K10 | M10: Alta | N10: Homologado – confianza Alta | P10: Homologación: confianza base Alta + confianza SAP Alta → Alta. El material ocupa 17 filas en la hoja 1060 NQN (lote/almacén). La cantidad SAP y la física de esta vista son el total del material.
A11: Neuquén | B11: 1060 | C11: Medicamentos | D11: 1000199 | E11: GLUCONATO DE CALCIO | F11: 122 | G11: GLUCONATO DE CALCIO AMP | H11: 3010 | I11: 290 | J11: 2720 | K11: 1303.294 | L11: =$J11*$K11 | M11: Alta | N11: Homologado – confianza Alta | P11: Homologado al master M03-006, pero sus códigos SAP (1005248) no figuran en el stock SAP de este centro. Cruce por nomenclatura: similitud 0.93. El material ocupa 2 filas en la hoja 1060 NQN (lote/almacén). La cantidad SAP y la física de esta vista son el total del material.
A12: Neuquén | B12: 1060 | C12: Medicamentos | D12: 1000005 | E12: AMIODARONA 150MG AMPOLLA DE 3 ML INYEC | F12: 342 | G12: AMIODARONA AMP | H12: 3456 | I12: 55 | J12: 3401 | K12: 947.2201 | L12: =$J12*$K12 | M12: Media | N12: Homologado – confianza Media – pendiente de validación | O12: Valorización a validar: relación de cantidades 63 a 1 entre SAP y el recuento físico. Sugiere distinta unidad de medida (SAP por caja o envase y el recuento por unidad). La diferencia económica de esta fila no debe tomarse como definitiva. | P12: Homologación: confianza base Media + confianza SAP Alta → Media. El material ocupa 26 filas en la hoja 1060 NQN (lote/almacén). La cantidad SAP y la física de esta vista son el total del material.
A13: Neuquén | B13: 1060 | C13: Medicamentos | D13: 1000124 | E13: IBUPROFENO COMP 600MG | F13: 396 | G13: IBUPROFENO 600MG COMP RECUBIERTOS | H13: 21380 | I13: 690 | J13: 20690 | K13: 148.22198 | L13: =$J13*$K13 | M13: Media | N13: Homologado – confianza Media – pendiente de validación | P13: Homologación: confianza base Media + confianza SAP Alta → Media. El material ocupa 34 filas en la hoja 1060 NQN (lote/almacén). La cantidad SAP y la física de esta vista son el total del material.
A14: Neuquén | B14: 1060 | C14: Medicamentos | D14: 1000430 | E14: POEN BIOPTAL GOTAS | F14: 188; 390 | G14: POEN-BIOPTAL NF COLIRIO; POENBIOPTAL GOTAS OFT X 5 ML | H14: 689 | I14: 79 | J14: 610 | K14: 4448.8275 | L14: =$J14*$K14 | M14: Baja | N14: Homologado – confianza Baja – pendiente de validación | P14: Varias denominaciones del inventario físico corresponden a este material SAP (188 POEN-BIOPTAL NF COLIRIO; 390 POENBIOPTAL GOTAS OFT X 5 ML). Se sumaron las cantidades físicas. Cruce por nomenclatura: similitud 0.63. Cruce por nomenclatura: una nomenclatura no informa dosis; similitud 0.64.
A15: Neuquén | B15: 1060 | C15: Medicamentos | D15: 1000045 | E15: DICLOFENAC 75MG AMPOLLA 3ML | F15: 80 | G15: DICLOFENAC AMP | H15: 11285 | I15: 33 | J15: 11252 | K15: 236.1373 | L15: =$J15*$K15 | M15: Media | N15: Homologado – confianza Media – pendiente de validación | O15: Valorización a validar: relación de cantidades 342 a 1 entre SAP y el recuento físico. Sugiere distinta unidad de medida (SAP por caja o envase y el recuento por unidad). La diferencia económica de esta fila no debe tomarse como definitiva. | P15: Cruce por nomenclatura: una nomenclatura no informa dosis; similitud 0.76. El material ocupa 42 filas en la hoja 1060 NQN (lote/almacén). La cantidad SAP y la física de esta vista son el total del material.
A16: Neuquén | B16: 1060 | C16: Medicamentos | D16: 1000035 | E16: SOLUCIÓN RINGER LACTATO 500 ML | F16: 216 | G16: SOLUCIÓN RINGER LACTATO | H16: 1813 | I16: 228 | J16: 1585 | K16: 1562.3013 | L16: =$J16*$K16 | M16: Media | N16: Homologado – confianza Media – pendiente de validación | P16: Homologación: confianza base Media + confianza SAP Alta → Media. El material ocupa 18 filas en la hoja 1060 NQN (lote/almacén). La cantidad SAP y la física de esta vista son el total del material.
A17: Neuquén | B17: 1060 | C17: Descartables | D17: 2000470 | E17: OTOSCOPIO | F17: 530 | G17: OTOSCOPIO | H17: 71 | I17: 11 | J17: 60 | K17: 38328.942 | L17: =$J17*$K17 | M17: Alta | N17: Homologado – confianza Alta | P17: Homologación: confianza base Alta + confianza SAP Alta → Alta. El material ocupa 2 filas en la hoja 1060 NQN (lote/almacén). La cantidad SAP y la física de esta vista son el total del material.
A18: Neuquén | B18: 1060 | C18: Medicamentos | D18: 1000497 | E18: IODOPOVIDONA SOLUC 10% X 60 ML | F18: 137; 469 | G18: IODOPOVIDONA 1000 ML; iodopovidona x 60 ml | H18: 360 | I18: 71 | J18: 289 | K18: 7619.6422 | L18: =$J18*$K18 | M18: Baja | N18: Homologado – confianza Baja – pendiente de validación | P18: Varias denominaciones del inventario físico corresponden a este material SAP (137 IODOPOVIDONA 1000 ML; 469 iodopovidona x 60 ml). Se sumaron las cantidades físicas. Homologación: confianza base Alta + confianza SAP Media → Media. Aunque la homologación vincula estos registros, la presentación no coincide con el material imputado (dosis/presentación distinta (1000ML vs 10%, 60ML); similitud 0.52). Nivel degradado a Baja: verificar si corresponde otro código SAP. Otros códigos SAP del master no están en el stock de este centro: 1000590. Cruce por nomenclatura: dosis coincide; similitud 0.81. El material ocupa 8 filas en la hoja 1060 NQN (lote/almacén). La cantidad SAP y la física de esta vista son el total del material.
A19: Neuquén | B19: 1060 | C19: Medicamentos | D19: 1000094 | E19: DEXAMETASONA INY 4MG/ML AMPOLLA | F19: 73 | G19: DEXAMETASONA AMP | H19: 6527 | I19: 193 | J19: 6334 | K19: 330.95254 | L19: =$J19*$K19 | M19: Media | N19: Homologado – confianza Media – pendiente de validación | P19: Cruce por nomenclatura: una nomenclatura no informa dosis; similitud 0.74. El cruce SAP–Avain identificó 2 códigos SAP como posibles equivalentes del mismo ítem de Avain (1000094, 1000478). Se imputó al primero (lógica BUSCARV); requiere validación posterior. El material ocupa 22 filas en la hoja 1060 NQN (lote/almacén). La cantidad SAP y la física de esta vista son el total del material.
A20: San Juan | B20: 1120 | C20: Medicamentos | D20: 1000478 | E20: DEXAMETASONA 8MG/2ML AMP(DESCONTINUADO) | F20: MED55 | G20: Dexametasona 8mg Amp x 2 ml | H20: 2853 | I20: 100 | J20: 2753 | K20: 702.7041 | L20: =$J20*$K20 | M20: Alta | N20: Homologado – confianza Alta | P20: Homologación: confianza base Alta + confianza SAP Alta → Alta. El material ocupa 12 filas en la hoja 1120 SJ (lote/almacén). La cantidad SAP y la física de esta vista son el total del material.
A21: Neuquén | B21: 1060 | C21: Descartables | D21: 2000058 | E21: LANCETA ESTERIL | F21: 527 | G21: LANCETAS | H21: 20552 | I21: 300 | J21: 20252 | K21: 92.772723 | L21: =$J21*$K21 | M21: Baja | N21: Homologado – confianza Baja – pendiente de validación | O21: Valorización a validar: relación de cantidades 69 a 1 entre SAP y el recuento físico. Sugiere distinta unidad de medida (SAP por caja o envase y el recuento por unidad). La diferencia económica de esta fila no debe tomarse como definitiva. | P21: La homologación no confirma la equivalencia (confianza base Sin coincidencia / confianza SAP Alta). Se imputó al código SAP del master con nivel Baja para no perder el recuento; requiere validación. Homologación: confianza base Sin coincidencia + confianza SAP Alta → Baja. El material ocupa 2 filas en la hoja 1060 NQN (lote/almacén). La cantidad SAP y la física de esta vista son el total del material.
A22: San Juan | B22: 1120 | C22: Medicamentos | D22: 1001129 | E22: BUCOANGIN CARAM ANTIB X9 | F22: MED30 | G22: Caramelos antigripales con benzocaina 20.7mg | H22: 964 | I22: 351 | J22: 613 | K22: 2964.0111 | L22: =$J22*$K22 | M22: Baja | N22: Homologado – confianza Baja – pendiente de validación | P22: Homologación: confianza base Baja + confianza SAP Alta → Baja. La nomenclatura del material imputado no respalda por sí sola la equivalencia (similitud 0.09); el vínculo proviene sólo de la homologación. Nivel degradado a Baja. El material ocupa 15 filas en la hoja 1120 SJ (lote/almacén). La cantidad SAP y la física de esta vista son el total del material.
A23: Neuquén | B23: 1060 | C23: Medicamentos | D23: 1000304 | E23: ADENOSINA 2 ML AMP 3 MG/1 ML | F23: 311 | G23: ADENOSINA AMP | H23: 1116 | I23: 0 | J23: 1116 | K23: 1497.545 | L23: =$J23*$K23 | M23: Media | N23: Homologado – confianza Media – pendiente de validación | P23: Homologación: confianza base Media + confianza SAP Alta → Media. El material ocupa 15 filas en la hoja 1060 NQN (lote/almacén). La cantidad SAP y la física de esta vista son el total del material.
A24: Neuquén | B24: 1060 | C24: Medicamentos | D24: 1000087 | E24: SALBUTAMOL PUFF ("AEROS" 250 DOSIS) 100M | F24: 204 | G24: SALBUTAMOL | H24: 463 | I24: 29 | J24: 434 | K24: 3630.0076 | L24: =$J24*$K24 | M24: Media | N24: Homologado – confianza Media – pendiente de validación | P24: Homologación: confianza base Media + confianza SAP Alta → Media. El material ocupa 14 filas en la hoja 1060 NQN (lote/almacén). La cantidad SAP y la física de esta vista son el total del material.
A25: San Juan | B25: 1120 | C25: Medicamentos | D25: 1000089 | E25: SOLUCION FISIOLOGICA DE 500CC | F25: MED168 | G25: Solucion fisiológica x 500 ml | H25: 1271 | I25: 249 | J25: 1022 | K25: 1447.5172 | L25: =$J25*$K25 | M25: Media | N25: Homologado – confianza Media – pendiente de validación | P25: Homologación: confianza base Media + confianza SAP Alta → Media. Otros códigos SAP del master no están en el stock de este centro: 1005145. El material ocupa 11 filas en la hoja 1120 SJ (lote/almacén). La cantidad SAP y la física de esta vista son el total del material.
A26: Neuquén | B26: 1060 | C26: Medicamentos | D26: 1000002 | E26: ADRENALINA 1MG AMPOLLA DE 1 ML INYEC | F26: MED-006; 2 | G26: Adrenalina 1mg/mL; ADRENALINA INY | H26: 5588 | I26: 603 | J26: 4985 | K26: 287.35597 | L26: =$J26*$K26 | M26: Baja | N26: Homologado – confianza Baja – pendiente de validación | P26: Varias denominaciones del inventario físico corresponden a este material SAP (MED-006 Adrenalina 1mg/mL; 2 ADRENALINA INY). Se sumaron las cantidades físicas. Cruce por nomenclatura: dosis coincide; similitud 0.78. Informe Avain: Diferencia stock actual - saldo de movimientos: 15 La denominación del inventario («ADRENALINA INY») difiere de la que registra el master para ese código («ADRENALINAINY»). Nivel degradado a Baja hasta validar la equivalencia. Homologación: confianza base Media + confianza SAP Alta → Baja. El material ocupa 27 filas en la hoja 1060 NQN (lote/almacén). La cantidad SAP y la física de esta vista son el total del material.
A27: Neuquén | B27: 1060 | C27: Medicamentos | D27: 1000105 | E27: METOCLOPRAMIDA 10MG/2ML AMPOLLA | F27: 160 | G27: METOCLOPRAMIDA AMP | H27: 5600 | I27: 146 | J27: 5454 | K27: 260.12259 | L27: =$J27*$K27 | M27: Media | N27: Homologado – confianza Media – pendiente de validación | P27: Cruce por nomenclatura: una nomenclatura no informa dosis; similitud 0.79. El material ocupa 30 filas en la hoja 1060 NQN (lote/almacén). La cantidad SAP y la física de esta vista son el total del material.
A28: Neuquén | B28: 1060 | C28: Medicamentos | D28: 1000183 | E28: MYLANTA TABLETAS COMPRIMIDOS | F28: 165 | G28: MYLANTA | H28: 5398 | I28: 0 | J28: 5398 | K28: 254.6908 | L28: =$J28*$K28 | M28: Media | N28: Homologado – confianza Media – pendiente de validación | P28: Cruce por nomenclatura: similitud 0.69. El cruce SAP–Avain identificó 2 códigos SAP como posibles equivalentes del mismo ítem de Avain (1000183, 1000188). Se imputó al primero (lógica BUSCARV); requiere validación posterior. El material ocupa 13 filas en la hoja 1060 NQN (lote/almacén). La cantidad SAP y la física de esta vista son el total del material.
A29: Neuquén | B29: 1060 | C29: Descartables | D29: 2001234 | E29: REGULADOR DE FLUJO | F29: 348 | G29: regulador de flujo | H29: 576 | I29: 0 | J29: 576 | K29: 2293.3308 | L29: =$J29*$K29 | M29: Alta | N29: Homologado – confianza Alta | P29: Cruce por nomenclatura: similitud 1.00. El material ocupa 2 filas en la hoja 1060 NQN (lote/almacén). La cantidad SAP y la física de esta vista son el total del material.
